Workbook

Sheet Consolidado
V1: FORMA DE PAGO
V2: EFECTIVO | W2: LATAS SAS
B3: INGRESOS | V3: TARJETA | W3: TOMAS GOMEZ
B4: EFECTIVO | C4: ENTREGA | D4: TARJETA LATAS | E4: TARJETA TOMAS | F4: BANCOLOMBIA LATAS | G4: BANCOLOMBIA TOMAS | H4: BBVA LATAS | I4: BBVA TOMAS | J4: GIRO | K4: DAVIVIENDA | L4: NEQUI TG | M4: NEQUI AB | N4: NEQUI OTRO | O4: TOTAL VENTA DIA | V4: BANCOLOMBIA
A5: 44562 | B5: =+'1'!$F$3 -> 0 | C5: =+'1'!$G$3 -> 0 | D5: =+'1'!$H$3 -> 0 | E5: =+'1'!$I$3 -> 0 | F5: =+'1'!$J$3 -> 0 | G5: =+'1'!$K$3 -> 0 | H5: =+'1'!$L$3 -> 0 | I5: =+'1'!$M$3 -> 0 | J5: =+'1'!$N$3 -> 0 | K5: =+'1'!$O$3 -> 0 | L5: =+'1'!$P$3 -> 0 | M5: =+'1'!$Q$3 -> 0 | N5: =+'1'!$R$3 -> 0 | O5: =SUM(B5:N5)-C5 -> 0 | V5: BBVA
A6: 44563 | B6: =+'2'!$F$3 -> 2369000 | C6: =+'2'!$G$3 -> 2369000 | D6: =+'2'!$H$3 -> 1380000 | E6: =+'2'!$I$3 -> 0 | F6: =+'2'!$I$3 -> 0 | G6: =+'2'!$K$3 -> 810000 | H6: =+'2'!$J$3 -> 2536000 | I6: =+'2'!$M$3 -> 0 | J6: =+'2'!$K$3 -> 810000 | K6: =+'2'!$L$3 -> 0 | L6: =+'2'!$P$3 -> 0 | M6: =+'2'!$Q$3 -> 0 | N6: =+'2'!$R$3 -> 0 | O6: =SUM(B6:N6) -> 10274000 | V6: GIRO
A7: 44564 | B7: =+'3'!$F$3 -> 2795000 | C7: =+'3'!$G$3 -> 2795000 | D7: =+'3'!$H$3 -> 1226000 | E7: =+'3'!$HI$3 -> 0 | F7: =+'3'!$I$3 -> 440000 | G7: =+'3'!$K$3 -> 1370000 | H7: =+'3'!$J$3 -> 2637000 | I7: =+'3'!$M$3 -> 0 | J7: =+'3'!$K$3 -> 1370000 | K7: =+'3'!$L$3 -> 0 | L7: =+'3'!$P$3 -> 0 | M7: =+'3'!$Q$3 -> 0 | N7: =+'3'!$R$3 -> 0 | O7: =SUM(B7:N7) -> 12633000 | V7: DAVIVIENDA
A8: 44565 | B8: =+'4'!$F$3 -> 0 | C8: =+'4'!$G$3 -> 0 | D8: =+'4'!$H$3 -> 0 | E8: =+'4'!$I$3 -> 0 | F8: =+'4'!$I$3 -> 0 | G8: =+'4'!$K$3 -> 0 | H8: =+'4'!$J$3 -> 0 | I8: =+'4'!$M$3 -> 0 | J8: =+'4'!$K$3 -> 0 | K8: =+'4'!$L$3 -> 0 | L8: =+'4'!$P$3 -> 0 | M8: =+'4'!$Q$3 -> 0 | N8: =+'4'!$R$3 -> 0 | O8: =SUM(B8:N8) -> 0 | V8: ENTREGA
A9: 44566 | B9: =+'5'!$F$3 -> 3168000 | C9: =+'5'!$G$3 -> 3168000 | D9: =+'5'!$H$3 -> 1920000 | E9: =+'5'!$I$3 -> 160000 | F9: =+'5'!$I$3 -> 160000 | G9: =+'5'!$K$3 -> 320000 | H9: =+'5'!$J$3 -> 2225000 | I9: =+'5'!$M$3 -> 0 | J9: =+'5'!$K$3 -> 320000 | K9: =+'5'!$L$3 -> 0 | L9: =+'5'!$P$3 -> 0 | M9: =+'5'!$Q$3 -> 0 | N9: =+'5'!$R$3 -> 0 | O9: =SUM(B9:N9) -> 11441000 | V9: NEQUI TG
A10: 44567 | B10: =+'6'!$F$3 -> 3020000 | C10: =+'6'!$G$3 -> 3020000 | D10: =+'6'!$H$3 -> 535000 | E10: =+'6'!$I$3 -> 60000 | F10: =+'6'!$I$3 -> 60000 | G10: =+'6'!$K$3 -> 0 | H10: =+'6'!$J$3 -> 2665000 | I10: =+'6'!$M$3 -> 0 | J10: =+'6'!$K$3 -> 0 | K10: =+'6'!$L$3 -> 0 | L10: =+'6'!$P$3 -> 0 | M10: =+'6'!$Q$3 -> 0 | N10: =+'6'!$R$3 -> 0 | O10: =SUM(B10:N10) -> 9360000 | V10: NEQUI AB
A11: 44568 | B11: =+'7'!$F$3 -> 3429000 | C11: =+'7'!$G$3 -> 3429000 | D11: =+'7'!$H$3 -> 1329000 | E11: =+'7'!$I$3 -> 0 | F11: =+'7'!$I$3 -> 0 | G11: =+'7'!$K$3 -> 0 | H11: =+'7'!$J$3 -> 2255000 | I11: =+'7'!$M$3 -> 0 | J11: =+'7'!$K$3 -> 0 | K11: =+'7'!$L$3 -> 0 | L11: =+'7'!$P$3 -> 0 | M11: =+'7'!$Q$3 -> 0 | N11: =+'7'!$R$3 -> 0 | O11: =SUM(B11:N11) -> 10442000 | V11: NEQUI OTRO
A12: 44569 | B12: =+'8'!$F$3 -> 3056000 | C12: =+'8'!$G$3 -> 3056000 | D12: =+'8'!$H$3 -> 626000 | E12: =+'8'!$I$3 -> 60000 | F12: =+'8'!$I$3 -> 60000 | G12: =+'8'!$K$3 -> 1165000 | H12: =+'8'!$J$3 -> 3971000 | I12: =+'8'!$M$3 -> 0 | J12: =+'8'!$K$3 -> 1165000 | K12: =+'8'!$L$3 -> 0 | L12: =+'8'!$P$3 -> 0 | M12: =+'8'!$Q$3 -> 0 | N12: =+'8'!$R$3 -> 0 | O12: =SUM(B12:N12) -> 13159000
A13: 44570 | B13: =+'9'!$F$3 -> 3895000 | C13: =+'9'!$G$3 -> 3895000 | D13: =+'9'!$H$3 -> 1450000 | E13: =+'8'!I3 -> 60000 | F13: =+'9'!$I$3 -> 520000 | G13: =+'9'!$K$3 -> 1210000 | H13: =+'9'!$J$3 -> 2135000 | I13: =+'9'!$M$3 -> 0 | J13: =+'9'!$K$3 -> 1210000 | K13: =+'9'!$L$3 -> 0 | L13: =+'9'!$P$3 -> 0 | M13: =+'9'!$Q$3 -> 0 | N13: =+'9'!$R$3 -> 0 | O13: =SUM(B13:N13) -> 14375000
A14: 44571 | B14: =+'10'!$F$3 -> 2469000 | C14: =+'10'!$G$3 -> 2469000 | D14: =+'10'!$H$3 -> 0 | E14: =+'10'!$I$3 -> 1060000 | F14: =+'10'!$I$3 -> 1060000 | G14: =+'10'!$K$3 -> 580000 | H14: =+'10'!$J$3 -> 1780000 | I14: =+'10'!MJ$3 -> 0 | J14: =+'10'!$K$3 -> 580000 | K14: =+'10'!$L$3 -> 0 | L14: =+'10'!$P$3 -> 0 | M14: =+'10'!$Q$3 -> 0 | N14: =+'10'!$R$3 -> 0 | O14: =SUM(B14:N14) -> 9998000
A15: 44572 | B15: =+'11'!$F$3 -> 0 | C15: =+'11'!$G$3 -> 0 | D15: =+'11'!$H$3 -> 0 | E15: =+'11'!$I$3 -> 0 | F15: =+'11'!$I$3 -> 0 | G15: =+'11'!$K$3 -> 0 | H15: =+'11'!$J$3 -> 0 | I15: =+'11'!M$3 -> 0 | J15: =+'11'!$K$3 -> 0 | K15: =+'11'!$L$3 -> 0 | L15: =+'11'!$P$3 -> 0 | M15: =+'11'!$Q$3 -> 0 | N15: =+'11'!$R$3 -> 0 | O15: =SUM(B15:N15) -> 0
A16: 44573 | B16: =+'12'!$F$3 -> 0 | C16: =+'12'!$G$3 -> 0 | D16: =+'12'!$H$3 -> 0 | E16: =+'12'!$I$3 -> 0 | F16: =+'12'!$I$3 -> 0 | G16: =+'12'!$K$3 -> 0 | H16: =+'12'!$J$3 -> 0 | I16: =+'12'!M$3 -> 0 | J16: =+'12'!$K$3 -> 0 | K16: =+'12'!$L$3 -> 0 | L16: =+'12'!$P$3 -> 0 | M16: =+'12'!$Q$3 -> 0 | N16: =+'12'!$R$3 -> 0 | O16: =SUM(B16:N16) -> 0
A17: 44574 | B17: =+'13'!$F$3 -> 3250000 | C17: =+'13'!$G$3 -> 3250000 | D17: =+'13'!$H$3 -> 405000 | E17: =+'13'!$I$3 -> 190000 | F17: =+'13'!$I$3 -> 190000 | G17: =+'13'!$K$3 -> 190000 | H17: =+'13'!$J$3 -> 1735000 | I17: =+'13'!$M$3 -> 0 | J17: =+'13'!$K$3 -> 190000 | K17: =+'13'!$L$3 -> 0 | L17: =+'13'!$P$3 -> 0 | M17: =+'13'!$Q$3 -> 0 | N17: =+'13'!$R$3 -> 0 | O17: =SUM(B17:N17) -> 9400000
A18: 44575 | B18: =+'14'!$F$3 -> 2050000 | C18: =+'14'!$G$3 -> 2050000 | D18: =+'14'!$H$3 -> 390000 | E18: =+'14'!$I$3 -> 0 | F18: =+'14'!$I$3 -> 0 | G18: =+'14'!$K$3 -> 360000 | H18: =+'14'!$J$3 -> 2949000 | I18: =+'14'!$M$3 -> 0 | J18: =+'14'!$K$3 -> 360000 | K18: =+'14'!$L$3 -> 0 | L18: =+'14'!$P$3 -> 0 | M18: =+'14'!$Q$3 -> 0 | N18: =+'14'!$R$3 -> 0 | O18: =SUM(B18:N18) -> 8159000
A19: 44576 | B19: =+'15'!$F$3 -> 3965000 | C19: =+'15'!$G$3 -> 3965000 | D19: =+'15'!$H$3 -> 0 | E19: =+'15'!$I$3 -> 150000 | F19: =+'15'!$I$3 -> 150000 | G19: =+'15'!$K$3 -> 850000 | H19: =+'15'!$J$3 -> 3190000 | I19: =+'15'!$M$3 -> 0 | J19: =+'15'!$K$3 -> 850000 | K19: =+'15'!$L$3 -> 0 | L19: =+'15'!$P$3 -> 0 | M19: =+'15'!$Q$3 -> 0 | N19: =+'15'!$R$3 -> 0 | O19: =SUM(B19:N19) -> 13120000
A20: 44577 | B20: =+'16'!$F$3 -> 3560000 | C20: =+'16'!$G$3 -> 3560000 | D20: =+'16'!$H$3 -> 922000 | E20: =+'16'!$I$3 -> 75000 | F20: =+'16'!$I$3 -> 75000 | G20: =+'16'!$K$3 -> 760000 | H20: =+'16'!$J$3 -> 3770000 | I20: =+'16'!$M$3 -> 0 | J20: =+'16'!$K$3 -> 760000 | K20: =+'16'!$L$3 -> 0 | L20: =+'16'!$P$3 -> 0 | M20: =+'16'!$Q$3 -> 0 | N20: =+'16'!$R$3 -> 0 | O20: =SUM(B20:N20) -> 13482000
A21: 44578 | B21: =+'17'!$F$3 -> 1348000 | C21: =+'17'!$G$3 -> 1348000 | D21: =+'17'!$H$3 -> 0 | E21: =+'17'!$I$3 -> 0 | F21: =+'17'!$I$3 -> 0 | G21: =+'17'!$K$3 -> 1730000 | H21: =+'17'!$J$3 -> 2192000 | I21: =+'17'!$M$3 -> 0 | J21: =+'17'!$K$3 -> 1730000 | K21: =+'17'!$L$3 -> 0 | L21: =+'17'!$P$3 -> 0 | M21: =+'17'!$Q$3 -> 0 | N21: =+'17'!$R$3 -> 0 | O21: =SUM(B21:N21) -> 8348000
A22: 44579 | B22: =+'18'!$F$3 -> 0 | C22: =+'18'!$G$3 -> 0 | D22: =+'18'!$H$3 -> 0 | E22: =+'18'!$I$3 -> 0 | F22: =+'18'!$I$3 -> 0 | G22: =+'18'!$K$3 -> 0 | H22: =+'18'!$J$3 -> 0 | I22: =+'18'!$M$3 -> 0 | J22: =+'18'!$K$3 -> 0 | K22: =+'18'!$L$3 -> 0 | L22: =+'18'!$P$3 -> 0 | M22: =+'18'!$Q$3 -> 0 | N22: =+'18'!$R$3 -> 0 | O22: =SUM(B22:N22) -> 0
A23: 44580 | B23: =+'19'!$F$3 -> 2950000 | C23: =+'19'!$G$3 -> 2630000 | D23: =+'19'!$H$3 -> 335000 | E23: =+'19'!$I$3 -> 320000 | F23: =+'19'!$I$3 -> 320000 | G23: =+'19'!$K$3 -> 440000 | H23: =+'19'!$J$3 -> 3425000 | I23: =+'19'!$M$3 -> 0 | J23: =+'19'!$K$3 -> 440000 | K23: =+'19'!$L$3 -> 0 | L23: =+'19'!$P$3 -> 0 | M23: =+'19'!$Q$3 -> 0 | N23: =+'19'!$R$3 -> 0 | O23: =SUM(B23:N23) -> 10860000
A24: 44581 | B24: =+'20'!$F$3 -> 2036000 | C24: =+'20'!$G$3 -> 2036000 | D24: =+'20'!$H$3 -> 0 | E24: =+'20'!$I$3 -> 0 | F24: =+'20'!$I$3 -> 0 | G24: =+'20'!$K$3 -> 450000 | H24: =+'20'!$J$3 -> 2090000 | I24: =+'20'!$M$3 -> 0 | J24: =+'20'!$K$3 -> 450000 | K24: =+'20'!$L$3 -> 0 | L24: =+'20'!$P$3 -> 0 | M24: =+'20'!$Q$3 -> 0 | N24: =+'20'!$R$3 -> 0 | O24: =SUM(B24:N24) -> 7062000
A25: 44582 | B25: =+'21'!$F$3 -> 2025000 | C25: =+'21'!$G$3 -> 2025000 | D25: =+'21'!$H$3 -> 280000 | E25: =+'21'!$I$3 -> 0 | F25: =+'21'!$I$3 -> 0 | G25: =+'21'!$K$3 -> 1025000 | H25: =+'21'!$J$3 -> 2725000 | I25: =+'21'!$M$3 -> 0 | J25: =+'21'!$K$3 -> 1025000 | K25: =+'21'!$L$3 -> 0 | L25: =+'21'!$P$3 -> 0 | M25: =+'21'!$Q$3 -> 0 | N25: =+'21'!$R$3 -> 0 | O25: =SUM(B25:N25) -> 9105000
A26: 44583 | B26: =+'22'!$F$3 -> 3584500 | C26: =+'22'!$G$3 -> 3584500 | D26: =+'22'!$H$3 -> 2760000 | E26: =+'22'!$I$3 -> 260000 | F26: =+'22'!$I$3 -> 260000 | G26: =+'22'!$K$3 -> 0 | H26: =+'22'!$J$3 -> 1815000 | I26: =+'22'!$M$3 -> 0 | J26: =+'22'!$K$3 -> 0 | K26: =+'22'!$L$3 -> 0 | L26: =+'22'!$P$3 -> 0 | M26: =+'22'!$Q$3 -> 0 | N26: =+'22'!$R$3 -> 0 | O26: =SUM(B26:N26) -> 12264000
A27: 44584 | B27: =+'23'!$F$3 -> 3432000 | C27: =+'23'!$G$3 -> 3432000 | D27: =+'23'!$H$3 -> 0 | E27: =+'23'!$I$3 -> 0 | F27: =+'23'!$I$3 -> 0 | G27: =+'23'!$K$3 -> 0 | H27: =+'23'!$J$3 -> 840000 | I27: =+'23'!$M$3 -> 0 | J27: =+'23'!$K$3 -> 0 | K27: =+'23'!$L$3 -> 0 | L27: =+'23'!$P$3 -> 0 | M27: =+'23'!$Q$3 -> 0 | N27: =+'23'!$R$3 -> 0 | O27: =SUM(B27:N27) -> 7704000
A28: 44585 | B28: =+'24'!$F$3 -> 2850000 | C28: =+'24'!$G$3 -> 2850000 | D28: =+'24'!$H$3 -> 2060000 | E28: =+'24'!$I$3 -> 190000 | F28: =+'24'!$I$3 -> 190000 | G28: =+'24'!$K$3 -> 565000 | H28: =+'24'!$J$3 -> 755000 | I28: =+'24'!$M$3 -> 0 | J28: =+'24'!$K$3 -> 565000 | K28: =+'24'!$L$3 -> 0 | L28: =+'24'!$P$3 -> 0 | M28: =+'24'!$Q$3 -> 0 | N28: =+'24'!$R$3 -> 0 | O28: =SUM(B28:N28) -> 10025000
A29: 44586 | B29: =+'25'!$F$3 -> 0 | C29: =+'25'!$G$3 -> 0 | D29: =+'25'!$H$3 -> 0 | E29: =+'25'!$I$3 -> 0 | F29: =+'25'!$I$3 -> 0 | G29: =+'25'!$IK$3 -> 0 | H29: =+'25'!$J$3 -> 0 | I29: =+'25'!$M$3 -> 0 | J29: =+'25'!$K$3 -> 0 | K29: =+'25'!$L$3 -> 0 | L29: =+'25'!$P$3 -> 0 | M29: =+'25'!$Q$3 -> 0 | N29: =+'25'!$R$3 -> 0 | O29: =SUM(B29:N29) -> 0
A30: 44587 | B30: =+'26'!$F$3 -> 5469000 | C30: =+'26'!$G$3 -> 5469000 | D30: =+'26'!$H$3 -> 0 | E30: =+'26'!$I$3 -> 50000 | F30: =+'26'!$I$3 -> 50000 | G30: =+'26'!$K$3 -> 297000 | H30: =+'26'!$J$3 -> 1905000 | I30: =+'26'!$M$3 -> 0 | J30: =+'26'!$K$3 -> 297000 | K30: =+'26'!$L$3 -> 0 | L30: =+'26'!$P$3 -> 0 | M30: =+'26'!$Q$3 -> 0 | N30: =+'26'!$R$3 -> 0 | O30: =SUM(B30:N30) -> 13537000
A31: 44588 | B31: =+'27'!$F$3 -> 2545000 | C31: =+'27'!$G$3 -> 1450000 | D31: =+'27'!$H$3 -> 190000 | E31: =+'27'!$I$3 -> 0 | F31: =+'27'!$I$3 -> 0 | G31: =+'27'!$K$3 -> 540000 | H31: =+'27'!$J$3 -> 1423000 | I31: =+'27'!$M$3 -> 0 | J31: =+'27'!$K$3 -> 540000 | K31: =+'27'!$L$3 -> 0 | L31: =+'27'!$P$3 -> 0 | M31: =+'27'!$Q$3 -> 0 | N31: =+'27'!$R$3 -> 0 | O31: =SUM(B31:N31) -> 6688000
A32: 44589 | B32: =+'28'!$F$3 -> 3420000 | C32: =+'28'!$G$3 -> 3420000 | D32: =+'28'!$H$3 -> 290000 | E32: =+'28'!$I$3 -> 0 | F32: =+'28'!$I$3 -> 0 | G32: =+'28'!$K$3 -> 0 | H32: =+'28'!$J$3 -> 1645000 | I32: =+'28'!$M$3 -> 0 | J32: =+'28'!$K$3 -> 0 | K32: =+'28'!$L$3 -> 0 | L32: =+'28'!$P$3 -> 0 | M32: =+'28'!$Q$3 -> 0 | N32: =+'28'!$R$3 -> 0 | O32: =SUM(B32:N32) -> 8775000
A33: 44590 | B33: =+'29'!$F$3 -> 3145000 | C33: =+'29'!$G$3 -> 3145000 | D33: =+'29'!$H$3 -> 250000 | E33: =+'29'!$I$3 -> 0 | F33: =+'29'!$I$3 -> 0 | G33: =+'29'!$K$3 -> 1680000 | H33: =+'29'!$J$3 -> 1090000 | I33: =+'29'!$M$3 -> 0 | J33: =+'29'!$K$3 -> 1680000 | K33: =+'29'!$L$3 -> 0 | L33: =+'29'!$P$3 -> 0 | M33: =+'29'!$Q$3 -> 0 | N33: =+'29'!$R$3 -> 0 | O33: =SUM(B33:N33) -> 10990000
A34: 44591 | B34: =+'30'!$F$3 -> 1555000 | C34: =+'30'!$G$3 -> 1555000 | D34: =+'30'!$H$3 -> 700000 | E34: =+'30'!$I$3 -> 0 | F34: =+'30'!$I$3 -> 0 | G34: =+'30'!$K$3 -> 180000 | H34: =+'30'!$J$3 -> 1300000 | I34: =+'30'!$M$3 -> 0 | J34: =+'30'!$K$3 -> 180000 | K34: =+'30'!$L$3 -> 0 | L34: =+'30'!$P$3 -> 0 | M34: =+'30'!$Q$3 -> 0 | N34: =+'30'!$R$3 -> 0 | O34: =SUM(B34:N34) -> 5470000
A35: 44592 | B35: =+'31'!$F$3 -> 2510000 | C35: =+'31'!$G$3 -> 2510000 | D35: =+'31'!$H$3 -> 0 | E35: =+'31'!$I$3 -> 0 | F35: =+'31'!$I$3 -> 0 | G35: =+'31'!$K$3 -> 0 | H35: =+'31'!$J$3 -> 2506000 | I35: =+'31'!$M$3 -> 0 | J35: =+'31'!$K$3 -> 0 | K35: =+'31'!$L$3 -> 0 | L35: =+'31'!$P$3 -> 0 | M35: =+'31'!$Q$3 -> 0 | N35: =+'31'!$R$3 -> 0 | O35: =SUM(B35:N35) -> 7526000
A36: TOTAL MES | B36: =SUM(B5:B35) -> 73895500 | C36: =SUM(C5:C35) -> 72480500 | D36: =SUM(D5:D35) -> 17048000 | E36: =SUM(E5:E35) -> 2635000 | F36: =SUM(F5:F35) -> 3535000 | G36: =SUM(G5:G35) -> 14522000 | H36: =SUM(H5:H35) -> 55559000 | I36: =SUM(I5:I35) -> 0 | ... O36: =SUM(O5:O35) -> 254197000
A42: FECHA | B42: PROVEEDOR | D42: FACTURA | E42: VALOR | F42: FORMA DE PAGO | G42: SALDO
G43: =+IF(F43="EFECTIVO",B36-E43,"N/A") -> N/A
G44: =+IF(F44="EFECTIVO",B37-E44,"N/A") -> N/A
G45: =+IF(F45="EFECTIVO",B38-E45,"N/A") -> N/A
...

Sheet 1
A1: LATAS Y PARTES DE LA COSTA
C2: CAJA MENOR
C3: CAJA EFECTIVO | D3: =+F3-G3 -> 0 | E3: =(SUM(F3:R3))-G3 -> 0 | F3: =SUM(F5:F50) -> 0 | G3: =SUM(G5:G50) -> 0 | H3: =SUM(H5:H50) -> 0 | I3: =SUM(I5:I50) -> 0 | J3: =SUM(J5:J50) -> 0 | K3: =SUM(K5:K50) -> 0 | L3: =SUM(L5:L50) -> 0 | M3: =SUM(M5:M50) -> 0 | ... R3: =SUM(R5:R50) -> 0
A4: EMPRESA | B4: FACTURA | C4: DESCRIPCIÓN | D4: VALOR | E4: FORMA PAGO | F4: EFECTIVO | G4: ENTREGA | H4: TARJETA LATAS | I4: TARJETA TOMAS | J4: BANCOLOMBIA LATAS | K4: BANCOLOMBIA TOMAS | L4: BBVA LATAS | M4: BBVA TOMAS | N4: GIRO | O4: DAVIVIENDA | P4: NEQUI TG | Q4: NEQUI AB | R4: NEQUI OTRO
F5: =IF(E5="EFECTIVO",D5,0) -> 0 | G5: =+IF(E5="ENTREGA",D5,0) -> 0 | H5: =+IF(AND(A5="latas sas",E5="tarjeta"),D5,0) -> 0 | I5: =+IF(AND(A5="tomas gomez",E5="tarjeta"),D5,0) -> 0 | J5: =+IF(AND($A5="latas sas",$E5="bancolombia"),$D5,0) -> 0 | K5: =+IF(AND($A5="tomas gomez",$E5="bancolombia"),$D5,0) -> 0 | L5: =+IF(AND($A5="latas sas",$E5="bbva"),$D5,0) -> 0 | M5: =+IF(AND($A5="tomas gomez",$E5="bbva"),$D5,0) -> 0 | N5: =IF(E5="GIRO",D5,0) -> 0 | O5: =IF(E5="DAVIVIENDA",D5,0) -> 0 | P5: =IF(E5="NEQUI TG",D5,0) -> 0 | Q5: =IF(E5="NEQUI AB",D5,0) -> 0 | R5: =IF(E5="NEQUI OTRO",D5,0) -> 0
F6: =IF(E6="EFECTIVO",D6,0) -> 0 | G6: =+IF(E6="ENTREGA",D6,0) -> 0 | H6: =+IF(AND(A6="latas sas",E6="tarjeta"),D6,0) -> 0 | I6: =+IF(AND(A6="tomas gomez",E6="tarjeta"),D6,0) -> 0 | J6: =+IF(AND($A6="latas sas",$E6="bancolombia"),$D6,0) -> 0 | K6: =+IF(AND($A6="tomas gomez",$E6="bancolombia"),$D6,0) -> 0 | L6: =+IF(AND($A6="latas sas",$E6="bbva"),$D6,0) -> 0 | M6: =+IF(AND($A6="tomas gomez",$E6="bbva"),$D6,0) -> 0 | N6: =IF(E6="GIRO",D6,0) -> 0 | O6: =IF(E6="DAVIVIENDA",D6,0) -> 0 | P6: =IF(E6="NEQUI TG",E6,0) -> 0 | Q6: =IF(E6="NEQUI AB",D6,0) -> 0 | R6: =IF(E6="NEQUI OTRO",D6,0) -> 0
F7: =IF(E7="EFECTIVO",D7,0) -> 0 | G7: =+IF(E7="ENTREGA",D7,0) -> 0 | H7: =+IF(AND(A7="latas sas",E7="tarjeta"),D7,0) -> 0 | I7: =+IF(AND(A7="tomas gomez",E7="tarjeta"),D7,0) -> 0 | J7: =+IF(AND($A7="latas sas",$E7="bancolombia"),$D7,0) -> 0 | K7: =+IF(AND($A7="tomas gomez",$E7="bancolombia"),$D7,0) -> 0 | L7: =+IF(AND($A7="latas sas",$E7="bbva"),$D7,0) -> 0 | M7: =+IF(AND($A7="tomas gomez",$E7="bbva"),$D7,0) -> 0 | N7: =IF(E7="GIRO",D7,0) -> 0 | O7: =IF(E7="DAVIVIENDA",D7,0) -> 0 | P7: =IF(E7="NEQUI TG",E7,0) -> 0 | Q7: =IF(E7="NEQUI AB",D7,0) -> 0 | R7: =IF(E7="NEQUI OTRO",D7,0) -> 0
F8: =IF(E8="EFECTIVO",D8,0) -> 0 | G8: =+IF(E8="ENTREGA",D8,0) -> 0 | H8: =+IF(AND(A8="latas sas",E8="tarjeta"),D8,0) -> 0 | I8: =+IF(AND(A8="tomas gomez",E8="tarjeta"),D8,0) -> 0 | J8: =+IF(AND($A8="latas sas",$E8="bancolombia"),$D8,0) -> 0 | K8: =+IF(AND($A8="tomas gomez",$E8="bancolombia"),$D8,0) -> 0 | L8: =+IF(AND($A8="latas sas",$E8="bbva"),$D8,0) -> 0 | M8: =+IF(AND($A8="tomas gomez",$E8="bbva"),$D8,0) -> 0 | N8: =IF(E8="GIRO",D8,0) -> 0 | O8: =IF(E8="DAVIVIENDA",D8,0) -> 0 | P8: =IF(E8="NEQUI TG",E8,0) -> 0 | Q8: =IF(E8="NEQUI AB",D8,0) -> 0 | R8: =IF(E8="NEQUI OTRO",D8,0) -> 0
F9: =IF(E9="EFECTIVO",D9,0) -> 0 | G9: =+IF(E9="ENTREGA",D9,0) -> 0 | H9: =+IF(AND(A9="latas sas",E9="tarjeta"),D9,0) -> 0 | I9: =+IF(AND(A9="tomas gomez",E9="tarjeta"),D9,0) -> 0 | J9: =+IF(AND($A9="latas sas",$E9="bancolombia"),$D9,0) -> 0 | K9: =+IF(AND($A9="tomas gomez",$E9="bancolombia"),$D9,0) -> 0 | L9: =+IF(AND($A9="latas sas",$E9="bbva"),$D9,0) -> 0 | M9: =+IF(AND($A9="tomas gomez",$E9="bbva"),$D9,0) -> 0 | N9: =IF(E9="GIRO",D9,0) -> 0 | O9: =IF(E9="DAVIVIENDA",D9,0) -> 0 | P9: =IF(E9="NEQUI TG",E9,0) -> 0 | Q9: =IF(E9="NEQUI AB",D9,0) -> 0 | R9: =IF(E9="NEQUI OTRO",D9,0) -> 0
F10: =IF(E10="EFECTIVO",D10,0) -> 0 | G10: =+IF(E10="ENTREGA",D10,0) -> 0 | H10: =+IF(AND(A10="latas sas",E10="tarjeta"),D10,0) -> 0 | I10: =+IF(AND(A10="tomas gomez",E10="tarjeta"),D10,0) -> 0 | J10: =+IF(AND($A10="latas sas",$E10="bancolombia"),$D10,0) -> 0 | K10: =+IF(AND($A10="tomas gomez",$E10="bancolombia"),$D10,0) -> 0 | L10: =+IF(AND($A10="latas sas",$E10="bbva"),$D10,0) -> 0 | M10: =+IF(AND($A10="tomas gomez",$E10="bbva"),$D10,0) -> 0 | N10: =IF(E10="GIRO",D10,0) -> 0 | O10: =IF(E10="DAVIVIENDA",D10,0) -> 0 | P10: =IF(E10="NEQUI TG",E10,0) -> 0 | Q10: =IF(E10="NEQUI AB",D10,0) -> 0 | R10: =IF(E10="NEQUI OTRO",D10,0) -> 0
F11: =IF(E11="EFECTIVO",D11,0) -> 0 | G11: =+IF(E11="ENTREGA",D11,0) -> 0 | H11: =+IF(AND(A11="latas sas",E11="tarjeta"),D11,0) -> 0 | I11: =+IF(AND(A11="tomas gomez",E11="tarjeta"),D11,0) -> 0 | J11: =+IF(AND($A11="latas sas",$E11="bancolombia"),$D11,0) -> 0 | K11: =+IF(AND($A11="tomas gomez",$E11="bancolombia"),$D11,0) -> 0 | L11: =+IF(AND($A11="latas sas",$E11="bbva"),$D11,0) -> 0 | M11: =+IF(AND($A11="tomas gomez",$E11="bbva"),$D11,0) -> 0 | N11: =IF(E11="GIRO",D11,0) -> 0 | O11: =IF(E11="DAVIVIENDA",D11,0) -> 0 | P11: =IF(E11="NEQUI TG",E11,0) -> 0 | Q11: =IF(E11="NEQUI AB",D11,0) -> 0 | R11: =IF(E11="NEQUI OTRO",D11,0) -> 0
F12: =IF(E12="EFECTIVO",D12,0) -> 0 | G12: =+IF(E12="ENTREGA",D12,0) -> 0 | H12: =+IF(AND(A12="latas sas",E12="tarjeta"),D12,0) -> 0 | I12: =+IF(AND(A12="tomas gomez",E12="tarjeta"),D12,0) -> 0 | J12: =+IF(AND($A12="latas sas",$E12="bancolombia"),$D12,0) -> 0 | K12: =+IF(AND($A12="tomas gomez",$E12="bancolombia"),$D12,0) -> 0 | L12: =+IF(AND($A12="latas sas",$E12="bbva"),$D12,0) -> 0 | M12: =+IF(AND($A12="tomas gomez",$E12="bbva"),$D12,0) -> 0 | N12: =IF(E12="GIRO",D12,0) -> 0 | O12: =IF(E12="DAVIVIENDA",D12,0) -> 0 | P12: =IF(E12="NEQUI TG",E12,0) -> 0 | Q12: =IF(E12="NEQUI AB",D12,0) -> 0 | R12: =IF(E12="NEQUI OTRO",D12,0) -> 0
F13: =IF(E13="EFECTIVO",D13,0) -> 0 | G13: =+IF(E13="ENTREGA",D13,0) -> 0 | H13: =+IF(AND(A13="latas sas",E13="tarjeta"),D13,0) -> 0 | I13: =+IF(AND(A13="tomas gomez",E13="tarjeta"),D13,0) -> 0 | J13: =+IF(AND($A13="latas sas",$E13="bancolombia"),$D13,0) -> 0 | K13: =+IF(AND($A13="tomas gomez",$E13="bancolombia"),$D13,0) -> 0 | L13: =+IF(AND($A13="latas sas",$E13="bbva"),$D13,0) -> 0 | M13: =+IF(AND($A13="tomas gomez",$E13="bbva"),$D13,0) -> 0 | N13: =IF(E13="GIRO",D13,0) -> 0 | O13: =IF(E13="DAVIVIENDA",D13,0) -> 0 | P13: =IF(E13="NEQUI TG",E13,0) -> 0 | Q13: =IF(E13="NEQUI AB",D13,0) -> 0 | R13: =IF(E13="NEQUI OTRO",D13,0) -> 0
F14: =IF(E14="EFECTIVO",D14,0) -> 0 | G14: =+IF(E14="ENTREGA",D14,0) -> 0 | H14: =+IF(AND(A14="latas sas",E14="tarjeta"),D14,0) -> 0 | I14: =+IF(AND(A14="tomas gomez",E14="tarjeta"),D14,0) -> 0 | J14: =+IF(AND($A14="latas sas",$E14="bancolombia"),$D14,0) -> 0 | K14: =+IF(AND($A14="tomas gomez",$E14="bancolombia"),$D14,0) -> 0 | L14: =+IF(AND($A14="latas sas",$E14="bbva"),$D14,0) -> 0 | M14: =+IF(AND($A14="tomas gomez",$E14="bbva"),$D14,0) -> 0 | N14: =IF(E14="GIRO",D14,0) -> 0 | O14: =IF(E14="DAVIVIENDA",D14,0) -> 0 | P14: =IF(E14="NEQUI TG",E14,0) -> 0 | Q14: =IF(E14="NEQUI AB",D14,0) -> 0 | R14: =IF(E14="NEQUI OTRO",D14,0) -> 0
F15: =IF(E15="EFECTIVO",D15,0) -> 0 | G15: =+IF(E15="ENTREGA",D15,0) -> 0 | H15: =+IF(AND(A15="latas sas",E15="tarjeta"),D15,0) -> 0 | I15: =+IF(AND(A15="tomas gomez",E15="tarjeta"),D15,0) -> 0 | J15: =+IF(AND($A15="latas sas",$E15="bancolombia"),$D15,0) -> 0 | K15: =+IF(AND($A15="tomas gomez",$E15="bancolombia"),$D15,0) -> 0 | L15: =+IF(AND($A15="latas sas",$E15="bbva"),$D15,0) -> 0 | M15: =+IF(AND($A15="tomas gomez",$E15="bbva"),$D15,0) -> 0 | N15: =IF(E15="GIRO",D15,0) -> 0 | O15: =IF(E15="DAVIVIENDA",D15,0) -> 0 | P15: =IF(E15="NEQUI TG",E15,0) -> 0 | Q15: =IF(E15="NEQUI AB",D15,0) -> 0 | R15: =IF(E15="NEQUI OTRO",D15,0) -> 0
F16: =IF(E16="EFECTIVO",D16,0) -> 0 | G16: =+IF(E16="ENTREGA",D16,0) -> 0 | H16: =+IF(AND(A16="latas sas",E16="tarjeta"),D16,0) -> 0 | I16: =+IF(AND(A16="tomas gomez",E16="tarjeta"),D16,0) -> 0 | J16: =+IF(AND($A16="latas sas",$E16="bancolombia"),$D16,0) -> 0 | K16: =+IF(AND($A16="tomas gomez",$E16="bancolombia"),$D16,0) -> 0 | L16: =+IF(AND($A16="latas sas",$E16="bbva"),$D16,0) -> 0 | M16: =+IF(AND($A16="tomas gomez",$E16="bbva"),$D16,0) -> 0 | N16: =IF(E16="GIRO",D16,0) -> 0 | O16: =IF(E16="DAVIVIENDA",D16,0) -> 0 | P16: =IF(E16="NEQUI TG",E16,0) -> 0 | Q16: =IF(E16="NEQUI AB",D16,0) -> 0 | R16: =IF(E16="NEQUI OTRO",D16,0) -> 0
F17: =IF(E17="EFECTIVO",D17,0) -> 0 | G17: =+IF(E17="ENTREGA",D17,0) -> 0 | H17: =+IF(AND(A17="latas sas",E17="tarjeta"),D17,0) -> 0 | I17: =+IF(AND(A17="tomas gomez",E17="tarjeta"),D17,0) -> 0 | J17: =+IF(AND($A17="latas sas",$E17="bancolombia"),$D17,0) -> 0 | K17: =+IF(AND($A17="tomas gomez",$E17="bancolombia"),$D17,0) -> 0 | L17: =+IF(AND($A17="latas sas",$E17="bbva"),$D17,0) -> 0 | M17: =+IF(AND($A17="tomas gomez",$E17="bbva"),$D17,0) -> 0 | N17: =IF(E17="GIRO",D17,0) -> 0 | O17: =IF(E17="DAVIVIENDA",D17,0) -> 0 | P17: =IF(E17="NEQUI TG",E17,0) -> 0 | Q17: =IF(E17="NEQUI AB",D17,0) -> 0 | R17: =IF(E17="NEQUI OTRO",D17,0) -> 0
... F51: =IF(E51="EFECTIVO",D51,0) -> 0 | G51: =+IF(E51="ENTREGA",D51,0) -> 0 | H51: =+IF(AND(A51="latas sas",E51="tarjeta"),D51,0) -> 0 | I51: =+IF(AND(A51="tomas gomez",E51="tarjeta"),D51,0) -> 0 | J51: =+IF(AND($A51="latas sas",$E51="bancolombia"),$D51,0) -> 0 | K51: =+IF(AND($A51="tomas gomez",$E51="bancolombia"),$D51,0) -> 0 | L51: =+IF(AND($A51="latas sas",$E51="bbva"),$D51,0) -> 0 | M51: =+IF(AND($A51="tomas gomez",$E51="bbva"),$D51,0) -> 0 | N51: =IF(E51="GIRO",D51,0) -> 0 | O51: =IF(E51="DAVIVIENDA",D51,0) -> 0 | P51: =IF(E51="NEQUI TG",E51,0) -> 0 | Q51: =IF(E51="NEQUI AB",D51,0) -> 0 | R51: =IF(E51="NEQUI OTRO",D51,0) -> 0

Sheet 2
A1: LATAS Y PARTES DE LA COSTA
C2: CAJA MENOR
C3: CAJA EFECTIVO | D3: =+F3-G3 -> 0 | E3: =(SUM(F3:R3))-G3 -> 7095000 | F3: =SUM(F5:F50) -> 2369000 | G3: =SUM(G5:G50) -> 2369000 | H3: =SUM(H5:H50) -> 1380000 | I3: =SUM(I5:I50) -> 0 | J3: =SUM(J5:J50) -> 2536000 | K3: =SUM(K5:K50) -> 810000 | L3: =SUM(L5:L50) -> 0 | M3: =SUM(M5:M50) -> 0 | ... R3: =SUM(R5:R50) -> 0
A4: EMPRESA | B4: FACTURA | C4: DESCRIPCIÓN | D4: VALOR | E4: FORMA PAGO | F4: EFECTIVO | G4: ENTREGA | H4: TARJETA LATAS | I4: TARJETA TOMAS | J4: BANCOLOMBIA LATAS | K4: BANCOLOMBIA TOMAS | L4: BBVA LATAS | M4: BBVA TOMAS | N4: GIRO | O4: DAVIVIENDA | P4: NEQUI TG | Q4: NEQUI AB | R4: NEQUI OTRO
A5: LATAS SAS | B5: 14079 | C5: CHEVR AVEO EMOTION SOPORTE DEF TRAS | D5: 140000 | E5: TARJETA | F5: =IF(E5="EFECTIVO",D5,0) -> 0 | G5: =+IF(E5="ENTREGA",D5,0) -> 0 | H5: =+IF(AND(A5="latas sas",E5="tarjeta"),D5,0) -> 140000 | I5: =+IF(AND(A5="tomas gomez",E5="tarjeta"),D5,0) -> 0 | J5: =+IF(AND($A5="latas sas",$E5="bancolombia"),$D5,0) -> 0 | K5: =+IF(AND($A5="tomas gomez",$E5="bancolombia"),$D5,0) -> 0 | L5: =+IF(AND($A5="latas sas",$E5="bbva"),$D5,0) -> 0 | M5: =+IF(AND($A5="tomas gomez",$E5="bbva"),$D5,0) -> 0 | N5: =IF(E5="GIRO",D5,0) -> 0 | O5: =IF(E5="DAVIVIENDA",D5,0) -> 0 | P5: =IF(E5="NEQUI TG",D5,0) -> 0 | Q5: =IF(E5="NEQUI AB",D5,0) -> 0 | R5: =IF(E5="NEQUI OTRO",D5,0) -> 0
A6: LATAS SAS | B6: 14080 | C6: KIA SPORTAGE FQ KIT EXPLORADORAS | D6: 170000 | E6: TARJETA | F6: =IF(E6="EFECTIVO",D6,0) -> 0 | G6: =+IF(E6="ENTREGA",D6,0) -> 0 | H6: =+IF(AND(A6="latas sas",E6="tarjeta"),D6,0) -> 170000 | I6: =+IF(AND(A6="tomas gomez",E6="tarjeta"),D6,0) -> 0 | J6: =+IF(AND($A6="latas sas",$E6="bancolombia"),$D6,0) -> 0 | K6: =+IF(AND($A6="tomas gomez",$E6="bancolombia"),$D6,0) -> 0 | L6: =+IF(AND($A6="latas sas",$E6="bbva"),$D6,0) -> 0 | M6: =+IF(AND($A6="tomas gomez",$E6="bbva"),$D6,0) -> 0 | N6: =IF(E6="GIRO",D6,0) -> 0 | O6: =IF(E6="DAVIVIENDA",D6,0) -> 0 | P6: =IF(E6="NEQUI TG",E6,0) -> 0 | Q6: =IF(E6="NEQUI AB",D6,0) -> 0 | R6: =IF(E6="NEQUI OTRO",D6,0) -> 0
A7: LATAS SAS | B7: 14081 | C7: CHEVR CRONOS TRAVIESA SUPERIOR | D7: 130000 | E7: BANCOLOMBIA | F7: =IF(E7="EFECTIVO",D7,0) -> 0 | G7: =+IF(E7="ENTREGA",D7,0) -> 0 | H7: =+IF(AND(A7="latas sas",E7="tarjeta"),D7,0) -> 0 | I7: =+IF(AND(A7="tomas gomez",E7="tarjeta"),D7,0) -> 0 | J7: =+IF(AND($A7="latas sas",$E7="bancolombia"),$D7,0) -> 130000 | K7: =+IF(AND($A7="tomas gomez",$E7="bancolombia"),$D7,0) -> 0 | L7: =+IF(AND($A7="latas sas",$E7="bbva"),$D7,0) -> 0 | M7: =+IF(AND($A7="tomas gomez",$E7="bbva"),$D7,0) -> 0 | N7: =IF(E7="GIRO",D7,0) -> 0 | O7: =IF(E7="DAVIVIENDA",D7,0) -> 0 | P7: =IF(E7="NEQUI TG",E7,0) -> 0 | Q7: =IF(E7="NEQUI AB",D7,0) -> 0 | R7: =IF(E7="NEQUI OTRO",D7,0) -> 0
A8: LATAS SAS | B8: 14082 | C8: KIA ION 12/14 DEF DEL C/REJILLA / TAPA EXPLORAD LH C/H | D8: 270000 | E8: BANCOLOMBIA | F8: =IF(E8="EFECTIVO",D8,0) -> 0 | G8: =+IF(E8="ENTREGA",D8,0) -> 0 | H8: =+IF(AND(A8="latas sas",E8="tarjeta"),D8,0) -> 0 | I8: =+IF(AND(A8="tomas gomez",E8="tarjeta"),D8,0) -> 0 | J8: =+IF(AND($A8="latas sas",$E8="bancolombia"),$D8,0) -> 270000 | K8: =+IF(AND($A8="tomas gomez",$E8="bancolombia"),$D8,0) -> 0 | L8: =+IF(AND($A8="latas sas",$E8="bbva"),$D8,0) -> 0 | M8: =+IF(AND($A8="tomas gomez",$E8="bbva"),$D8,0) -> 0 | N8: =IF(E8="GIRO",D8,0) -> 0 | O8: =IF(E8="DAVIVIENDA",D8,0) -> 0 | P8: =IF(E8="NEQUI TG",E8,0) -> 0 | Q8: =IF(E8="NEQUI AB",D8,0) -> 0 | R8: =IF(E8="NEQUI OTRO",D8,0) -> 0
A9: TOMAS GOMEZ | B9: 6417 | C9: HY GRAN I10 LUNA LH | D9: 30000 | E9: EFECTIVO | F9: =IF(E9="EFECTIVO",D9,0) -> 30000 | G9: =+IF(E9="ENTREGA",D9,0) -> 0 | H9: =+IF(AND(A9="latas sas",E9="tarjeta"),D9,0) -> 0 | I9: =+IF(AND(A9="tomas gomez",E9="tarjeta"),D9,0) -> 0 | J9: =+IF(AND($A9="latas sas",$E9="bancolombia"),$D9,0) -> 0 | K9: =+IF(AND($A9="tomas gomez",$E9="bancolombia"),$D9,0) -> 0 | L9: =+IF(AND($A9="latas sas",$E9="bbva"),$D9,0) -> 0 | M9: =+IF(AND($A9="tomas gomez",$E9="bbva"),$D9,0) -> 0 | N9: =IF(E9="GIRO",D9,0) -> 0 | O9: =IF(E9="DAVIVIENDA",D9,0) -> 0 | P9: =IF(E9="NEQUI TG",E9,0) -> 0 | Q9: =IF(E9="NEQUI AB",D9,0) -> 0 | R9: =IF(E9="NEQUI OTRO",D9,0) -> 0
A10: LATAS SAS | B10: 14083 | C10: CHEVR CRONOS LAMP RH/LH / BOMBILLO H4 | D10: 245000 | E10: EFECTIVO | F10: =IF(E10="EFECTIVO",D10,0) -> 245000 | G10: =+IF(E10="ENTREGA",D10,0) -> 0 | H10: =+IF(AND(A10="latas sas",E10="tarjeta"),D10,0) -> 0 | I10: =+IF(AND(A10="tomas gomez",E10="tarjeta"),D10,0) -> 0 | J10: =+IF(AND($A10="latas sas",$E10="bancolombia"),$D10,0) -> 0 | K10: =+IF(AND($A10="tomas gomez",$E10="bancolombia"),$D10,0) -> 0 | L10: =+IF(AND($A10="latas sas",$E10="bbva"),$D10,0) -> 0 | M10: =+IF(AND($A10="tomas gomez",$E10="bbva"),$D10,0) -> 0 | N10: =IF(E10="GIRO",D10,0) -> 0 | O10: =IF(E10="DAVIVIENDA",D10,0) -> 0 | P10: =IF(E10="NEQUI TG",E10,0) -> 0 | Q10: =IF(E10="NEQUI AB",D10,0) -> 0 | R10: =IF(E10="NEQUI OTRO",D10,0) -> 0
A11: LATAS SAS | B11: 14084 | C11: CHEVR SPARK GT FRONTAL / 11/13 EXPLORAD RH | D11: 480000 | E11: TARJETA | F11: =IF(E11="EFECTIVO",D11,0) -> 0 | G11: =+IF(E11="ENTREGA",D11,0) -> 0 | H11: =+IF(AND(A11="latas sas",E11="tarjeta"),D11,0) -> 480000 | I11: =+IF(AND(A11="tomas gomez",E11="tarjeta"),D11,0) -> 0 | J11: =+IF(AND($A11="latas sas",$E11="bancolombia"),$D11,0) -> 0 | K11: =+IF(AND($A11="tomas gomez",$E11="bancolombia"),$D11,0) -> 0 | L11: =+IF(AND($A11="latas sas",$E11="bbva"),$D11,0) -> 0 | M11: =+IF(AND($A11="tomas gomez",$E11="bbva"),$D11,0) -> 0 | N11: =IF(E11="GIRO",D11,0) -> 0 | O11: =IF(E11="DAVIVIENDA",D11,0) -> 0 | P11: =IF(E11="NEQUI TG",E11,0) -> 0 | Q11: =IF(E11="NEQUI AB",D11,0) -> 0 | R11: =IF(E11="NEQUI OTRO",D11,0) -> 0
A12: LATAS SAS | B12: 14085 | C12: HY ATOS LAMP RH | D12: 90000 | E12: TARJETA | F12: =IF(E12="EFECTIVO",D12,0) -> 0 | G12: =+IF(E12="ENTREGA",D12,0) -> 0 | H12: =+IF(AND(A12="latas sas",E12="tarjeta"),D12,0) -> 90000 | I12: =+IF(AND(A12="tomas gomez",E12="tarjeta"),D12,0) -> 0 | J12: =+IF(AND($A12="latas sas",$E12="bancolombia"),$D12,0) -> 0 | K12: =+IF(AND($A12="tomas gomez",$E12="bancolombia"),$D12,0) -> 0 | L12: =+IF(AND($A12="latas sas",$E12="bbva"),$D12,0) -> 0 | M12: =+IF(AND($A12="tomas gomez",$E12="bbva"),$D12,0) -> 0 | N12: =IF(E12="GIRO",D12,0) -> 0 | O12: =IF(E12="DAVIVIENDA",D12,0) -> 0 | P12: =IF(E12="NEQUI TG",E12,0) -> 0 | Q12: =IF(E12="NEQUI AB",D12,0) -> 0 | R12: =IF(E12="NEQUI OTRO",D12,0) -> 0
A13: LATAS SAS | B13: 14086 | C13: KIA MORNING DEF DEL | D13: 150000 | E13: EFECTIVO | F13: =IF(E13="EFECTIVO",D13,0) -> 150000 | G13: =+IF(E13="ENTREGA",D13,0) -> 0 | H13: =+IF(AND(A13="latas sas",E13="tarjeta"),D13,0) -> 0 | I13: =+IF(AND(A13="tomas gomez",E13="tarjeta"),D13,0) -> 0 | J13: =+IF(AND($A13="latas sas",$E13="bancolombia"),$D13,0) -> 0 | K13: =+IF(AND($A13="tomas gomez",$E13="bancolombia"),$D13,0) -> 0 | L13: =+IF(AND($A13="latas sas",$E13="bbva"),$D13,0) -> 0 | M13: =+IF(AND($A13="tomas gomez",$E13="bbva"),$D13,0) -> 0 | N13: =IF(E13="GIRO",D13,0) -> 0 | O13: =IF(E13="DAVIVIENDA",D13,0) -> 0 | P13: =IF(E13="NEQUI TG",E13,0) -> 0 | Q13: =IF(E13="NEQUI AB",D13,0) -> 0 | R13: =IF(E13="NEQUI OTRO",D13,0) -> 0
A14: LATAS SAS | B14: 14087 | C14: TOYOTA HILUX 89/97 BABERO 4X2 | D14: 180000 | E14: EFECTIVO | F14: =IF(E14="EFECTIVO",D14,0) -> 180000 | G14: =+IF(E14="ENTREGA",D14,0) -> 0 | H14: =+IF(AND(A14="latas sas",E14="tarjeta"),D14,0) -> 0 | I14: =+IF(AND(A14="tomas gomez",E14="tarjeta"),D14,0) -> 0 | J14: =+IF(AND($A14="latas sas",$E14="bancolombia"),$D14,0) -> 0 | K14: =+IF(AND($A14="tomas gomez",$E14="bancolombia"),$D14,0) -> 0 | L14: =+IF(AND($A14="latas sas",$E14="bbva"),$D14,0) -> 0 | M14: =+IF(AND($A14="tomas gomez",$E14="bbva"),$D14,0) -> 0 | N14: =IF(E14="GIRO",D14,0) -> 0 | O14: =IF(E14="DAVIVIENDA",D14,0) -> 0 | P14: =IF(E14="NEQUI TG",E14,0) -> 0 | Q14: =IF(E14="NEQUI AB",D14,0) -> 0 | R14: =IF(E14="NEQUI OTRO",D14,0) -> 0
A15: LATAS SAS | B15: 14088 | C15: CHEVR AVEO SOPORTE DEF DEL | D15: 120000 | E15: TARJETA | F15: =IF(E15="EFECTIVO",D15,0) -> 0 | G15: =+IF(E15="ENTREGA",D15,0) -> 0 | H15: =+IF(AND(A15="latas sas",E15="tarjeta"),D15,0) -> 120000 | I15: =+IF(AND(A15="tomas gomez",E15="tarjeta"),D15,0) -> 0 | J15: =+IF(AND($A15="latas sas",$E15="bancolombia"),$D15,0) -> 0 | K15: =+IF(AND($A15="tomas gomez",$E15="bancolombia"),$D15,0) -> 0 | L15: =+IF(AND($A15="latas sas",$E15="bbva"),$D15,0) -> 0 | M15: =+IF(AND($A15="tomas gomez",$E15="bbva"),$D15,0) -> 0 | N15: =IF(E15="GIRO",D15,0) -> 0 | O15: =IF(E15="DAVIVIENDA",D15,0) -> 0 | P15: =IF(E15="NEQUI TG",E15,0) -> 0 | Q15: =IF(E15="NEQUI AB",D15,0) -> 0 | R15: =IF(E15="NEQUI OTRO",D15,0) -> 0
A16: TOMAS GOMEZ | B16: 6418 | C16: NISSAN FRONTIER NP300 17/20 STOP LH DEPO | D16: 260000 | E16: BANCOLOMBIA | F16: =IF(E16="EFECTIVO",D16,0) -> 0 | G16: =+IF(E16="ENTREGA",D16,0) -> 0 | H16: =+IF(AND(A16="latas sas",E16="tarjeta"),D16,0) -> 0 | I16: =+IF(AND(A16="tomas gomez",E16="tarjeta"),D16,0) -> 0 | J16: =+IF(AND($A16="latas sas",$E16="bancolombia"),$D16,0) -> 0 | K16: =+IF(AND($A16="tomas gomez",$E16="bancolombia"),$D16,0) -> 260000 | L16: =+IF(AND($A16="latas sas",$E16="bbva"),$D16,0) -> 0 | M16: =+IF(AND($A16="tomas gomez",$E16="bbva"),$D16,0) -> 0 | N16: =IF(E16="GIRO",D16,0) -> 0 | O16: =IF(E16="DAVIVIENDA",D16,0) -> 0 | P16: =IF(E16="NEQUI TG",E16,0) -> 0 | Q16: =IF(E16="NEQUI AB",D16,0) -> 0 | R16: =IF(E16="NEQUI OTRO",D16,0) -> 0
A17: LATAS SAS | B17: 14089 | C17: MAZDA ALLEGRO DEPOSITO AUX RADIADOR | D17: 80000 | E17: BANCOLOMBIA | F17: =IF(E17="EFECTIVO",D17,0) -> 0 | G17: =+IF(E17="ENTREGA",D17,0) -> 0 | H17: =+IF(AND(A17="latas sas",E17="tarjeta"),D17,0) -> 0 | I17: =+IF(AND(A17="tomas gomez",E17="tarjeta"),D17,0) -> 0 | J17: =+IF(AND($A17="latas sas",$E17="bancolombia"),$D17,0) -> 80000 | K17: =+IF(AND($A17="tomas gomez",$E17="bancolombia"),$D17,0) -> 0 | L17: =+IF(AND($A17="latas sas",$E17="bbva"),$D17,0) -> 0 | M17: =+IF(AND($A17="tomas gomez",$E17="bbva"),$D17,0) -> 0 | N17: =IF(E17="GIRO",D17,0) -> 0 | O17: =IF(E17="DAVIVIENDA",D17,0) -> 0 | P17: =IF(E17="NEQUI TG",E17,0) -> 0 | Q17: =IF(E17="NEQUI AB",D17,0) -> 0 | R17: =IF(E17="NEQUI OTRO",D17,0) -> 0
... A22: LATAS SAS | B22: 14092 | C22: CHEVR SPARK GT BABERO DEF TRAS | D22: 96000 | E22: BANCOLOMBIA | F22: =IF(E22="EFECTIVO",D22,0) -> 0 | G22: =+IF(E22="ENTREGA",D22,0) -> 0 | H22: =+IF(AND(A22="latas sas",E22="tarjeta"),D22,0) -> 0 | I22: =+IF(AND(A22="tomas gomez",E22="tarjeta"),D22,0) -> 0 | J22: =+IF(AND($A22="latas sas",$E22="bancolombia"),$D22,0) -> 96000 | K22: =+IF(AND($A22="tomas gomez",$E22="bancolombia"),$D22,0) -> 0 | L22: =+IF(AND($A22="latas sas",$E22="bbva"),$D22,0) -> 0 | M22: =+IF(AND($A22="tomas gomez",$E22="bbva"),$D22,0) -> 0 | N22: =IF(E22="GIRO",D22,0) -> 0 | O22: =IF(E22="DAVIVIENDA",D22,0) -> 0 | P22: =IF(E22="NEQUI TG",E22,0) -> 0 | Q22: =IF(E22="NEQUI AB",D22,0) -> 0 | R22: =IF(E22="NEQUI OTRO",D22,0) -> 0
C23: DEVOLUCION BABERO DEF TRAS SPARK GT NEQUI SR TOMAS | D23: -140000 | F23: =IF(E23="EFECTIVO",D23,0) -> 0 | G23: =+IF(E23="ENTREGA",D23,0) -> 0 | H23: =+IF(AND(A23="latas sas",E23="tarjeta"),D23,0) -> 0 | I23: =+IF(AND(A23="tomas gomez",E23="tarjeta"),D23,0) -> 0 | J23: =+IF(AND($A23="latas sas",$E23="bancolombia"),$D23,0) -> 0 | K23: =+IF(AND($A23="tomas gomez",$E23="bancolombia"),$D23,0) -> 0 | L23: =+IF(AND($A23="latas sas",$E23="bbva"),$D23,0) -> 0 | M23: =+IF(AND($A23="tomas gomez",$E23="bbva"),$D23,0) -> 0 | N23: =IF(E23="GIRO",D23,0) -> 0 | O23: =IF(E23="DAVIVIENDA",D23,0) -> 0 | P23: =IF(E23="NEQUI TG",E23,0) -> 0 | Q23: =IF(E23="NEQUI AB",D23,0) -> 0 | R23: =IF(E23="NEQUI OTRO",D23,0) -> 0
A24: LATAS SAS | B24: 14093 | C24: KIA ION 16/17 DEF DEL / LAMP RH/LH / GUARDAF LH / RADIADOR / CONDENSADOR / MOTOVENTILADOR /SOPORTE DEF DEL / GUIA DEF DEL RH-LH / FRONTAL / REJILLA DEF / KIT EXPLORADORA | D24: 1220000 | E24: EFECTIVO | F24: =IF(E24="EFECTIVO",D24,0) -> 1220000 | G24: =+IF(E24="ENTREGA",D24,0) -> 0 | H24: =+IF(AND(A24="latas sas",E24="tarjeta"),D24,0) -> 0 | I24: =+IF(AND(A24="tomas gomez",E24="tarjeta"),D24,0) -> 0 | J24: =+IF(AND($A24="latas sas",$E24="bancolombia"),$D24,0) -> 0 | K24: =+IF(AND($A24="tomas gomez",$E24="bancolombia"),$D24,0) -> 0 | L24: =+IF(AND($A24="latas sas",$E24="bbva"),$D24,0) -> 0 | M24: =+IF(AND($A24="tomas gomez",$E24="bbva"),$D24,0) -> 0 | N24: =IF(E24="GIRO",D24,0) -> 0 | O24: =IF(E24="DAVIVIENDA",D24,0) -> 0 | P24: =IF(E24="NEQUI TG",E24,0) -> 0 | Q24: =IF(E24="NEQUI AB",D24,0) -> 0 | R24: =IF(E24="NEQUI OTRO",D24,0) -> 0
A25: LATAS SAS | B25: 14093 | C25: KIA ION 16/17 DEF DEL / LAMP RH/LH / GUARDAF LH / RADIADOR / CONDENSADOR / MOTOVENTILADOR /SOPORTE DEF DEL / GUIA DEF DEL RH-LH / FRONTAL / REJILLA DEF / KIT EXPLORADORA | D25: 1000000 | E25: BANCOLOMBIA | F25: =IF(E25="EFECTIVO",D25,0) -> 0 | G25: =+IF(E25="ENTREGA",D25,0) -> 0 | H25: =+IF(AND(A25="latas sas",E25="tarjeta"),D25,0) -> 0 | I25: =+IF(AND(A25="tomas gomez",E25="tarjeta"),D25,0) -> 0 | J25: =+IF(AND($A25="latas sas",$E25="bancolombia"),$D25,0) -> 1000000 | K25: =+IF(AND($A25="tomas gomez",$E25="bancolombia"),$D25,0) -> 0 | L25: =+IF(AND($A25="latas sas",$E25="bbva"),$D25,0) -> 0 | M25: =+IF(AND($A25="tomas gomez",$E25="bbva"),$D25,0) -> 0 | N25: =IF(E25="GIRO",D25,0) -> 0 | O25: =IF(E25="DAVIVIENDA",D25,0) -> 0 | P25: =IF(E25="NEQUI TG",E25,0) -> 0 | Q25: =IF(E25="NEQUI AB",D25,0) -> 0 | R25: =IF(E25="NEQUI OTRO",D25,0) -> 0
A26: LATAS SAS | B26: 14095 | C26: CHEVR AVEO SEDAN DEF DEL / SOPORTE DEF DEL / PERSIANA | D26: 350000 | E26: BANCOLOMBIA | F26: =IF(E26="EFECTIVO",D26,0) -> 0 | G26: =+IF(E26="ENTREGA",D26,0) -> 0 | H26: =+IF(AND(A26="latas sas",E26="tarjeta"),D26,0) -> 0 | I26: =+IF(AND(A26="tomas gomez",E26="tarjeta"),D26,0) -> 0 | J26: =+IF(AND($A26="latas sas",$E26="bancolombia"),$D26,0) -> 350000 | K26: =+IF(AND($A26="tomas gomez",$E26="bancolombia"),$D26,0) -> 0 | L26: =+IF(AND($A26="latas sas",$E26="bbva"),$D26,0) -> 0 | M26: =+IF(AND($A26="tomas gomez",$E26="bbva"),$D26,0) -> 0 | N26: =IF(E26="GIRO",D26,0) -> 0 | O26: =IF(E26="DAVIVIENDA",D26,0) -> 0 | P26: =IF(E26="NEQUI TG",E26,0) -> 0 | Q26: =IF(E26="NEQUI AB",D26,0) -> 0 | R26: =IF(E26="NEQUI OTRO",D26,0) -> 0
A27: LATAS SAS | B27: 14094 | C27: CHEVR AVEO EMOTION LAMP RH/LH / 1 BOMBILLO 2 CONT | D27: 264000 | E27: EFECTIVO | F27: =IF(E27="EFECTIVO",D27,0) -> 264000 | G27: =+IF(E27="ENTREGA",D27,0) -> 0 | H27: =+IF(AND(A27="latas sas",E27="tarjeta"),D27,0) -> 0 | I27: =+IF(AND(A27="tomas gomez",E27="tarjeta"),D27,0) -> 0 | J27: =+IF(AND($A27="latas sas",$E27="bancolombia"),$D27,0) -> 0 | K27: =+IF(AND($A27="tomas gomez",$E27="bancolombia"),$D27,0) -> 0 | L27: =+IF(AND($A27="latas sas",$E27="bbva"),$D27,0) -> 0 | M27: =+IF(AND($A27="tomas gomez",$E27="bbva"),$D27,0) -> 0 | N27: =IF(E27="GIRO",D27,0) -> 0 | O27: =IF(E27="DAVIVIENDA",D27,0) -> 0 | P27: =IF(E27="NEQUI TG",E27,0) -> 0 | Q27: =IF(E27="NEQUI AB",D27,0) -> 0 | R27: =IF(E27="NEQUI OTRO",D27,0) -> 0
A28: TOMAS GOMEZ | B28: 6419 | C28: MAZDA ALLEGRO HB STOP RH | D28: 240000 | E28: EFECTIVO | F28: =IF(E28="EFECTIVO",D28,0) -> 240000 | G28: =+IF(E28="ENTREGA",D28,0) -> 0 | H28: =+IF(AND(A28="latas sas",E28="tarjeta"),D28,0) -> 0 | I28: =+IF(AND(A28="tomas gomez",E28="tarjeta"),D28,0) -> 0 | J28: =+IF(AND($A28="latas sas",$E28="bancolombia"),$D28,0) -> 0 | K28: =+IF(AND($A28="tomas gomez",$E28="bancolombia"),$D28,0) -> 0 | L28: =+IF(AND($A28="latas sas",$E28="bbva"),$D28,0) -> 0 | M28: =+IF(AND($A28="tomas gomez",$E28="bbva"),$D28,0) -> 0 | N28: =IF(E28="GIRO",D28,0) -> 0 | O28: =IF(E28="DAVIVIENDA",D28,0) -> 0 | P28: =IF(E28="NEQUI TG",E28,0) -> 0 | Q28: =IF(E28="NEQUI AB",D28,0) -> 0 | R28: =IF(E28="NEQUI OTRO",D28,0) -> 0
A29: LATAS SAS | B29: 14096 | C29: CHEVR CRONOS DEF TRAS CREDITO ALBERTO TORRES | D29: 140000 | F29: =IF(E29="EFECTIVO",D29,0) -> 0 | G29: =+IF(E29="ENTREGA",D29,0) -> 0 | H29: =+IF(AND(A29="latas sas",E29="tarjeta"),D29,0) -> 0 | I29: =+IF(AND(A29="tomas gomez",E29="tarjeta"),D29,0) -> 0 | J29: =+IF(AND($A29="latas sas",$E29="bancolombia"),$D29,0) -> 0 | K29: =+IF(AND($A29="tomas gomez",$E29="bancolombia"),$D29,0) -> 0 | L29: =+IF(AND($A29="latas sas",$E29="bbva"),$D29,0) -> 0 | M29: =+IF(AND($A29="tomas gomez",$E29="bbva"),$D29,0) -> 0 | N29: =IF(E29="GIRO",D29,0) -> 0 | O29: =IF(E29="DAVIVIENDA",D29,0) -> 0 | P29: =IF(E29="NEQUI TG",E29,0) -> 0 | Q29: =IF(E29="NEQUI AB",D29,0) -> 0 | R29: =IF(E29="NEQUI OTRO",D29,0) -> 0
A30: LATAS SAS | B30: 14097 | C30: KIA ION MANIJA INT DEL RH CREDITO ALBERTO TORRES | D30: 35000 | F30: =IF(E30="EFECTIVO",D30,0) -> 0 | G30: =+IF(E30="ENTREGA",D30,0) -> 0 | H30: =+IF(AND(A30="latas sas",E30="tarjeta"),D30,0) -> 0 | I30: =+IF(AND(A30="tomas gomez",E30="tarjeta"),D30,0) -> 0 | J30: =+IF(AND($A30="latas sas",$E30="bancolombia"),$D30,0) -> 0 | K30: =+IF(AND($A30="tomas gomez",$E30="bancolombia"),$D30,0) -> 0 | L30: =+IF(AND($A30="latas sas",$E30="bbva"),$D30,0) -> 0 | M30: =+IF(AND($A30="tomas gomez",$E30="bbva"),$D30,0) -> 0 | N30: =IF(E30="GIRO",D30,0) -> 0 | O30: =IF(E30="DAVIVIENDA",D30,0) -> 0 | P30: =IF(E30="NEQUI TG",E30,0) -> 0 | Q30: =IF(E30="NEQUI AB",D30,0) -> 0 | R30: =IF(E30="NEQUI OTRO",D30,0) -> 0
A31: LATAS SAS | B31: 14098 | C31: HY I10 GUARDAF RH/LH | D31: 300000 | E31: BANCOLOMBIA | F31: =IF(E31="EFECTIVO",D31,0) -> 0 | G31: =+IF(E31="ENTREGA",D31,0) -> 0 | H31: =+IF(AND(A31="latas sas",E31="tarjeta"),D31,0) -> 0 | I31: =+IF(AND(A31="tomas gomez",E31="tarjeta"),D31,0) -> 0 | J31: =+IF(AND($A31="latas sas",$E31="bancolombia"),$D31,0) -> 300000 | K31: =+IF(AND($A31="tomas gomez",$E31="bancolombia"),$D31,0) -> 0 | L31: =+IF(AND($A31="latas sas",$E31="bbva"),$D31,0) -> 0 | M31: =+IF(AND($A31="tomas gomez",$E31="bbva"),$D31,0) -> 0 | N31: =IF(E31="GIRO",D31,0) -> 0 | O31: =IF(E31="DAVIVIENDA",D31,0) -> 0 | P31: =IF(E31="NEQUI TG",E31,0) -> 0 | Q31: =IF(E31="NEQUI AB",D31,0) -> 0 | R31: =IF(E31="NEQUI OTRO",D31,0) -> 0
A32: LATAS SAS | B32: 14099 | C32: CHEVR AVEO GUARDAF RH/LH | D32: 380000 | E32: TARJETA | F32: =IF(E32="EFECTIVO",D32,0) -> 0 | G32: =+IF(E32="ENTREGA",D32,0) -> 0 | H32: =+IF(AND(A32="latas sas",E32="tarjeta"),D32,0) -> 380000 | I32: =+IF(AND(A32="tomas gomez",E32="tarjeta"),D32,0) -> 0 | J32: =+IF(AND($A32="latas sas",$E32="bancolombia"),$D32,0) -> 0 | K32: =+IF(AND($A32="tomas gomez",$E32="bancolombia"),$D32,0) -> 0 | L32: =+IF(AND($A32="latas sas",$E32="bbva"),$D32,0) -> 0 | M32: =+IF(AND($A32="tomas gomez",$E32="bbva"),$D32,0) -> 0 | N32: =IF(E32="GIRO",D32,0) -> 0 | O32: =IF(E32="DAVIVIENDA",D32,0) -> 0 | P32: =IF(E32="NEQUI TG",E32,0) -> 0 | Q32: =IF(E32="NEQUI AB",D32,0) -> 0 | R32: =IF(E32="NEQUI OTRO",D32,0) -> 0
D33: 2369000 | E33: ENTREGA | F33: =IF(E33="EFECTIVO",D33,0) -> 0 | G33: =+IF(E33="ENTREGA",D33,0) -> 2369000 | H33: =+IF(AND(A33="latas sas",E33="tarjeta"),D33,0) -> 0 | I33: =+IF(AND(A33="tomas gomez",E33="tarjeta"),D33,0) -> 0 | J33: =+IF(AND($A33="latas sas",$E33="bancolombia"),$D33,0) -> 0 | K33: =+IF(AND($A33="tomas gomez",$E33="bancolombia"),$D33,0) -> 0 | L33: =+IF(AND($A33="latas sas",$E33="bbva"),$D33,0) -> 0 | M33: =+IF(AND($A33="tomas gomez",$E33="bbva"),$D33,0) -> 0 | N33: =IF(E33="GIRO",D33,0) -> 0 | O33: =IF(E33="DAVIVIENDA",D33,0) -> 0 | P33: =IF(E33="NEQUI TG",E33,0) -> 0 | Q33: =IF(E33="NEQUI AB",D33,0) -> 0 | R33: =IF(E33="NEQUI OTRO",D33,0) -> 0
A34: TOMAS GOMEZ | B34: 6420 | C34: TOYOTA FORTUNER LAMP 12/16 LH DEPO | D34: 550000 | E34: BANCOLOMBIA | F34: =IF(E34="EFECTIVO",D34,0) -> 0 | G34: =+IF(E34="ENTREGA",D34,0) -> 0 | H34: =+IF(AND(A34="latas sas",E34="tarjeta"),D34,0) -> 0 | I34: =+IF(AND(A34="tomas gomez",E34="tarjeta"),D34,0) -> 0 | J34: =+IF(AND($A34="latas sas",$E34="bancolombia"),$D34,0) -> 0 | K34: =+IF(AND($A34="tomas gomez",$E34="bancolombia"),$D34,0) -> 550000 | L34: =+IF(AND($A34="latas sas",$E34="bbva"),$D34,0) -> 0 | M34: =+IF(AND($A34="tomas gomez",$E34="bbva"),$D34,0) -> 0 | N34: =IF(E34="GIRO",D34,0) -> 0 | O34: =IF(E34="DAVIVIENDA",D34,0) -> 0 | P34: =IF(E34="NEQUI TG",E34,0) -> 0 | Q34: =IF(E34="NEQUI AB",D34,0) -> 0 | R34: =IF(E34="NEQUI OTRO",D34,0) -> 0
F35: =IF(E35="EFECTIVO",D35,0) -> 0 | G35: =+IF(E35="ENTREGA",D35,0) -> 0 | H35: =+IF(AND(A35="latas sas",E35="tarjeta"),D35,0) -> 0 | I35: =+IF(AND(A35="tomas gomez",E35="tarjeta"),D35,0) -> 0 | J35: =+IF(AND($A35="latas sas",$E35="bancolombia"),$D35,0) -> 0 | K35: =+IF(AND($A35="tomas gomez",$E35="bancolombia"),$D35,0) -> 0 | L35: =+IF(AND($A35="latas sas",$E35="bbva"),$D35,0) -> 0 | M35: =+IF(AND($A35="tomas gomez",$E35="bbva"),$D35,0) -> 0 | N35: =IF(E35="GIRO",D35,0) -> 0 | O35: =IF(E35="DAVIVIENDA",D35,0) -> 0 | P35: =IF(E35="NEQUI TG",E35,0) -> 0 | Q35: =IF(E35="NEQUI AB",D35,0) -> 0 | R35: =IF(E35="NEQUI OTRO",D35,0) -> 0
F36: =IF(E36="EFECTIVO",D36,0) -> 0 | G36: =+IF(E36="ENTREGA",D36,0) -> 0 | H36: =+IF(AND(A36="latas sas",E36="tarjeta"),D36,0) -> 0 | I36: =+IF(AND(A36="tomas gomez",E36="tarjeta"),D36,0) -> 0 | J36: =+IF(AND($A36="latas sas",$E36="bancolombia"),$D36,0) -> 0 | K36: =+IF(AND($A36="tomas gomez",$E36="bancolombia"),$D36,0) -> 0 | L36: =+IF(AND($A36="latas sas",$E36="bbva"),$D36,0) -> 0 | M36: =+IF(AND($A36="tomas gomez",$E36="bbva"),$D36,0) -> 0 | N36: =IF(E36="GIRO",D36,0) -> 0 | O36: =IF(E36="DAVIVIENDA",D36,0) -> 0 | P36: =IF(E36="NEQUI TG",E36,0) -> 0 | Q36: =IF(E36="NEQUI AB",D36,0) -> 0 | R36: =IF(E36="NEQUI OTRO",D36,0) -> 0
F37: =IF(E37="EFECTIVO",D37,0) -> 0 | G37: =+IF(E37="ENTREGA",D37,0) -> 0 | H37: =+IF(AND(A37="latas sas",E37="tarjeta"),D37,0) -> 0 | I37: =+IF(AND(A37="tomas gomez",E37="tarjeta"),D37,0) -> 0 | J37: =+IF(AND($A37="latas sas",$E37="bancolombia"),$D37,0) -> 0 | K37: =+IF(AND($A37="tomas gomez",$E37="bancolombia"),$D37,0) -> 0 | L37: =+IF(AND($A37="latas sas",$E37="bbva"),$D37,0) -> 0 | M37: =+IF(AND($A37="tomas gomez",$E37="bbva"),$D37,0) -> 0 | N37: =IF(E37="GIRO",D37,0) -> 0 | O37: =IF(E37="DAVIVIENDA",D37,0) -> 0 | P37: =IF(E37="NEQUI TG",E37,0) -> 0 | Q37: =IF(E37="NEQUI AB",D37,0) -> 0 | R37: =IF(E37="NEQUI OTRO",D37,0) -> 0
F38: =IF(E38="EFECTIVO",D38,0) -> 0 | G38: =+IF(E38="ENTREGA",D38,0) -> 0 | H38: =+IF(AND(A38="latas sas",E38="tarjeta"),D38,0) -> 0 | I38: =+IF(AND(A38="tomas gomez",E38="tarjeta"),D38,0) -> 0 | J38: =+IF(AND($A38="latas sas",$E38="bancolombia"),$D38,0) -> 0 | K38: =+IF(AND($A38="tomas gomez",$E38="bancolombia"),$D38,0) -> 0 | L38: =+IF(AND($A38="latas sas",$E38="bbva"),$D38,0) -> 0 | M38: =+IF(AND($A38="tomas gomez",$E38="bbva"),$D38,0) -> 0 | N38: =IF(E38="GIRO",D38,0) -> 0 | O38: =IF(E38="DAVIVIENDA",D38,0) -> 0 | P38: =IF(E38="NEQUI TG",E38,0) -> 0 | Q38: =IF(E38="NEQUI AB",D38,0) -> 0 | R38: =IF(E38="NEQUI OTRO",D38,0) -> 0
F39: =IF(E39="EFECTIVO",D39,0) -> 0 | G39: =+IF(E39="ENTREGA",D39,0) -> 0 | H39: =+IF(AND(A39="latas sas",E39="tarjeta"),D39,0) -> 0 | I39: =+IF(AND(A39="tomas gomez",E39="tarjeta"),D39,0) -> 0 | J39: =+IF(AND($A39="latas sas",$E39="bancolombia"),$D39,0) -> 0 | K39: =+IF(AND($A39="tomas gomez",$E39="bancolombia"),$D39,0) -> 0 | L39: =+IF(AND($A39="latas sas",$E39="bbva"),$D39,0) -> 0 | M39: =+IF(AND($A39="tomas gomez",$E39="bbva"),$D39,0) -> 0 | N39: =IF(E39="GIRO",D39,0) -> 0 | O39: =IF(E39="DAVIVIENDA",D39,0) -> 0 | P39: =IF(E39="NEQUI TG",E39,0) -> 0 | Q39: =IF(E39="NEQUI AB",D39,0) -> 0 | R39: =IF(E39="NEQUI OTRO",D39,0) -> 0
F40: =IF(E40="EFECTIVO",D40,0) -> 0 | G40: =+IF(E40="ENTREGA",D40,0) -> 0 | H40: =+IF(AND(A40="latas sas",E40="tarjeta"),D40,0) -> 0 | I40: =+IF(AND(A40="tomas gomez",E40="tarjeta"),D40,0) -> 0 | J40: =+IF(AND($A40="latas sas",$E40="bancolombia"),$D40,0) -> 0 | K40: =+IF(AND($A40="tomas gomez",$E40="bancolombia"),$D40,0) -> 0 | L40: =+IF(AND($A40="latas sas",$E40="bbva"),$D40,0) -> 0 | M40: =+IF(AND($A40="tomas gomez",$E40="bbva"),$D40,0) -> 0 | N40: =IF(E40="GIRO",D40,0) -> 0 | O40: =IF(E40="DAVIVIENDA",D40,0) -> 0 | P40: =IF(E40="NEQUI TG",E40,0) -> 0 | Q40: =IF(E40="NEQUI AB",D40,0) -> 0 | R40: =IF(E40="NEQUI OTRO",D40,0) -> 0
F41: =IF(E41="EFECTIVO",D41,0) -> 0 | G41: =+IF(E41="ENTREGA",D41,0) -> 0 | H41: =+IF(AND(A41="latas sas",E41="tarjeta"),D41,0) -> 0 | I41: =+IF(AND(A41="tomas gomez",E41="tarjeta"),D41,0) -> 0 | J41: =+IF(AND($A41="latas sas",$E41="bancolombia"),$D41,0) -> 0 | K41: =+IF(AND($A41="tomas gomez",$E41="bancolombia"),$D41,0) -> 0 | L41: =+IF(AND($A41="latas sas",$E41="bbva"),$D41,0) -> 0 | M41: =+IF(AND($A41="tomas gomez",$E41="bbva"),$D41,0) -> 0 | N41: =IF(E41="GIRO",D41,0) -> 0 | O41: =IF(E41="DAVIVIENDA",D41,0) -> 0 | P41: =IF(E41="NEQUI TG",E41,0) -> 0 | Q41: =IF(E41="NEQUI AB",D41,0) -> 0 | R41: =IF(E41="NEQUI OTRO",D41,0) -> 0
F42: =IF(E42="EFECTIVO",D42,0) -> 0 | G42: =+IF(E42="ENTREGA",D42,0) -> 0 | H42: =+IF(AND(A42="latas sas",E42="tarjeta"),D42,0) -> 0 | I42: =+IF(AND(A42="tomas gomez",E42="tarjeta"),D42,0) -> 0 | J42: =+IF(AND($A42="latas sas",$E42="bancolombia"),$D42,0) -> 0 | K42: =+IF(AND($A42="tomas gomez",$E42="bancolombia"),$D42,0) -> 0 | L42: =+IF(AND($A42="latas sas",$E42="bbva"),$D42,0) -> 0 | M42: =+IF(AND($A42="tomas gomez",$E42="bbva"),$D42,0) -> 0 | N42: =IF(E42="GIRO",D42,0) -> 0 | O42: =IF(E42="DAVIVIENDA",D42,0) -> 0 | P42: =IF(E42="NEQUI TG",E42,0) -> 0 | Q42: =IF(E42="NEQUI AB",D42,0) -> 0 | R42: =IF(E42="NEQUI OTRO",D42,0) -> 0
F43: =IF(E43="EFECTIVO",D43,0) -> 0 | G43: =+IF(E43="ENTREGA",D43,0) -> 0 | H43: =+IF(AND(A43="latas sas",E43="tarjeta"),D43,0) -> 0 | I43: =+IF(AND(A43="tomas gomez",E43="tarjeta"),D43,0) -> 0 | J43: =+IF(AND($A43="latas sas",$E43="bancolombia"),$D43,0) -> 0 | K43: =+IF(AND($A43="tomas gomez",$E43="bancolombia"),$D43,0) -> 0 | L43: =+IF(AND($A43="latas sas",$E43="bbva"),$D43,0) -> 0 | M43: =+IF(AND($A43="tomas gomez",$E43="bbva"),$D43,0) -> 0 | N43: =IF(E43="GIRO",D43,0) -> 0 | O43: =IF(E43="DAVIVIENDA",D43,0) -> 0 | P43: =IF(E43="NEQUI TG",E43,0) -> 0 | Q43: =IF(E43="NEQUI AB",D43,0) -> 0 | R43: =IF(E43="NEQUI OTRO",D43,0) -> 0
F44: =IF(E44="EFECTIVO",D44,0) -> 0 | G44: =+IF(E44="ENTREGA",D44,0) -> 0 | H44: =+IF(AND(A44="latas sas",E44="tarjeta"),D44,0) -> 0 | I44: =+IF(AND(A44="tomas gomez",E44="tarjeta"),D44,0) -> 0 | J44: =+IF(AND($A44="latas sas",$E44="bancolombia"),$D44,0) -> 0 | K44: =+IF(AND($A44="tomas gomez",$E44="bancolombia"),$D44,0) -> 0 | L44: =+IF(AND($A44="latas sas",$E44="bbva"),$D44,0) -> 0 | M44: =+IF(AND($A44="tomas gomez",$E44="bbva"),$D44,0) -> 0 | N44: =IF(E44="GIRO",D44,0) -> 0 | O44: =IF(E44="DAVIVIENDA",D44,0) -> 0 | P44: =IF(E44="NEQUI TG",E44,0) -> 0 | Q44: =IF(E44="NEQUI AB",D44,0) -> 0 | R44: =IF(E44="NEQUI OTRO",D44,0) -> 0
...

Sheet 3
A1: LATAS Y PARTES DE LA COSTA
C2: CAJA MENOR
C3: CAJA EFECTIVO | D3: =+F3-G3 -> 0 | E3: =(SUM(F3:R3))-G3 -> 8468000 | F3: =SUM(F5:F50) -> 2795000 | G3: =SUM(G5:G50) -> 2795000 | H3: =SUM(H5:H50) -> 1226000 | I3: =SUM(I5:I50) -> 440000 | J3: =SUM(J5:J50) -> 2637000 | K3: =SUM(K5:K50) -> 1370000 | L3: =SUM(L5:L50) -> 0 | M3: =SUM(M5:M50) -> 0 | ... R3: =SUM(R5:R50) -> 0
A4: EMPRESA | B4: FACTURA | C4: DESCRIPCIÓN | D4: VALOR | E4: FORMA PAGO | F4: EFECTIVO | G4: ENTREGA | H4: TARJETA LATAS | I4: TARJETA TOMAS | J4: BANCOLOMBIA LATAS | K4: BANCOLOMBIA TOMAS | L4: BBVA LATAS | M4: BBVA TOMAS | N4: GIRO | O4: DAVIVIENDA | P4: NEQUI TG | Q4: NEQUI AB | R4: NEQUI OTRO
A5: LATAS SAS | B5: 14100 | C5: RENAULT LOGAN SANDERO AMORTIGUADORES DELANTEROS | D5: 220000 | E5: EFECTIVO | F5: =IF(E5="EFECTIVO",D5,0) -> 220000 | G5: =+IF(E5="ENTREGA",D5,0) -> 0 | H5: =+IF(AND(A5="latas sas",E5="tarjeta"),D5,0) -> 0 | I5: =+IF(AND(A5="tomas gomez",E5="tarjeta"),D5,0) -> 0 | J5: =+IF(AND($A5="latas sas",$E5="bancolombia"),$D5,0) -> 0 | K5: =+IF(AND($A5="tomas gomez",$E5="bancolombia"),$D5,0) -> 0 | L5: =+IF(AND($A5="latas sas",$E5="bbva"),$D5,0) -> 0 | M5: =+IF(AND($A5="tomas gomez",$E5="bbva"),$D5,0) -> 0 | N5: =IF(E5="GIRO",D5,0) -> 0 | O5: =IF(E5="DAVIVIENDA",D5,0) -> 0 | P5: =IF(E5="NEQUI TG",D5,0) -> 0 | Q5: =IF(E5="NEQUI AB",D5,0) -> 0 | R5: =IF(E5="NEQUI OTRO",D5,0) -> 0
A6: TOMAS GOMEZ | B6: 6421 | C6: HY ATOS STOP LH DEPO | D6: 125000 | E6: EFECTIVO | F6: =IF(E6="EFECTIVO",D6,0) -> 125000 | G6: =+IF(E6="ENTREGA",D6,0) -> 0 | H6: =+IF(AND(A6="latas sas",E6="tarjeta"),D6,0) -> 0 | I6: =+IF(AND(A6="tomas gomez",E6="tarjeta"),D6,0) -> 0 | J6: =+IF(AND($A6="latas sas",$E6="bancolombia"),$D6,0) -> 0 | K6: =+IF(AND($A6="tomas gomez",$E6="bancolombia"),$D6,0) -> 0 | L6: =+IF(AND($A6="latas sas",$E6="bbva"),$D6,0) -> 0 | M6: =+IF(AND($A6="tomas gomez",$E6="bbva"),$D6,0) -> 0 | N6: =IF(E6="GIRO",D6,0) -> 0 | O6: =IF(E6="DAVIVIENDA",D6,0) -> 0 | P6: =IF(E6="NEQUI TG",E6,0) -> 0 | Q6: =IF(E6="NEQUI AB",D6,0) -> 0 | R6: =IF(E6="NEQUI OTRO",D6,0) -> 0
A7: LATAS SAS | B7: 14101 | C7: CHEVR SAIL TRAVIESA INF | D7: 200000 | E7: BANCOLOMBIA | F7: =IF(E7="EFECTIVO",D7,0) -> 0 | G7: =+IF(E7="ENTREGA",D7,0) -> 0 | H7: =+IF(AND(A7="latas sas",E7="tarjeta"),D7,0) -> 0 | I7: =+IF(AND(A7="tomas gomez",E7="tarjeta"),D7,0) -> 0 | J7: =+IF(AND($A7="latas sas",$E7="bancolombia"),$D7,0) -> 200000 | K7: =+IF(AND($A7="tomas gomez",$E7="bancolombia"),$D7,0) -> 0 | L7: =+IF(AND($A7="latas sas",$E7="bbva"),$D7,0) -> 0 | M7: =+IF(AND($A7="tomas gomez",$E7="bbva"),$D7,0) -> 0 | N7: =IF(E7="GIRO",D7,0) -> 0 | O7: =IF(E7="DAVIVIENDA",D7,0) -> 0 | P7: =IF(E7="NEQUI TG",E7,0) -> 0 | Q7: =IF(E7="NEQUI AB",D7,0) -> 0 | R7: =IF(E7="NEQUI OTRO",D7,0) -> 0
A8: TOMAS GOMEZ | B8: 6422 | C8: NISSAN FRONTIER STOP LH BICOLOR | D8: 70000 | E8: BANCOLOMBIA | F8: =IF(E8="EFECTIVO",D8,0) -> 0 | G8: =+IF(E8="ENTREGA",D8,0) -> 0 | H8: =+IF(AND(A8="latas sas",E8="tarjeta"),D8,0) -> 0 | I8: =+IF(AND(A8="tomas gomez",E8="tarjeta"),D8,0) -> 0 | J8: =+IF(AND($A8="latas sas",$E8="bancolombia"),$D8,0) -> 0 | K8: =+IF(AND($A8="tomas gomez",$E8="bancolombia"),$D8,0) -> 70000 | L8: =+IF(AND($A8="latas sas",$E8="bbva"),$D8,0) -> 0 | M8: =+IF(AND($A8="tomas gomez",$E8="bbva"),$D8,0) -> 0 | N8: =IF(E8="GIRO",D8,0) -> 0 | O8: =IF(E8="DAVIVIENDA",D8,0) -> 0 | P8: =IF(E8="NEQUI TG",E8,0) -> 0 | Q8: =IF(E8="NEQUI AB",D8,0) -> 0 | R8: =IF(E8="NEQUI OTRO",D8,0) -> 0
A9: LATAS SAS | B9: 14102 | C9: RENAULT LOGAN SANDERO 16/20 TAPA RETROV RH C/L / PLUMILLA 20/22 SILICONA | D9: 70000 | E9: BANCOLOMBIA | F9: =IF(E9="EFECTIVO",D9,0) -> 0 | G9: =+IF(E9="ENTREGA",D9,0) -> 0 | H9: =+IF(AND(A9="latas sas",E9="tarjeta"),D9,0) -> 0 | I9: =+IF(AND(A9="tomas gomez",E9="tarjeta"),D9,0) -> 0 | J9: =+IF(AND($A9="latas sas",$E9="bancolombia"),$D9,0) -> 70000 | K9: =+IF(AND($A9="tomas gomez",$E9="bancolombia"),$D9,0) -> 0 | L9: =+IF(AND($A9="latas sas",$E9="bbva"),$D9,0) -> 0 | M9: =+IF(AND($A9="tomas gomez",$E9="bbva"),$D9,0) -> 0 | N9: =IF(E9="GIRO",D9,0) -> 0 | O9: =IF(E9="DAVIVIENDA",D9,0) -> 0 | P9: =IF(E9="NEQUI TG",E9,0) -> 0 | Q9: =IF(E9="NEQUI AB",D9,0) -> 0 | R9: =IF(E9="NEQUI OTRO",D9,0) -> 0
A10: LATAS SAS | B10: 14121 | C10: MAZDA CX5 PASO RUEDA LH | D10: 130000 | E10: TARJETA | F10: =IF(E10="EFECTIVO",D10,0) -> 0 | G10: =+IF(E10="ENTREGA",D10,0) -> 0 | H10: =+IF(AND(A10="latas sas",E10="tarjeta"),D10,0) -> 130000 | I10: =+IF(AND(A10="tomas gomez",E10="tarjeta"),D10,0) -> 0 | J10: =+IF(AND($A10="latas sas",$E10="bancolombia"),$D10,0) -> 0 | K10: =+IF(AND($A10="tomas gomez",$E10="bancolombia"),$D10,0) -> 0 | L10: =+IF(AND($A10="latas sas",$E10="bbva"),$D10,0) -> 0 | M10: =+IF(AND($A10="tomas gomez",$E10="bbva"),$D10,0) -> 0 | N10: =IF(E10="GIRO",D10,0) -> 0 | O10: =IF(E10="DAVIVIENDA",D10,0) -> 0 | P10: =IF(E10="NEQUI TG",E10,0) -> 0 | Q10: =IF(E10="NEQUI AB",D10,0) -> 0 | R10: =IF(E10="NEQUI OTRO",D10,0) -> 0
A11: LATAS SAS | B11: 14103 | C11: HY ATOS GUARDAF RH / DEF DEL | D11: 320000 | E11: EFECTIVO | F11: =IF(E11="EFECTIVO",D11,0) -> 320000 | G11: =+IF(E11="ENTREGA",D11,0) -> 0 | H11: =+IF(AND(A11="latas sas",E11="tarjeta"),D11,0) -> 0 | I11: =+IF(AND(A11="tomas gomez",E11="tarjeta"),D11,0) -> 0 | J11: =+IF(AND($A11="latas sas",$E11="bancolombia"),$D11,0) -> 0 | K11: =+IF(AND($A11="tomas gomez",$E11="bancolombia"),$D11,0) -> 0 | L11: =+IF(AND($A11="latas sas",$E11="bbva"),$D11,0) -> 0 | M11: =+IF(AND($A11="tomas gomez",$E11="bbva"),$D11,0) -> 0 | N11: =IF(E11="GIRO",D11,0) -> 0 | O11: =IF(E11="DAVIVIENDA",D11,0) -> 0 | P11: =IF(E11="NEQUI TG",E11,0) -> 0 | Q11: =IF(E11="NEQUI AB",D11,0) -> 0 | R11: =IF(E11="NEQUI OTRO",D11,0) -> 0
A12: LATAS SAS | B12: 14104 | C12: HY ATOS RETROV RH | D12: 70000 | E12: EFECTIVO | F12: =IF(E12="EFECTIVO",D12,0) -> 70000 | G12: =+IF(E12="ENTREGA",D12,0) -> 0 | H12: =+IF(AND(A12="latas sas",E12="tarjeta"),D12,0) -> 0 | I12: =+IF(AND(A12="tomas gomez",E12="tarjeta"),D12,0) -> 0 | J12: =+IF(AND($A12="latas sas",$E12="bancolombia"),$D12,0) -> 0 | K12: =+IF(AND($A12="tomas gomez",$E12="bancolombia"),$D12,0) -> 0 | L12: =+IF(AND($A12="latas sas",$E12="bbva"),$D12,0) -> 0 | M12: =+IF(AND($A12="tomas gomez",$E12="bbva"),$D12,0) -> 0 | N12: =IF(E12="GIRO",D12,0) -> 0 | O12: =IF(E12="DAVIVIENDA",D12,0) -> 0 | P12: =IF(E12="NEQUI TG",E12,0) -> 0 | Q12: =IF(E12="NEQUI AB",D12,0) -> 0 | R12: =IF(E12="NEQUI OTRO",D12,0) -> 0
A13: LATAS SAS | B13: 14105 | C13: HY ATOS DEF DEL / DEF TRAS / PLUMILLA 16/20 SILICONA | D13: 326000 | E13: TARJETA | F13: =IF(E13="EFECTIVO",D13,0) -> 0 | G13: =+IF(E13="ENTREGA",D13,0) -> 0 | H13: =+IF(AND(A13="latas sas",E13="tarjeta"),D13,0) -> 326000 | I13: =+IF(AND(A13="tomas gomez",E13="tarjeta"),D13,0) -> 0 | J13: =+IF(AND($A13="latas sas",$E13="bancolombia"),$D13,0) -> 0 | K13: =+IF(AND($A13="tomas gomez",$E13="bancolombia"),$D13,0) -> 0 | L13: =+IF(AND($A13="latas sas",$E13="bbva"),$D13,0) -> 0 | M13: =+IF(AND($A13="tomas gomez",$E13="bbva"),$D13,0) -> 0 | N13: =IF(E13="GIRO",D13,0) -> 0 | O13: =IF(E13="DAVIVIENDA",D13,0) -> 0 | P13: =IF(E13="NEQUI TG",E13,0) -> 0 | Q13: =IF(E13="NEQUI AB",D13,0) -> 0 | R13: =IF(E13="NEQUI OTRO",D13,0) -> 0
A14: TOMAS GOMEZ | B14: 6424 | C14: NISSAN FRONTIER STOP RH BICOLOR | D14: 70000 | E14: BANCOLOMBIA | F14: =IF(E14="EFECTIVO",D14,0) -> 0 | G14: =+IF(E14="ENTREGA",D14,0) -> 0 | H14: =+IF(AND(A14="latas sas",E14="tarjeta"),D14,0) -> 0 | I14: =+IF(AND(A14="tomas gomez",E14="tarjeta"),D14,0) -> 0 | J14: =+IF(AND($A14="latas sas",$E14="bancolombia"),$D14,0) -> 0 | K14: =+IF(AND($A14="tomas gomez",$E14="bancolombia"),$D14,0) -> 70000 | L14: =+IF(AND($A14="latas sas",$E14="bbva"),$D14,0) -> 0 | M14: =+IF(AND($A14="tomas gomez",$E14="bbva"),$D14,0) -> 0 | N14: =IF(E14="GIRO",D14,0) -> 0 | O14: =IF(E14="DAVIVIENDA",D14,0) -> 0 | P14: =IF(E14="NEQUI TG",E14,0) -> 0 | Q14: =IF(E14="NEQUI AB",D14,0) -> 0 | R14: =IF(E14="NEQUI OTRO",D14,0) -> 0
A15: TOMAS GOMEZ | B15: LPC14120 | C15: HY ATOS RETROV RH | D15: 70000 | E15: BANCOLOMBIA | F15: =IF(E15="EFECTIVO",D15,0) -> 0 | G15: =+IF(E15="ENTREGA",D15,0) -> 0 | H15: =+IF(AND(A15="latas sas",E15="tarjeta"),D15,0) -> 0 | I15: =+IF(AND(A15="tomas gomez",E15="tarjeta"),D15,0) -> 0 | J15: =+IF(AND($A15="latas sas",$E15="bancolombia"),$D15,0) -> 0 | K15: =+IF(AND($A15="tomas gomez",$E15="bancolombia"),$D15,0) -> 70000 | L15: =+IF(AND($A15="latas sas",$E15="bbva"),$D15,0) -> 0 | M15: =+IF(AND($A15="tomas gomez",$E15="bbva"),$D15,0) -> 0 | N15: =IF(E15="GIRO",D15,0) -> 0 | O15: =IF(E15="DAVIVIENDA",D15,0) -> 0 | P15: =IF(E15="NEQUI TG",E15,0) -> 0 | Q15: =IF(E15="NEQUI AB",D15,0) -> 0 | R15: =IF(E15="NEQUI OTRO",D15,0) -> 0
A16: LATAS SAS | B16: 14106 | C16: NISSAN TIDA DEF DEL PEN POR ENTREGAR | D16: 230000 | E16: BANCOLOMBIA | F16: =IF(E16="EFECTIVO",D16,0) -> 0 | G16: =+IF(E16="ENTREGA",D16,0) -> 0 | H16: =+IF(AND(A16="latas sas",E16="tarjeta"),D16,0) -> 0 | I16: =+IF(AND(A16="tomas gomez",E16="tarjeta"),D16,0) -> 0 | J16: =+IF(AND($A16="latas sas",$E16="bancolombia"),$D16,0) -> 230000 | K16: =+IF(AND($A16="tomas gomez",$E16="bancolombia"),$D16,0) -> 0 | L16: =+IF(AND($A16="latas sas",$E16="bbva"),$D16,0) -> 0 | M16: =+IF(AND($A16="tomas gomez",$E16="bbva"),$D16,0) -> 0 | N16: =IF(E16="GIRO",D16,0) -> 0 | O16: =IF(E16="DAVIVIENDA",D16,0) -> 0 | P16: =IF(E16="NEQUI TG",E16,0) -> 0 | Q16: =IF(E16="NEQUI AB",D16,0) -> 0 | R16: =IF(E16="NEQUI OTRO",D16,0) -> 0
A17: TOMAS GOMEZ | B17: 6425 | C17: MAZDA ALLEGRO STOP RH | D17: 170000 | E17: EFECTIVO | F17: =IF(E17="EFECTIVO",D17,0) -> 170000 | G17: =+IF(E17="ENTREGA",D17,0) -> 0 | H17: =+IF(AND(A17="latas sas",E17="tarjeta"),D17,0) -> 0 | I17: =+IF(AND(A17="tomas gomez",E17="tarjeta"),D17,0) -> 0 | J17: =+IF(AND($A17="latas sas",$E17="bancolombia"),$D17,0) -> 0 | K17: =+IF(AND($A17="tomas gomez",$E17="bancolombia"),$D17,0) -> 0 | L17: =+IF(AND($A17="latas sas",$E17="bbva"),$D17,0) -> 0 | M17: =+IF(AND($A17="tomas gomez",$E17="bbva"),$D17,0) -> 0 | N17: =IF(E17="GIRO",D17,0) -> 0 | O17: =IF(E17="DAVIVIENDA",D17,0) -> 0 | P17: =IF(E17="NEQUI TG",E17,0) -> 0 | Q17: =IF(E17="NEQUI AB",D17,0) -> 0 | R17: =IF(E17="NEQUI OTRO",D17,0) -> 0
A18: LATAS SAS | B18: 14107 | C18: HY GRAN I10 FRONTAL | D18: 250000 | E18: BANCOLOMBIA | F18: =IF(E18="EFECTIVO",D18,0) -> 0 | G18: =+IF(E18="ENTREGA",D18,0) -> 0 | H18: =+IF(AND(A18="latas sas",E18="tarjeta"),D18,0) -> 0 | I18: =+IF(AND(A18="tomas gomez",E18="tarjeta"),D18,0) -> 0 | J18: =+IF(AND($A18="latas sas",$E18="bancolombia"),$D18,0) -> 250000 | K18: =+IF(AND($A18="tomas gomez",$E18="bancolombia"),$D18,0) -> 0 | L18: =+IF(AND($A18="latas sas",$E18="bbva"),$D18,0) -> 0 | M18: =+IF(AND($A18="tomas gomez",$E18="bbva"),$D18,0) -> 0 | N18: =IF(E18="GIRO",D18,0) -> 0 | O18: =IF(E18="DAVIVIENDA",D18,0) -> 0 | P18: =IF(E18="NEQUI TG",E18,0) -> 0 | Q18: =IF(E18="NEQUI AB",D18,0) -> 0 | R18: =IF(E18="NEQUI OTRO",D18,0) -> 0
A19: LATAS SAS | B19: 14108 | C19: KIA ION 12/17 PASO RUEDA LH | D19: 50000 | E19: EFECTIVO | F19: =IF(E19="EFECTIVO",D19,0) -> 50000 | G19: =+IF(E19="ENTREGA",D19,0) -> 0 | H19: =+IF(AND(A19="latas sas",E19="tarjeta"),D19,0) -> 0 | I19: =+IF(AND(A19="tomas gomez",E19="tarjeta"),D19,0) -> 0 | J19: =+IF(AND($A19="latas sas",$E19="bancolombia"),$D19,0) -> 0 | K19: =+IF(AND($A19="tomas gomez",$E19="bancolombia"),$D19,0) -> 0 | L19: =+IF(AND($A19="latas sas",$E19="bbva"),$D19,0) -> 0 | M19: =+IF(AND($A19="tomas gomez",$E19="bbva"),$D19,0) -> 0 | N19: =IF(E19="GIRO",D19,0) -> 0 | O19: =IF(E19="DAVIVIENDA",D19,0) -> 0 | P19: =IF(E19="NEQUI TG",E19,0) -> 0 | Q19: =IF(E19="NEQUI AB",D19,0) -> 0 | R19: =IF(E19="NEQUI OTRO",D19,0) -> 0
