Workbook

Sheet Consolidado
V1: FORMA DE PAGO
V2: EFECTIVO | W2: LATAS SAS
B3: INGRESOS | V3: TARJETA | W3: TOMAS GOMEZ
B4: EFECTIVO | C4: ENTREGA | D4: TARJETA LATAS | E4: TARJETA TOMAS | F4: BANCOLOMBIA LATAS | G4: BANCOLOMBIA TOMAS | H4: BBVA LATAS | I4: BBVA TOMAS | J4: GIRO | K4: DAVIVIENDA | L4: NEQUI TG | M4: NEQUI AB | N4: NEQUI OTRO | O4: TOTAL VENTA DIA | V4: BANCOLOMBIA
A5: 44562 | B5: =+#REF! -> #REF! | C5: =+#REF! -> #REF! | D5: =+#REF! -> #REF! | E5: =+#REF! -> #REF! | F5: =+#REF! -> #REF! | G5: =+#REF! -> #REF! | H5: =+#REF! -> #REF! | I5: =+#REF! -> #REF! | ... N5: =+#REF! -> #REF! | O5: =SUM(B5:N5)-C5 -> #REF! | V5: BBVA
A6: 44563 | B6: =+'2'!$F$3 -> 539000 | C6: =+'2'!$G$3 -> 539000 | D6: =+'2'!$H$3 -> 450000 | E6: =+'2'!$I$3 -> 0 | F6: =+'2'!$I$3 -> 0 | G6: =+'2'!$K$3 -> 0 | H6: =+'2'!$J$3 -> 380000 | I6: =+'2'!$M$3 -> 0 | J6: =+'2'!$K$3 -> 0 | K6: =+'2'!$L$3 -> 0 | L6: =+'2'!$P$3 -> 46000 | M6: =+'2'!$Q$3 -> 0 | N6: =+'2'!$R$3 -> 0 | O6: =SUM(B6:N6) -> 1954000 | V6: GIRO
A7: 44564 | B7: =+'3'!$F$3 -> 2446000 | C7: =+'3'!$G$3 -> 2446000 | D7: =+'3'!$H$3 -> 75000 | E7: =+'3'!$HI$3 -> 0 | F7: =+'3'!$I$3 -> 0 | G7: =+'3'!$K$3 -> 0 | H7: =+'3'!$J$3 -> 1937000 | I7: =+'3'!$M$3 -> 0 | J7: =+'3'!$K$3 -> 0 | K7: =+'3'!$L$3 -> 0 | L7: =+'3'!$P$3 -> 0 | M7: =+'3'!$Q$3 -> 0 | N7: =+'3'!$R$3 -> 0 | O7: =SUM(B7:N7) -> 6904000 | V7: DAVIVIENDA
A8: 44565 | B8: =+'4'!$F$3 -> 833000 | C8: =+'4'!$G$3 -> 633000 | D8: =+'4'!$H$3 -> 0 | E8: =+'4'!$I$3 -> 0 | F8: =+'4'!$I$3 -> 0 | G8: =+'4'!$K$3 -> 0 | H8: =+'4'!$J$3 -> 1420000 | I8: =+'4'!$M$3 -> 0 | J8: =+'4'!$K$3 -> 0 | K8: =+'4'!$L$3 -> 0 | L8: =+'4'!$P$3 -> 0 | M8: =+'4'!$Q$3 -> 0 | N8: =+'4'!$R$3 -> 0 | O8: =SUM(B8:N8) -> 2886000 | V8: ENTREGA
A9: 44566 | B9: =+'5'!$F$3 -> 998800 | C9: =+'5'!$G$3 -> 998800 | D9: =+'5'!$H$3 -> 510000 | E9: =+'5'!$I$3 -> 0 | F9: =+'5'!$I$3 -> 0 | G9: =+'5'!$K$3 -> 1050000 | H9: =+'5'!$J$3 -> 795000 | I9: =+'5'!$M$3 -> 0 | J9: =+'5'!$K$3 -> 1050000 | K9: =+'5'!$L$3 -> 0 | L9: =+'5'!$P$3 -> 0 | M9: =+'5'!$Q$3 -> 0 | N9: =+'5'!$R$3 -> 0 | O9: =SUM(B9:N9) -> 5402600 | V9: NEQUI TG
A10: TOTAL MES | B10: =SUM(B5:B9) -> #REF! | C10: =SUM(C5:C9) -> #REF! | D10: =SUM(D5:D9) -> #REF! | E10: =SUM(E5:E9) -> #REF! | F10: =SUM(F5:F9) -> #REF! | G10: =SUM(G5:G9) -> #REF! | H10: =SUM(H5:H9) -> #REF! | I10: =SUM(I5:I9) -> #REF! | ... O10: =SUM(O5:O9) -> #REF!
A16: FECHA | B16: PROVEEDOR | D16: FACTURA | E16: VALOR | F16: FORMA DE PAGO | G16: SALDO
G17: =+IF(F17="EFECTIVO",B10-E17,"N/A") -> N/A
G18: =+IF(F18="EFECTIVO",B11-E18,"N/A") -> N/A
G19: =+IF(F19="EFECTIVO",B12-E19,"N/A") -> N/A
G20: =+IF(F20="EFECTIVO",B13-E20,"N/A") -> N/A
G21: =+IF(F21="EFECTIVO",B14-E21,"N/A") -> N/A
G22: =+IF(F22="EFECTIVO",B15-E22,"N/A") -> N/A
G23: =+IF(F23="EFECTIVO",B16-E23,"N/A") -> N/A
G24: =+IF(F24="EFECTIVO",B17-E24,"N/A") -> N/A
G25: =+IF(F25="EFECTIVO",B18-E25,"N/A") -> N/A
G26: =+IF(F26="EFECTIVO",B19-E26,"N/A") -> N/A
G27: =+IF(F27="EFECTIVO",B20-E27,"N/A") -> N/A
G28: =+IF(F28="EFECTIVO",B21-E28,"N/A") -> N/A
... G42: =+IF(F42="EFECTIVO",B35-E42,"N/A") -> N/A

Sheet 2
A1: LATAS Y PARTES DE LA COSTA
C2: CAJA MENOR
C3: CAJA EFECTIVO | D3: =+F3-G3 -> 0 | E3: =(SUM(F3:R3))-G3 -> 1415000 | F3: =SUM(F5:F50) -> 539000 | G3: =SUM(G5:G50) -> 539000 | H3: =SUM(H5:H50) -> 450000 | I3: =SUM(I5:I50) -> 0 | J3: =SUM(J5:J50) -> 380000 | K3: =SUM(K5:K50) -> 0 | L3: =SUM(L5:L50) -> 0 | M3: =SUM(M5:M50) -> 0 | ... R3: =SUM(R5:R50) -> 0
A4: EMPRESA | B4: NOTA | C4: DESCRIPCIÓN | D4: VALOR | E4: FORMA PAGO | F4: EFECTIVO | G4: ENTREGA | H4: TARJETA LATAS | I4: TARJETA TOMAS | J4: BANCOLOMBIA LATAS | K4: BANCOLOMBIA TOMAS | L4: BBVA LATAS | M4: BBVA TOMAS | N4: GIRO | O4: DAVIVIENDA | P4: NEQUI TG | Q4: NEQUI AB | R4: NEQUI OTRO
B5: TITO | C5: RENAULT DUSTER M/N LUNA RH | D5: 35000 | E5: EFECTIVO | F5: =IF(E5="EFECTIVO",D5,0) -> 35000 | G5: =+IF(E5="ENTREGA",D5,0) -> 0 | H5: =+IF(AND(A5="latas sas",E5="tarjeta"),D5,0) -> 0 | I5: =+IF(AND(A5="tomas gomez",E5="tarjeta"),D5,0) -> 0 | J5: =+IF(AND($A5="latas sas",$E5="bancolombia"),$D5,0) -> 0 | K5: =+IF(AND($A5="tomas gomez",$E5="bancolombia"),$D5,0) -> 0 | L5: =+IF(AND($A5="latas sas",$E5="bbva"),$D5,0) -> 0 | M5: =+IF(AND($A5="tomas gomez",$E5="bbva"),$D5,0) -> 0 | N5: =IF(E5="GIRO",D5,0) -> 0 | O5: =IF(E5="DAVIVIENDA",D5,0) -> 0 | P5: =IF(E5="NEQUI TG",D5,0) -> 0 | Q5: =IF(E5="NEQUI AB",D5,0) -> 0 | R5: =IF(E5="NEQUI OTRO",D5,0) -> 0
C6: CHEVRO AVEO PERSIANA SDN | D6: 80000 | E6: EFECTIVO | F6: =IF(E6="EFECTIVO",D6,0) -> 80000 | G6: =+IF(E6="ENTREGA",D6,0) -> 0 | H6: =+IF(AND(A6="latas sas",E6="tarjeta"),D6,0) -> 0 | I6: =+IF(AND(A6="tomas gomez",E6="tarjeta"),D6,0) -> 0 | J6: =+IF(AND($A6="latas sas",$E6="bancolombia"),$D6,0) -> 0 | K6: =+IF(AND($A6="tomas gomez",$E6="bancolombia"),$D6,0) -> 0 | L6: =+IF(AND($A6="latas sas",$E6="bbva"),$D6,0) -> 0 | M6: =+IF(AND($A6="tomas gomez",$E6="bbva"),$D6,0) -> 0 | N6: =IF(E6="GIRO",D6,0) -> 0 | O6: =IF(E6="DAVIVIENDA",D6,0) -> 0 | P6: =IF(E6="NEQUI TG",E6,0) -> 0 | Q6: =IF(E6="NEQUI AB",D6,0) -> 0 | R6: =IF(E6="NEQUI OTRO",D6,0) -> 0
C7: CHEVR SPARK GT LUNA RH | D7: 35000 | E7: EFECTIVO | F7: =IF(E7="EFECTIVO",D7,0) -> 35000 | G7: =+IF(E7="ENTREGA",D7,0) -> 0 | H7: =+IF(AND(A7="latas sas",E7="tarjeta"),D7,0) -> 0 | I7: =+IF(AND(A7="tomas gomez",E7="tarjeta"),D7,0) -> 0 | J7: =+IF(AND($A7="latas sas",$E7="bancolombia"),$D7,0) -> 0 | K7: =+IF(AND($A7="tomas gomez",$E7="bancolombia"),$D7,0) -> 0 | L7: =+IF(AND($A7="latas sas",$E7="bbva"),$D7,0) -> 0 | M7: =+IF(AND($A7="tomas gomez",$E7="bbva"),$D7,0) -> 0 | N7: =IF(E7="GIRO",D7,0) -> 0 | O7: =IF(E7="DAVIVIENDA",D7,0) -> 0 | P7: =IF(E7="NEQUI TG",E7,0) -> 0 | Q7: =IF(E7="NEQUI AB",D7,0) -> 0 | R7: =IF(E7="NEQUI OTRO",D7,0) -> 0
C8: HY I10 MANIJA INT LH VARILLA | D8: 30000 | E8: EFECTIVO | F8: =IF(E8="EFECTIVO",D8,0) -> 30000 | G8: =+IF(E8="ENTREGA",D8,0) -> 0 | H8: =+IF(AND(A8="latas sas",E8="tarjeta"),D8,0) -> 0 | I8: =+IF(AND(A8="tomas gomez",E8="tarjeta"),D8,0) -> 0 | J8: =+IF(AND($A8="latas sas",$E8="bancolombia"),$D8,0) -> 0 | K8: =+IF(AND($A8="tomas gomez",$E8="bancolombia"),$D8,0) -> 0 | L8: =+IF(AND($A8="latas sas",$E8="bbva"),$D8,0) -> 0 | M8: =+IF(AND($A8="tomas gomez",$E8="bbva"),$D8,0) -> 0 | N8: =IF(E8="GIRO",D8,0) -> 0 | O8: =IF(E8="DAVIVIENDA",D8,0) -> 0 | P8: =IF(E8="NEQUI TG",E8,0) -> 0 | Q8: =IF(E8="NEQUI AB",D8,0) -> 0 | R8: =IF(E8="NEQUI OTRO",D8,0) -> 0
C9: REANULT DIRECC GUARDAF | D9: 15000 | E9: EFECTIVO | F9: =IF(E9="EFECTIVO",D9,0) -> 15000 | G9: =+IF(E9="ENTREGA",D9,0) -> 0 | H9: =+IF(AND(A9="latas sas",E9="tarjeta"),D9,0) -> 0 | I9: =+IF(AND(A9="tomas gomez",E9="tarjeta"),D9,0) -> 0 | J9: =+IF(AND($A9="latas sas",$E9="bancolombia"),$D9,0) -> 0 | K9: =+IF(AND($A9="tomas gomez",$E9="bancolombia"),$D9,0) -> 0 | L9: =+IF(AND($A9="latas sas",$E9="bbva"),$D9,0) -> 0 | M9: =+IF(AND($A9="tomas gomez",$E9="bbva"),$D9,0) -> 0 | N9: =IF(E9="GIRO",D9,0) -> 0 | O9: =IF(E9="DAVIVIENDA",D9,0) -> 0 | P9: =IF(E9="NEQUI TG",E9,0) -> 0 | Q9: =IF(E9="NEQUI AB",D9,0) -> 0 | R9: =IF(E9="NEQUI OTRO",D9,0) -> 0
C10: 16 PINES | D10: 16000 | E10: NEQUI TG | F10: =IF(E10="EFECTIVO",D10,0) -> 0 | G10: =+IF(E10="ENTREGA",D10,0) -> 0 | H10: =+IF(AND(A10="latas sas",E10="tarjeta"),D10,0) -> 0 | I10: =+IF(AND(A10="tomas gomez",E10="tarjeta"),D10,0) -> 0 | J10: =+IF(AND($A10="latas sas",$E10="bancolombia"),$D10,0) -> 0 | K10: =+IF(AND($A10="tomas gomez",$E10="bancolombia"),$D10,0) -> 0 | L10: =+IF(AND($A10="latas sas",$E10="bbva"),$D10,0) -> 0 | M10: =+IF(AND($A10="tomas gomez",$E10="bbva"),$D10,0) -> 0 | N10: =IF(E10="GIRO",D10,0) -> 0 | O10: =IF(E10="DAVIVIENDA",D10,0) -> 0 | P10: =IF(E10="NEQUI TG",D10,0) -> 16000 | Q10: =IF(E10="NEQUI AB",D10,0) -> 0 | R10: =IF(E10="NEQUI OTRO",D10,0) -> 0
C11: CHEVR SAIL LUNA LH | D11: 30000 | E11: EFECTIVO | F11: =IF(E11="EFECTIVO",D11,0) -> 30000 | G11: =+IF(E11="ENTREGA",D11,0) -> 0 | H11: =+IF(AND(A11="latas sas",E11="tarjeta"),D11,0) -> 0 | I11: =+IF(AND(A11="tomas gomez",E11="tarjeta"),D11,0) -> 0 | J11: =+IF(AND($A11="latas sas",$E11="bancolombia"),$D11,0) -> 0 | K11: =+IF(AND($A11="tomas gomez",$E11="bancolombia"),$D11,0) -> 0 | L11: =+IF(AND($A11="latas sas",$E11="bbva"),$D11,0) -> 0 | M11: =+IF(AND($A11="tomas gomez",$E11="bbva"),$D11,0) -> 0 | N11: =IF(E11="GIRO",D11,0) -> 0 | O11: =IF(E11="DAVIVIENDA",D11,0) -> 0 | P11: =IF(E11="NEQUI TG",D11,0) -> 0 | Q11: =IF(E11="NEQUI AB",D11,0) -> 0 | R11: =IF(E11="NEQUI OTRO",D11,0) -> 0
A12: LATAS SAS | C12: RENAUT MEGANE CONTRA TAPA GASOLINA | D12: 60000 | E12: BANCOLOMBIA | F12: =IF(E12="EFECTIVO",D12,0) -> 0 | G12: =+IF(E12="ENTREGA",D12,0) -> 0 | H12: =+IF(AND(A12="latas sas",E12="tarjeta"),D12,0) -> 0 | I12: =+IF(AND(A12="tomas gomez",E12="tarjeta"),D12,0) -> 0 | J12: =+IF(AND($A12="latas sas",$E12="bancolombia"),$D12,0) -> 60000 | K12: =+IF(AND($A12="tomas gomez",$E12="bancolombia"),$D12,0) -> 0 | L12: =+IF(AND($A12="latas sas",$E12="bbva"),$D12,0) -> 0 | M12: =+IF(AND($A12="tomas gomez",$E12="bbva"),$D12,0) -> 0 | N12: =IF(E12="GIRO",D12,0) -> 0 | O12: =IF(E12="DAVIVIENDA",D12,0) -> 0 | P12: =IF(E12="NEQUI TG",D12,0) -> 0 | Q12: =IF(E12="NEQUI AB",D12,0) -> 0 | R12: =IF(E12="NEQUI OTRO",D12,0) -> 0
C13: NISSAN FRONTIER STOP RH DEPO D22 D4 | D13: 120000 | E13: EFECTIVO | F13: =IF(E13="EFECTIVO",D13,0) -> 120000 | G13: =+IF(E13="ENTREGA",D13,0) -> 0 | H13: =+IF(AND(A13="latas sas",E13="tarjeta"),D13,0) -> 0 | I13: =+IF(AND(A13="tomas gomez",E13="tarjeta"),D13,0) -> 0 | J13: =+IF(AND($A13="latas sas",$E13="bancolombia"),$D13,0) -> 0 | K13: =+IF(AND($A13="tomas gomez",$E13="bancolombia"),$D13,0) -> 0 | L13: =+IF(AND($A13="latas sas",$E13="bbva"),$D13,0) -> 0 | M13: =+IF(AND($A13="tomas gomez",$E13="bbva"),$D13,0) -> 0 | N13: =IF(E13="GIRO",D13,0) -> 0 | O13: =IF(E13="DAVIVIENDA",D13,0) -> 0 | P13: =IF(E13="NEQUI TG",D13,0) -> 0 | Q13: =IF(E13="NEQUI AB",D13,0) -> 0 | R13: =IF(E13="NEQUI OTRO",D13,0) -> 0
C14: HY GRAND I10 LUNA LH | D14: 30000 | E14: EFECTIVO | F14: =IF(E14="EFECTIVO",D14,0) -> 30000 | G14: =+IF(E14="ENTREGA",D14,0) -> 0 | H14: =+IF(AND(A14="latas sas",E14="tarjeta"),D14,0) -> 0 | I14: =+IF(AND(A14="tomas gomez",E14="tarjeta"),D14,0) -> 0 | J14: =+IF(AND($A14="latas sas",$E14="bancolombia"),$D14,0) -> 0 | K14: =+IF(AND($A14="tomas gomez",$E14="bancolombia"),$D14,0) -> 0 | L14: =+IF(AND($A14="latas sas",$E14="bbva"),$D14,0) -> 0 | M14: =+IF(AND($A14="tomas gomez",$E14="bbva"),$D14,0) -> 0 | N14: =IF(E14="GIRO",D14,0) -> 0 | O14: =IF(E14="DAVIVIENDA",D14,0) -> 0 | P14: =IF(E14="NEQUI TG",D14,0) -> 0 | Q14: =IF(E14="NEQUI AB",D14,0) -> 0 | R14: =IF(E14="NEQUI OTRO",D14,0) -> 0
B15: ICOTEA | C15: HY ION TAPA EXPLORADORA RH 18/22 | D15: 60000 | E15: EFECTIVO | F15: =IF(E15="EFECTIVO",D15,0) -> 60000 | G15: =+IF(E15="ENTREGA",D15,0) -> 0 | H15: =+IF(AND(A15="latas sas",E15="tarjeta"),D15,0) -> 0 | I15: =+IF(AND(A15="tomas gomez",E15="tarjeta"),D15,0) -> 0 | J15: =+IF(AND($A15="latas sas",$E15="bancolombia"),$D15,0) -> 0 | K15: =+IF(AND($A15="tomas gomez",$E15="bancolombia"),$D15,0) -> 0 | L15: =+IF(AND($A15="latas sas",$E15="bbva"),$D15,0) -> 0 | M15: =+IF(AND($A15="tomas gomez",$E15="bbva"),$D15,0) -> 0 | N15: =IF(E15="GIRO",D15,0) -> 0 | O15: =IF(E15="DAVIVIENDA",D15,0) -> 0 | P15: =IF(E15="NEQUI TG",D15,0) -> 0 | Q15: =IF(E15="NEQUI AB",D15,0) -> 0 | R15: =IF(E15="NEQUI OTRO",D15,0) -> 0
C16: KIA ION 12/17 DEVOLUCION GUIA FACT 14093 (20/01/26) | D16: -60000 | E16: EFECTIVO | F16: =IF(E16="EFECTIVO",D16,0) -> -60000 | G16: =+IF(E16="ENTREGA",D16,0) -> 0 | H16: =+IF(AND(A16="latas sas",E16="tarjeta"),D16,0) -> 0 | I16: =+IF(AND(A16="tomas gomez",E16="tarjeta"),D16,0) -> 0 | J16: =+IF(AND($A16="latas sas",$E16="bancolombia"),$D16,0) -> 0 | K16: =+IF(AND($A16="tomas gomez",$E16="bancolombia"),$D16,0) -> 0 | L16: =+IF(AND($A16="latas sas",$E16="bbva"),$D16,0) -> 0 | M16: =+IF(AND($A16="tomas gomez",$E16="bbva"),$D16,0) -> 0 | N16: =IF(E16="GIRO",D16,0) -> 0 | O16: =IF(E16="DAVIVIENDA",D16,0) -> 0 | P16: =IF(E16="NEQUI TG",D16,0) -> 0 | Q16: =IF(E16="NEQUI AB",D16,0) -> 0 | R16: =IF(E16="NEQUI OTRO",D16,0) -> 0
C17: KIA ION 12/17 PASO RUEDA RH/LH/ 10 PINES | D17: 110000 | E17: EFECTIVO | F17: =IF(E17="EFECTIVO",D17,0) -> 110000 | G17: =+IF(E17="ENTREGA",D17,0) -> 0 | H17: =+IF(AND(A17="latas sas",E17="tarjeta"),D17,0) -> 0 | I17: =+IF(AND(A17="tomas gomez",E17="tarjeta"),D17,0) -> 0 | J17: =+IF(AND($A17="latas sas",$E17="bancolombia"),$D17,0) -> 0 | K17: =+IF(AND($A17="tomas gomez",$E17="bancolombia"),$D17,0) -> 0 | L17: =+IF(AND($A17="latas sas",$E17="bbva"),$D17,0) -> 0 | M17: =+IF(AND($A17="tomas gomez",$E17="bbva"),$D17,0) -> 0 | N17: =IF(E17="GIRO",D17,0) -> 0 | O17: =IF(E17="DAVIVIENDA",D17,0) -> 0 | P17: =IF(E17="NEQUI TG",D17,0) -> 0 | Q17: =IF(E17="NEQUI AB",D17,0) -> 0 | R17: =IF(E17="NEQUI OTRO",D17,0) -> 0
C18: 10 PINES | D18: 10000 | E18: EFECTIVO | F18: =IF(E18="EFECTIVO",D18,0) -> 10000 | G18: =+IF(E18="ENTREGA",D18,0) -> 0 | H18: =+IF(AND(A18="latas sas",E18="tarjeta"),D18,0) -> 0 | I18: =+IF(AND(A18="tomas gomez",E18="tarjeta"),D18,0) -> 0 | J18: =+IF(AND($A18="latas sas",$E18="bancolombia"),$D18,0) -> 0 | K18: =+IF(AND($A18="tomas gomez",$E18="bancolombia"),$D18,0) -> 0 | L18: =+IF(AND($A18="latas sas",$E18="bbva"),$D18,0) -> 0 | M18: =+IF(AND($A18="tomas gomez",$E18="bbva"),$D18,0) -> 0 | N18: =IF(E18="GIRO",D18,0) -> 0 | O18: =IF(E18="DAVIVIENDA",D18,0) -> 0 | P18: =IF(E18="NEQUI TG",D18,0) -> 0 | Q18: =IF(E18="NEQUI AB",D18,0) -> 0 | R18: =IF(E18="NEQUI OTRO",D18,0) -> 0
A19: LATAS SAS | C19: CHEVR AVEO RADIADOR ENVIO EL CARMEN DE BOLIVAR | D19: 230000 | E19: BANCOLOMBIA | F19: =IF(E19="EFECTIVO",D19,0) -> 0 | G19: =+IF(E19="ENTREGA",D19,0) -> 0 | H19: =+IF(AND(A19="latas sas",E19="tarjeta"),D19,0) -> 0 | I19: =+IF(AND(A19="tomas gomez",E19="tarjeta"),D19,0) -> 0 | J19: =+IF(AND($A19="latas sas",$E19="bancolombia"),$D19,0) -> 230000 | K19: =+IF(AND($A19="tomas gomez",$E19="bancolombia"),$D19,0) -> 0 | L19: =+IF(AND($A19="latas sas",$E19="bbva"),$D19,0) -> 0 | M19: =+IF(AND($A19="tomas gomez",$E19="bbva"),$D19,0) -> 0 | N19: =IF(E19="GIRO",D19,0) -> 0 | O19: =IF(E19="DAVIVIENDA",D19,0) -> 0 | P19: =IF(E19="NEQUI TG",D19,0) -> 0 | Q19: =IF(E19="NEQUI AB",D19,0) -> 0 | R19: =IF(E19="NEQUI OTRO",D19,0) -> 0
A20: LATAS SAS | C20: CHEVR AVEO EMOTION SEDAN BOCEL PERSIANA ENVIO EL CARMEN DE BOLIVAR | D20: 90000 | E20: BANCOLOMBIA | F20: =IF(E20="EFECTIVO",D20,0) -> 0 | G20: =+IF(E20="ENTREGA",D20,0) -> 0 | H20: =+IF(AND(A20="latas sas",E20="tarjeta"),D20,0) -> 0 | I20: =+IF(AND(A20="tomas gomez",E20="tarjeta"),D20,0) -> 0 | J20: =+IF(AND($A20="latas sas",$E20="bancolombia"),$D20,0) -> 90000 | K20: =+IF(AND($A20="tomas gomez",$E20="bancolombia"),$D20,0) -> 0 | L20: =+IF(AND($A20="latas sas",$E20="bbva"),$D20,0) -> 0 | M20: =+IF(AND($A20="tomas gomez",$E20="bbva"),$D20,0) -> 0 | N20: =IF(E20="GIRO",D20,0) -> 0 | O20: =IF(E20="DAVIVIENDA",D20,0) -> 0 | P20: =IF(E20="NEQUI TG",D20,0) -> 0 | Q20: =IF(E20="NEQUI AB",D20,0) -> 0 | R20: =IF(E20="NEQUI OTRO",D20,0) -> 0
C21: HY I10 MANIJA INT RH VARILLA ENVIO SANTA MARTA | D21: 30000 | E21: NEQUI TG | F21: =IF(E21="EFECTIVO",D21,0) -> 0 | G21: =+IF(E21="ENTREGA",D21,0) -> 0 | H21: =+IF(AND(A21="latas sas",E21="tarjeta"),D21,0) -> 0 | I21: =+IF(AND(A21="tomas gomez",E21="tarjeta"),D21,0) -> 0 | J21: =+IF(AND($A21="latas sas",$E21="bancolombia"),$D21,0) -> 0 | K21: =+IF(AND($A21="tomas gomez",$E21="bancolombia"),$D21,0) -> 0 | L21: =+IF(AND($A21="latas sas",$E21="bbva"),$D21,0) -> 0 | M21: =+IF(AND($A21="tomas gomez",$E21="bbva"),$D21,0) -> 0 | N21: =IF(E21="GIRO",D21,0) -> 0 | O21: =IF(E21="DAVIVIENDA",D21,0) -> 0 | P21: =IF(E21="NEQUI TG",D21,0) -> 30000 | Q21: =IF(E21="NEQUI AB",D21,0) -> 0 | R21: =IF(E21="NEQUI OTRO",D21,0) -> 0
C22: PAGO QUE REALIZA SR TOMAS | D22: -1000 | E22: EFECTIVO | F22: =IF(E22="EFECTIVO",D22,0) -> -1000 | G22: =+IF(E22="ENTREGA",D22,0) -> 0 | H22: =+IF(AND(A22="latas sas",E22="tarjeta"),D22,0) -> 0 | I22: =+IF(AND(A22="tomas gomez",E22="tarjeta"),D22,0) -> 0 | J22: =+IF(AND($A22="latas sas",$E22="bancolombia"),$D22,0) -> 0 | K22: =+IF(AND($A22="tomas gomez",$E22="bancolombia"),$D22,0) -> 0 | L22: =+IF(AND($A22="latas sas",$E22="bbva"),$D22,0) -> 0 | M22: =+IF(AND($A22="tomas gomez",$E22="bbva"),$D22,0) -> 0 | N22: =IF(E22="GIRO",D22,0) -> 0 | O22: =IF(E22="DAVIVIENDA",D22,0) -> 0 | P22: =IF(E22="NEQUI TG",D22,0) -> 0 | Q22: =IF(E22="NEQUI AB",D22,0) -> 0 | R22: =IF(E22="NEQUI OTRO",D22,0) -> 0
A23: LATAS SAS | B23: PEDRO MARAUTO | C23: CHEVRO CAPTIVA LAMP LH FONDO CROMADO | D23: 450000 | E23: TARJETA | F23: =IF(E23="EFECTIVO",D23,0) -> 0 | G23: =+IF(E23="ENTREGA",D23,0) -> 0 | H23: =+IF(AND(A23="latas sas",E23="tarjeta"),D23,0) -> 450000 | I23: =+IF(AND(A23="tomas gomez",E23="tarjeta"),D23,0) -> 0 | J23: =+IF(AND($A23="latas sas",$E23="bancolombia"),$D23,0) -> 0 | K23: =+IF(AND($A23="tomas gomez",$E23="bancolombia"),$D23,0) -> 0 | L23: =+IF(AND($A23="latas sas",$E23="bbva"),$D23,0) -> 0 | M23: =+IF(AND($A23="tomas gomez",$E23="bbva"),$D23,0) -> 0 | N23: =IF(E23="GIRO",D23,0) -> 0 | O23: =IF(E23="DAVIVIENDA",D23,0) -> 0 | P23: =IF(E23="NEQUI TG",D23,0) -> 0 | Q23: =IF(E23="NEQUI AB",D23,0) -> 0 | R23: =IF(E23="NEQUI OTRO",D23,0) -> 0
C24: KIA ION MANIJA LH EXT DEL | D24: 45000 | E24: EFECTIVO | F24: =IF(E24="EFECTIVO",D24,0) -> 45000 | G24: =+IF(E24="ENTREGA",D24,0) -> 0 | H24: =+IF(AND(A24="latas sas",E24="tarjeta"),D24,0) -> 0 | I24: =+IF(AND(A24="tomas gomez",E24="tarjeta"),D24,0) -> 0 | J24: =+IF(AND($A24="latas sas",$E24="bancolombia"),$D24,0) -> 0 | K24: =+IF(AND($A24="tomas gomez",$E24="bancolombia"),$D24,0) -> 0 | L24: =+IF(AND($A24="latas sas",$E24="bbva"),$D24,0) -> 0 | M24: =+IF(AND($A24="tomas gomez",$E24="bbva"),$D24,0) -> 0 | N24: =IF(E24="GIRO",D24,0) -> 0 | O24: =IF(E24="DAVIVIENDA",D24,0) -> 0 | P24: =IF(E24="NEQUI TG",D24,0) -> 0 | Q24: =IF(E24="NEQUI AB",D24,0) -> 0 | R24: =IF(E24="NEQUI OTRO",D24,0) -> 0
D25: 539000 | E25: ENTREGA | F25: =IF(E25="EFECTIVO",D25,0) -> 0 | G25: =+IF(E25="ENTREGA",D25,0) -> 539000 | H25: =+IF(AND(A25="latas sas",E25="tarjeta"),D25,0) -> 0 | I25: =+IF(AND(A25="tomas gomez",E25="tarjeta"),D25,0) -> 0 | J25: =+IF(AND($A25="latas sas",$E25="bancolombia"),$D25,0) -> 0 | K25: =+IF(AND($A25="tomas gomez",$E25="bancolombia"),$D25,0) -> 0 | L25: =+IF(AND($A25="latas sas",$E25="bbva"),$D25,0) -> 0 | M25: =+IF(AND($A25="tomas gomez",$E25="bbva"),$D25,0) -> 0 | N25: =IF(E25="GIRO",D25,0) -> 0 | O25: =IF(E25="DAVIVIENDA",D25,0) -> 0 | P25: =IF(E25="NEQUI TG",D25,0) -> 0 | Q25: =IF(E25="NEQUI AB",D25,0) -> 0 | R25: =IF(E25="NEQUI OTRO",D25,0) -> 0
F26: =IF(E26="EFECTIVO",D26,0) -> 0 | G26: =+IF(E26="ENTREGA",D26,0) -> 0 | H26: =+IF(AND(A26="latas sas",E26="tarjeta"),D26,0) -> 0 | I26: =+IF(AND(A26="tomas gomez",E26="tarjeta"),D26,0) -> 0 | J26: =+IF(AND($A26="latas sas",$E26="bancolombia"),$D26,0) -> 0 | K26: =+IF(AND($A26="tomas gomez",$E26="bancolombia"),$D26,0) -> 0 | L26: =+IF(AND($A26="latas sas",$E26="bbva"),$D26,0) -> 0 | M26: =+IF(AND($A26="tomas gomez",$E26="bbva"),$D26,0) -> 0 | N26: =IF(E26="GIRO",D26,0) -> 0 | O26: =IF(E26="DAVIVIENDA",D26,0) -> 0 | P26: =IF(E26="NEQUI TG",D26,0) -> 0 | Q26: =IF(E26="NEQUI AB",D26,0) -> 0 | R26: =IF(E26="NEQUI OTRO",D26,0) -> 0
F27: =IF(E27="EFECTIVO",D27,0) -> 0 | G27: =+IF(E27="ENTREGA",D27,0) -> 0 | H27: =+IF(AND(A27="latas sas",E27="tarjeta"),D27,0) -> 0 | I27: =+IF(AND(A27="tomas gomez",E27="tarjeta"),D27,0) -> 0 | J27: =+IF(AND($A27="latas sas",$E27="bancolombia"),$D27,0) -> 0 | K27: =+IF(AND($A27="tomas gomez",$E27="bancolombia"),$D27,0) -> 0 | L27: =+IF(AND($A27="latas sas",$E27="bbva"),$D27,0) -> 0 | M27: =+IF(AND($A27="tomas gomez",$E27="bbva"),$D27,0) -> 0 | N27: =IF(E27="GIRO",D27,0) -> 0 | O27: =IF(E27="DAVIVIENDA",D27,0) -> 0 | P27: =IF(E27="NEQUI TG",D27,0) -> 0 | Q27: =IF(E27="NEQUI AB",D27,0) -> 0 | R27: =IF(E27="NEQUI OTRO",D27,0) -> 0
F28: =IF(E28="EFECTIVO",D28,0) -> 0 | G28: =+IF(E28="ENTREGA",D28,0) -> 0 | H28: =+IF(AND(A28="latas sas",E28="tarjeta"),D28,0) -> 0 | I28: =+IF(AND(A28="tomas gomez",E28="tarjeta"),D28,0) -> 0 | J28: =+IF(AND($A28="latas sas",$E28="bancolombia"),$D28,0) -> 0 | K28: =+IF(AND($A28="tomas gomez",$E28="bancolombia"),$D28,0) -> 0 | L28: =+IF(AND($A28="latas sas",$E28="bbva"),$D28,0) -> 0 | M28: =+IF(AND($A28="tomas gomez",$E28="bbva"),$D28,0) -> 0 | N28: =IF(E28="GIRO",D28,0) -> 0 | O28: =IF(E28="DAVIVIENDA",D28,0) -> 0 | P28: =IF(E28="NEQUI TG",D28,0) -> 0 | Q28: =IF(E28="NEQUI AB",D28,0) -> 0 | R28: =IF(E28="NEQUI OTRO",D28,0) -> 0
F29: =IF(E29="EFECTIVO",D29,0) -> 0 | G29: =+IF(E29="ENTREGA",D29,0) -> 0 | H29: =+IF(AND(A29="latas sas",E29="tarjeta"),D29,0) -> 0 | I29: =+IF(AND(A29="tomas gomez",E29="tarjeta"),D29,0) -> 0 | J29: =+IF(AND($A29="latas sas",$E29="bancolombia"),$D29,0) -> 0 | K29: =+IF(AND($A29="tomas gomez",$E29="bancolombia"),$D29,0) -> 0 | L29: =+IF(AND($A29="latas sas",$E29="bbva"),$D29,0) -> 0 | M29: =+IF(AND($A29="tomas gomez",$E29="bbva"),$D29,0) -> 0 | N29: =IF(E29="GIRO",D29,0) -> 0 | O29: =IF(E29="DAVIVIENDA",D29,0) -> 0 | P29: =IF(E29="NEQUI TG",D29,0) -> 0 | Q29: =IF(E29="NEQUI AB",D29,0) -> 0 | R29: =IF(E29="NEQUI OTRO",D29,0) -> 0
F30: =IF(E30="EFECTIVO",D30,0) -> 0 | G30: =+IF(E30="ENTREGA",D30,0) -> 0 | H30: =+IF(AND(A30="latas sas",E30="tarjeta"),D30,0) -> 0 | I30: =+IF(AND(A30="tomas gomez",E30="tarjeta"),D30,0) -> 0 | J30: =+IF(AND($A30="latas sas",$E30="bancolombia"),$D30,0) -> 0 | K30: =+IF(AND($A30="tomas gomez",$E30="bancolombia"),$D30,0) -> 0 | L30: =+IF(AND($A30="latas sas",$E30="bbva"),$D30,0) -> 0 | M30: =+IF(AND($A30="tomas gomez",$E30="bbva"),$D30,0) -> 0 | N30: =IF(E30="GIRO",D30,0) -> 0 | O30: =IF(E30="DAVIVIENDA",D30,0) -> 0 | P30: =IF(E30="NEQUI TG",D30,0) -> 0 | Q30: =IF(E30="NEQUI AB",D30,0) -> 0 | R30: =IF(E30="NEQUI OTRO",D30,0) -> 0
F31: =IF(E31="EFECTIVO",D31,0) -> 0 | G31: =+IF(E31="ENTREGA",D31,0) -> 0 | H31: =+IF(AND(A31="latas sas",E31="tarjeta"),D31,0) -> 0 | I31: =+IF(AND(A31="tomas gomez",E31="tarjeta"),D31,0) -> 0 | J31: =+IF(AND($A31="latas sas",$E31="bancolombia"),$D31,0) -> 0 | K31: =+IF(AND($A31="tomas gomez",$E31="bancolombia"),$D31,0) -> 0 | L31: =+IF(AND($A31="latas sas",$E31="bbva"),$D31,0) -> 0 | M31: =+IF(AND($A31="tomas gomez",$E31="bbva"),$D31,0) -> 0 | N31: =IF(E31="GIRO",D31,0) -> 0 | O31: =IF(E31="DAVIVIENDA",D31,0) -> 0 | P31: =IF(E31="NEQUI TG",D31,0) -> 0 | Q31: =IF(E31="NEQUI AB",D31,0) -> 0 | R31: =IF(E31="NEQUI OTRO",D31,0) -> 0
F32: =IF(E32="EFECTIVO",D32,0) -> 0 | G32: =+IF(E32="ENTREGA",D32,0) -> 0 | H32: =+IF(AND(A32="latas sas",E32="tarjeta"),D32,0) -> 0 | I32: =+IF(AND(A32="tomas gomez",E32="tarjeta"),D32,0) -> 0 | J32: =+IF(AND($A32="latas sas",$E32="bancolombia"),$D32,0) -> 0 | K32: =+IF(AND($A32="tomas gomez",$E32="bancolombia"),$D32,0) -> 0 | L32: =+IF(AND($A32="latas sas",$E32="bbva"),$D32,0) -> 0 | M32: =+IF(AND($A32="tomas gomez",$E32="bbva"),$D32,0) -> 0 | N32: =IF(E32="GIRO",D32,0) -> 0 | O32: =IF(E32="DAVIVIENDA",D32,0) -> 0 | P32: =IF(E32="NEQUI TG",D32,0) -> 0 | Q32: =IF(E32="NEQUI AB",D32,0) -> 0 | R32: =IF(E32="NEQUI OTRO",D32,0) -> 0
F33: =IF(E33="EFECTIVO",D33,0) -> 0 | G33: =+IF(E33="ENTREGA",D33,0) -> 0 | H33: =+IF(AND(A33="latas sas",E33="tarjeta"),D33,0) -> 0 | I33: =+IF(AND(A33="tomas gomez",E33="tarjeta"),D33,0) -> 0 | J33: =+IF(AND($A33="latas sas",$E33="bancolombia"),$D33,0) -> 0 | K33: =+IF(AND($A33="tomas gomez",$E33="bancolombia"),$D33,0) -> 0 | L33: =+IF(AND($A33="latas sas",$E33="bbva"),$D33,0) -> 0 | M33: =+IF(AND($A33="tomas gomez",$E33="bbva"),$D33,0) -> 0 | N33: =IF(E33="GIRO",D33,0) -> 0 | O33: =IF(E33="DAVIVIENDA",D33,0) -> 0 | P33: =IF(E33="NEQUI TG",D33,0) -> 0 | Q33: =IF(E33="NEQUI AB",D33,0) -> 0 | R33: =IF(E33="NEQUI OTRO",D33,0) -> 0
F34: =IF(E34="EFECTIVO",D34,0) -> 0 | G34: =+IF(E34="ENTREGA",D34,0) -> 0 | H34: =+IF(AND(A34="latas sas",E34="tarjeta"),D34,0) -> 0 | I34: =+IF(AND(A34="tomas gomez",E34="tarjeta"),D34,0) -> 0 | J34: =+IF(AND($A34="latas sas",$E34="bancolombia"),$D34,0) -> 0 | K34: =+IF(AND($A34="tomas gomez",$E34="bancolombia"),$D34,0) -> 0 | L34: =+IF(AND($A34="latas sas",$E34="bbva"),$D34,0) -> 0 | M34: =+IF(AND($A34="tomas gomez",$E34="bbva"),$D34,0) -> 0 | N34: =IF(E34="GIRO",D34,0) -> 0 | O34: =IF(E34="DAVIVIENDA",D34,0) -> 0 | P34: =IF(E34="NEQUI TG",D34,0) -> 0 | Q34: =IF(E34="NEQUI AB",D34,0) -> 0 | R34: =IF(E34="NEQUI OTRO",D34,0) -> 0
F35: =IF(E35="EFECTIVO",D35,0) -> 0 | G35: =+IF(E35="ENTREGA",D35,0) -> 0 | H35: =+IF(AND(A35="latas sas",E35="tarjeta"),D35,0) -> 0 | I35: =+IF(AND(A35="tomas gomez",E35="tarjeta"),D35,0) -> 0 | J35: =+IF(AND($A35="latas sas",$E35="bancolombia"),$D35,0) -> 0 | K35: =+IF(AND($A35="tomas gomez",$E35="bancolombia"),$D35,0) -> 0 | L35: =+IF(AND($A35="latas sas",$E35="bbva"),$D35,0) -> 0 | M35: =+IF(AND($A35="tomas gomez",$E35="bbva"),$D35,0) -> 0 | N35: =IF(E35="GIRO",D35,0) -> 0 | O35: =IF(E35="DAVIVIENDA",D35,0) -> 0 | P35: =IF(E35="NEQUI TG",D35,0) -> 0 | Q35: =IF(E35="NEQUI AB",D35,0) -> 0 | R35: =IF(E35="NEQUI OTRO",D35,0) -> 0
F36: =IF(E36="EFECTIVO",D36,0) -> 0 | G36: =+IF(E36="ENTREGA",D36,0) -> 0 | H36: =+IF(AND(A36="latas sas",E36="tarjeta"),D36,0) -> 0 | I36: =+IF(AND(A36="tomas gomez",E36="tarjeta"),D36,0) -> 0 | J36: =+IF(AND($A36="latas sas",$E36="bancolombia"),$D36,0) -> 0 | K36: =+IF(AND($A36="tomas gomez",$E36="bancolombia"),$D36,0) -> 0 | L36: =+IF(AND($A36="latas sas",$E36="bbva"),$D36,0) -> 0 | M36: =+IF(AND($A36="tomas gomez",$E36="bbva"),$D36,0) -> 0 | N36: =IF(E36="GIRO",D36,0) -> 0 | O36: =IF(E36="DAVIVIENDA",D36,0) -> 0 | P36: =IF(E36="NEQUI TG",D36,0) -> 0 | Q36: =IF(E36="NEQUI AB",D36,0) -> 0 | R36: =IF(E36="NEQUI OTRO",D36,0) -> 0
F37: =IF(E37="EFECTIVO",D37,0) -> 0 | G37: =+IF(E37="ENTREGA",D37,0) -> 0 | H37: =+IF(AND(A37="latas sas",E37="tarjeta"),D37,0) -> 0 | I37: =+IF(AND(A37="tomas gomez",E37="tarjeta"),D37,0) -> 0 | J37: =+IF(AND($A37="latas sas",$E37="bancolombia"),$D37,0) -> 0 | K37: =+IF(AND($A37="tomas gomez",$E37="bancolombia"),$D37,0) -> 0 | L37: =+IF(AND($A37="latas sas",$E37="bbva"),$D37,0) -> 0 | M37: =+IF(AND($A37="tomas gomez",$E37="bbva"),$D37,0) -> 0 | N37: =IF(E37="GIRO",D37,0) -> 0 | O37: =IF(E37="DAVIVIENDA",D37,0) -> 0 | P37: =IF(E37="NEQUI TG",D37,0) -> 0 | Q37: =IF(E37="NEQUI AB",D37,0) -> 0 | R37: =IF(E37="NEQUI OTRO",D37,0) -> 0
... F51: =IF(E51="EFECTIVO",D51,0) -> 0 | G51: =+IF(E51="ENTREGA",D51,0) -> 0 | H51: =+IF(AND(A51="latas sas",E51="tarjeta"),D51,0) -> 0 | I51: =+IF(AND(A51="tomas gomez",E51="tarjeta"),D51,0) -> 0 | J51: =+IF(AND($A51="latas sas",$E51="bancolombia"),$D51,0) -> 0 | K51: =+IF(AND($A51="tomas gomez",$E51="bancolombia"),$D51,0) -> 0 | L51: =+IF(AND($A51="latas sas",$E51="bbva"),$D51,0) -> 0 | M51: =+IF(AND($A51="tomas gomez",$E51="bbva"),$D51,0) -> 0 | N51: =IF(E51="GIRO",D51,0) -> 0 | O51: =IF(E51="DAVIVIENDA",D51,0) -> 0 | P51: =IF(E51="NEQUI TG",D51,0) -> 0 | Q51: =IF(E51="NEQUI AB",D51,0) -> 0 | R51: =IF(E51="NEQUI OTRO",D51,0) -> 0

Sheet 3
A1: LATAS Y PARTES DE LA COSTA
C2: CAJA MENOR
C3: CAJA EFECTIVO | D3: =+F3-G3 -> 0 | E3: =(SUM(F3:R3))-G3 -> 4458000 | F3: =SUM(F5:F50) -> 2446000 | G3: =SUM(G5:G50) -> 2446000 | H3: =SUM(H5:H50) -> 75000 | I3: =SUM(I5:I50) -> 0 | J3: =SUM(J5:J50) -> 1937000 | K3: =SUM(K5:K50) -> 0 | L3: =SUM(L5:L50) -> 0 | M3: =SUM(M5:M50) -> 0 | ... R3: =SUM(R5:R50) -> 0
A4: EMPRESA | B4: NOTA | C4: DESCRIPCIÓN | D4: VALOR | E4: FORMA PAGO | F4: EFECTIVO | G4: ENTREGA | H4: TARJETA LATAS | I4: TARJETA TOMAS | J4: BANCOLOMBIA LATAS | K4: BANCOLOMBIA TOMAS | L4: BBVA LATAS | M4: BBVA TOMAS | N4: GIRO | O4: DAVIVIENDA | P4: NEQUI TG | Q4: NEQUI AB | R4: NEQUI OTRO
B5: RODRIGO | C5: HY I10 DEF TRAS | D5: 160000 | E5: EFECTIVO | F5: =IF(E5="EFECTIVO",D5,0) -> 160000 | G5: =+IF(E5="ENTREGA",D5,0) -> 0 | H5: =+IF(AND(A5="latas sas",E5="tarjeta"),D5,0) -> 0 | I5: =+IF(AND(A5="tomas gomez",E5="tarjeta"),D5,0) -> 0 | J5: =+IF(AND($A5="latas sas",$E5="bancolombia"),$D5,0) -> 0 | K5: =+IF(AND($A5="tomas gomez",$E5="bancolombia"),$D5,0) -> 0 | L5: =+IF(AND($A5="latas sas",$E5="bbva"),$D5,0) -> 0 | M5: =+IF(AND($A5="tomas gomez",$E5="bbva"),$D5,0) -> 0 | N5: =IF(E5="GIRO",D5,0) -> 0 | O5: =IF(E5="DAVIVIENDA",D5,0) -> 0 | P5: =IF(E5="NEQUI TG",D5,0) -> 0 | Q5: =IF(E5="NEQUI AB",D5,0) -> 0 | R5: =IF(E5="NEQUI OTRO",D5,0) -> 0
C6: CHEVR AVEO SEDAN EXPLORADORA LH | D6: 40000 | E6: BANCOLOMBIA | F6: =IF(E6="EFECTIVO",D6,0) -> 0 | G6: =+IF(E6="ENTREGA",D6,0) -> 0 | H6: =+IF(AND(A6="latas sas",E6="tarjeta"),D6,0) -> 0 | I6: =+IF(AND(A6="tomas gomez",E6="tarjeta"),D6,0) -> 0 | J6: =+IF(AND($A6="latas sas",$E6="bancolombia"),$D6,0) -> 0 | K6: =+IF(AND($A6="tomas gomez",$E6="bancolombia"),$D6,0) -> 0 | L6: =+IF(AND($A6="latas sas",$E6="bbva"),$D6,0) -> 0 | M6: =+IF(AND($A6="tomas gomez",$E6="bbva"),$D6,0) -> 0 | N6: =IF(E6="GIRO",D6,0) -> 0 | O6: =IF(E6="DAVIVIENDA",D6,0) -> 0 | P6: =IF(E6="NEQUI TG",E6,0) -> 0 | Q6: =IF(E6="NEQUI AB",D6,0) -> 0 | R6: =IF(E6="NEQUI OTRO",D6,0) -> 0
C7: NEILA | F7: =IF(E7="EFECTIVO",D7,0) -> 0 | G7: =+IF(E7="ENTREGA",D7,0) -> 0 | H7: =+IF(AND(A7="latas sas",E7="tarjeta"),D7,0) -> 0 | I7: =+IF(AND(A7="tomas gomez",E7="tarjeta"),D7,0) -> 0 | J7: =+IF(AND($A7="latas sas",$E7="bancolombia"),$D7,0) -> 0 | K7: =+IF(AND($A7="tomas gomez",$E7="bancolombia"),$D7,0) -> 0 | L7: =+IF(AND($A7="latas sas",$E7="bbva"),$D7,0) -> 0 | M7: =+IF(AND($A7="tomas gomez",$E7="bbva"),$D7,0) -> 0 | N7: =IF(E7="GIRO",D7,0) -> 0 | O7: =IF(E7="DAVIVIENDA",D7,0) -> 0 | P7: =IF(E7="NEQUI TG",E7,0) -> 0 | Q7: =IF(E7="NEQUI AB",D7,0) -> 0 | R7: =IF(E7="NEQUI OTRO",D7,0) -> 0
C8: CHEVR SPARK GT 15/15 DEF DEL | D8: 260000 | E8: EFECTIVO | F8: =IF(E8="EFECTIVO",D8,0) -> 260000 | G8: =+IF(E8="ENTREGA",D8,0) -> 0 | H8: =+IF(AND(A8="latas sas",E8="tarjeta"),D8,0) -> 0 | I8: =+IF(AND(A8="tomas gomez",E8="tarjeta"),D8,0) -> 0 | J8: =+IF(AND($A8="latas sas",$E8="bancolombia"),$D8,0) -> 0 | K8: =+IF(AND($A8="tomas gomez",$E8="bancolombia"),$D8,0) -> 0 | L8: =+IF(AND($A8="latas sas",$E8="bbva"),$D8,0) -> 0 | M8: =+IF(AND($A8="tomas gomez",$E8="bbva"),$D8,0) -> 0 | N8: =IF(E8="GIRO",D8,0) -> 0 | O8: =IF(E8="DAVIVIENDA",D8,0) -> 0 | P8: =IF(E8="NEQUI TG",E8,0) -> 0 | Q8: =IF(E8="NEQUI AB",D8,0) -> 0 | R8: =IF(E8="NEQUI OTRO",D8,0) -> 0
A9: LATAS SAS | C9: BOMBILLO 2 CONT HELLA | D9: 4000 | E9: BANCOLOMBIA | F9: =IF(E9="EFECTIVO",D9,0) -> 0 | G9: =+IF(E9="ENTREGA",D9,0) -> 0 | H9: =+IF(AND(A9="latas sas",E9="tarjeta"),D9,0) -> 0 | I9: =+IF(AND(A9="tomas gomez",E9="tarjeta"),D9,0) -> 0 | J9: =+IF(AND($A9="latas sas",$E9="bancolombia"),$D9,0) -> 4000 | K9: =+IF(AND($A9="tomas gomez",$E9="bancolombia"),$D9,0) -> 0 | L9: =+IF(AND($A9="latas sas",$E9="bbva"),$D9,0) -> 0 | M9: =+IF(AND($A9="tomas gomez",$E9="bbva"),$D9,0) -> 0 | N9: =IF(E9="GIRO",D9,0) -> 0 | O9: =IF(E9="DAVIVIENDA",D9,0) -> 0 | P9: =IF(E9="NEQUI TG",E9,0) -> 0 | Q9: =IF(E9="NEQUI AB",D9,0) -> 0 | R9: =IF(E9="NEQUI OTRO",D9,0) -> 0
C10: RENAULT LOGAN SANDERO 16/20 TAPA RETROV RH C/H | D10: 55000 | E10: EFECTIVO | F10: =IF(E10="EFECTIVO",D10,0) -> 55000 | G10: =+IF(E10="ENTREGA",D10,0) -> 0 | H10: =+IF(AND(A10="latas sas",E10="tarjeta"),D10,0) -> 0 | I10: =+IF(AND(A10="tomas gomez",E10="tarjeta"),D10,0) -> 0 | J10: =+IF(AND($A10="latas sas",$E10="bancolombia"),$D10,0) -> 0 | K10: =+IF(AND($A10="tomas gomez",$E10="bancolombia"),$D10,0) -> 0 | L10: =+IF(AND($A10="latas sas",$E10="bbva"),$D10,0) -> 0 | M10: =+IF(AND($A10="tomas gomez",$E10="bbva"),$D10,0) -> 0 | N10: =IF(E10="GIRO",D10,0) -> 0 | O10: =IF(E10="DAVIVIENDA",D10,0) -> 0 | P10: =IF(E10="NEQUI TG",E10,0) -> 0 | Q10: =IF(E10="NEQUI AB",D10,0) -> 0 | R10: =IF(E10="NEQUI OTRO",D10,0) -> 0
A11: LATAS SAS | C11: TOYOTA VIGO CAJA DE DIRECCION | D11: 700000 | E11: BANCOLOMBIA | F11: =IF(E11="EFECTIVO",D11,0) -> 0 | G11: =+IF(E11="ENTREGA",D11,0) -> 0 | H11: =+IF(AND(A11="latas sas",E11="tarjeta"),D11,0) -> 0 | I11: =+IF(AND(A11="tomas gomez",E11="tarjeta"),D11,0) -> 0 | J11: =+IF(AND($A11="latas sas",$E11="bancolombia"),$D11,0) -> 700000 | K11: =+IF(AND($A11="tomas gomez",$E11="bancolombia"),$D11,0) -> 0 | L11: =+IF(AND($A11="latas sas",$E11="bbva"),$D11,0) -> 0 | M11: =+IF(AND($A11="tomas gomez",$E11="bbva"),$D11,0) -> 0 | N11: =IF(E11="GIRO",D11,0) -> 0 | O11: =IF(E11="DAVIVIENDA",D11,0) -> 0 | P11: =IF(E11="NEQUI TG",E11,0) -> 0 | Q11: =IF(E11="NEQUI AB",D11,0) -> 0 | R11: =IF(E11="NEQUI OTRO",D11,0) -> 0
C12: HY ATOS MANIJA DEL RH | D12: 14000 | E12: EFECTIVO | F12: =IF(E12="EFECTIVO",D12,0) -> 14000 | G12: =+IF(E12="ENTREGA",D12,0) -> 0 | H12: =+IF(AND(A12="latas sas",E12="tarjeta"),D12,0) -> 0 | I12: =+IF(AND(A12="tomas gomez",E12="tarjeta"),D12,0) -> 0 | J12: =+IF(AND($A12="latas sas",$E12="bancolombia"),$D12,0) -> 0 | K12: =+IF(AND($A12="tomas gomez",$E12="bancolombia"),$D12,0) -> 0 | L12: =+IF(AND($A12="latas sas",$E12="bbva"),$D12,0) -> 0 | M12: =+IF(AND($A12="tomas gomez",$E12="bbva"),$D12,0) -> 0 | N12: =IF(E12="GIRO",D12,0) -> 0 | O12: =IF(E12="DAVIVIENDA",D12,0) -> 0 | P12: =IF(E12="NEQUI TG",E12,0) -> 0 | Q12: =IF(E12="NEQUI AB",D12,0) -> 0 | R12: =IF(E12="NEQUI OTRO",D12,0) -> 0
A13: LATAS SAS | C13: HY ATOS 6 MANIJAS ELEVA VIDRIOS | D13: 48000 | E13: BANCOLOMBIA | F13: =IF(E13="EFECTIVO",D13,0) -> 0 | G13: =+IF(E13="ENTREGA",D13,0) -> 0 | H13: =+IF(AND(A13="latas sas",E13="tarjeta"),D13,0) -> 0 | I13: =+IF(AND(A13="tomas gomez",E13="tarjeta"),D13,0) -> 0 | J13: =+IF(AND($A13="latas sas",$E13="bancolombia"),$D13,0) -> 48000 | K13: =+IF(AND($A13="tomas gomez",$E13="bancolombia"),$D13,0) -> 0 | L13: =+IF(AND($A13="latas sas",$E13="bbva"),$D13,0) -> 0 | M13: =+IF(AND($A13="tomas gomez",$E13="bbva"),$D13,0) -> 0 | N13: =IF(E13="GIRO",D13,0) -> 0 | O13: =IF(E13="DAVIVIENDA",D13,0) -> 0 | P13: =IF(E13="NEQUI TG",E13,0) -> 0 | Q13: =IF(E13="NEQUI AB",D13,0) -> 0 | R13: =IF(E13="NEQUI OTRO",D13,0) -> 0
B14: MARCOS | C14: TOYOTA PRADO MODELO NUEVO 2 GUIAS | D14: 130000 | E14: EFECTIVO | F14: =IF(E14="EFECTIVO",D14,0) -> 130000 | G14: =+IF(E14="ENTREGA",D14,0) -> 0 | H14: =+IF(AND(A14="latas sas",E14="tarjeta"),D14,0) -> 0 | I14: =+IF(AND(A14="tomas gomez",E14="tarjeta"),D14,0) -> 0 | J14: =+IF(AND($A14="latas sas",$E14="bancolombia"),$D14,0) -> 0 | K14: =+IF(AND($A14="tomas gomez",$E14="bancolombia"),$D14,0) -> 0 | L14: =+IF(AND($A14="latas sas",$E14="bbva"),$D14,0) -> 0 | M14: =+IF(AND($A14="tomas gomez",$E14="bbva"),$D14,0) -> 0 | N14: =IF(E14="GIRO",D14,0) -> 0 | O14: =IF(E14="DAVIVIENDA",D14,0) -> 0 | P14: =IF(E14="NEQUI TG",E14,0) -> 0 | Q14: =IF(E14="NEQUI AB",D14,0) -> 0 | R14: =IF(E14="NEQUI OTRO",D14,0) -> 0
B15: WILL | C15: CHEVR SPARK GT RADIADOR/ GUIA LH | D15: 250000 | E15: EFECTIVO | F15: =IF(E15="EFECTIVO",D15,0) -> 250000 | G15: =+IF(E15="ENTREGA",D15,0) -> 0 | H15: =+IF(AND(A15="latas sas",E15="tarjeta"),D15,0) -> 0 | I15: =+IF(AND(A15="tomas gomez",E15="tarjeta"),D15,0) -> 0 | J15: =+IF(AND($A15="latas sas",$E15="bancolombia"),$D15,0) -> 0 | K15: =+IF(AND($A15="tomas gomez",$E15="bancolombia"),$D15,0) -> 0 | L15: =+IF(AND($A15="latas sas",$E15="bbva"),$D15,0) -> 0 | M15: =+IF(AND($A15="tomas gomez",$E15="bbva"),$D15,0) -> 0 | N15: =IF(E15="GIRO",D15,0) -> 0 | O15: =IF(E15="DAVIVIENDA",D15,0) -> 0 | P15: =IF(E15="NEQUI TG",E15,0) -> 0 | Q15: =IF(E15="NEQUI AB",D15,0) -> 0 | R15: =IF(E15="NEQUI OTRO",D15,0) -> 0
B16: OSWALDO STA MARTA | C16: CHEVR BEAT DEF DEL / PASO RUEDA RH/LH/ GUARDAF LH /COBRO POR EFECTY | D16: 680000 | E16: EFECTIVO | F16: =IF(E16="EFECTIVO",D16,0) -> 680000 | G16: =+IF(E16="ENTREGA",D16,0) -> 0 | H16: =+IF(AND(A16="latas sas",E16="tarjeta"),D16,0) -> 0 | I16: =+IF(AND(A16="tomas gomez",E16="tarjeta"),D16,0) -> 0 | J16: =+IF(AND($A16="latas sas",$E16="bancolombia"),$D16,0) -> 0 | K16: =+IF(AND($A16="tomas gomez",$E16="bancolombia"),$D16,0) -> 0 | L16: =+IF(AND($A16="latas sas",$E16="bbva"),$D16,0) -> 0 | M16: =+IF(AND($A16="tomas gomez",$E16="bbva"),$D16,0) -> 0 | N16: =IF(E16="GIRO",D16,0) -> 0 | O16: =IF(E16="DAVIVIENDA",D16,0) -> 0 | P16: =IF(E16="NEQUI TG",E16,0) -> 0 | Q16: =IF(E16="NEQUI AB",D16,0) -> 0 | R16: =IF(E16="NEQUI OTRO",D16,0) -> 0
A17: LATAS SAS | C17: MAZDA ALLEGRO LAMP RH/LH/STOP RH/LH DEPO | D17: 900000 | E17: BANCOLOMBIA | F17: =IF(E17="EFECTIVO",D17,0) -> 0 | G17: =+IF(E17="ENTREGA",D17,0) -> 0 | H17: =+IF(AND(A17="latas sas",E17="tarjeta"),D17,0) -> 0 | I17: =+IF(AND(A17="tomas gomez",E17="tarjeta"),D17,0) -> 0 | J17: =+IF(AND($A17="latas sas",$E17="bancolombia"),$D17,0) -> 900000 | K17: =+IF(AND($A17="tomas gomez",$E17="bancolombia"),$D17,0) -> 0 | L17: =+IF(AND($A17="latas sas",$E17="bbva"),$D17,0) -> 0 | M17: =+IF(AND($A17="tomas gomez",$E17="bbva"),$D17,0) -> 0 | N17: =IF(E17="GIRO",D17,0) -> 0 | O17: =IF(E17="DAVIVIENDA",D17,0) -> 0 | P17: =IF(E17="NEQUI TG",E17,0) -> 0 | Q17: =IF(E17="NEQUI AB",D17,0) -> 0 | R17: =IF(E17="NEQUI OTRO",D17,0) -> 0
B18: CHINO GALAN | C18: KIA ION DEF DEL/ GUARDAF RH/ LAMP RH/GUIA RH/ TAPA EXPLORADORA C/H RH | D18: 700000 | E18: EFECTIVO | F18: =IF(E18="EFECTIVO",D18,0) -> 700000 | G18: =+IF(E18="ENTREGA",D18,0) -> 0 | H18: =+IF(AND(A18="latas sas",E18="tarjeta"),D18,0) -> 0 | I18: =+IF(AND(A18="tomas gomez",E18="tarjeta"),D18,0) -> 0 | J18: =+IF(AND($A18="latas sas",$E18="bancolombia"),$D18,0) -> 0 | K18: =+IF(AND($A18="tomas gomez",$E18="bancolombia"),$D18,0) -> 0 | L18: =+IF(AND($A18="latas sas",$E18="bbva"),$D18,0) -> 0 | M18: =+IF(AND($A18="tomas gomez",$E18="bbva"),$D18,0) -> 0 | N18: =IF(E18="GIRO",D18,0) -> 0 | O18: =IF(E18="DAVIVIENDA",D18,0) -> 0 | P18: =IF(E18="NEQUI TG",E18,0) -> 0 | Q18: =IF(E18="NEQUI AB",D18,0) -> 0 | R18: =IF(E18="NEQUI OTRO",D18,0) -> 0
D19: 2249000 | E19: ENTREGA | F19: =IF(E19="EFECTIVO",D19,0) -> 0 | G19: =+IF(E19="ENTREGA",D19,0) -> 2249000 | H19: =+IF(AND(A19="latas sas",E19="tarjeta"),D19,0) -> 0 | I19: =+IF(AND(A19="tomas gomez",E19="tarjeta"),D19,0) -> 0 | J19: =+IF(AND($A19="latas sas",$E19="bancolombia"),$D19,0) -> 0 | K19: =+IF(AND($A19="tomas gomez",$E19="bancolombia"),$D19,0) -> 0 | L19: =+IF(AND($A19="latas sas",$E19="bbva"),$D19,0) -> 0 | M19: =+IF(AND($A19="tomas gomez",$E19="bbva"),$D19,0) -> 0 | N19: =IF(E19="GIRO",D19,0) -> 0 | O19: =IF(E19="DAVIVIENDA",D19,0) -> 0 | P19: =IF(E19="NEQUI TG",E19,0) -> 0 | Q19: =IF(E19="NEQUI AB",D19,0) -> 0 | R19: =IF(E19="NEQUI OTRO",D19,0) -> 0
A20: LATAS SAS | C20: CHEVR SAIL REJILLA DEF/GUARDAF RH | D20: 185000 | E20: BANCOLOMBIA | F20: =IF(E20="EFECTIVO",D20,0) -> 0 | G20: =+IF(E20="ENTREGA",D20,0) -> 0 | H20: =+IF(AND(A20="latas sas",E20="tarjeta"),D20,0) -> 0 | I20: =+IF(AND(A20="tomas gomez",E20="tarjeta"),D20,0) -> 0 | J20: =+IF(AND($A20="latas sas",$E20="bancolombia"),$D20,0) -> 185000 | K20: =+IF(AND($A20="tomas gomez",$E20="bancolombia"),$D20,0) -> 0 | L20: =+IF(AND($A20="latas sas",$E20="bbva"),$D20,0) -> 0 | M20: =+IF(AND($A20="tomas gomez",$E20="bbva"),$D20,0) -> 0 | N20: =IF(E20="GIRO",D20,0) -> 0 | O20: =IF(E20="DAVIVIENDA",D20,0) -> 0 | P20: =IF(E20="NEQUI TG",E20,0) -> 0 | Q20: =IF(E20="NEQUI AB",D20,0) -> 0 | R20: =IF(E20="NEQUI OTRO",D20,0) -> 0
C21: MAZDA ALLEGRO DEF DEL/ ABONO EN CAJA | D21: 100000 | F21: =IF(E21="EFECTIVO",D21,0) -> 0 | G21: =+IF(E21="ENTREGA",D21,0) -> 0 | H21: =+IF(AND(A21="latas sas",E21="tarjeta"),D21,0) -> 0 | I21: =+IF(AND(A21="tomas gomez",E21="tarjeta"),D21,0) -> 0 | J21: =+IF(AND($A21="latas sas",$E21="bancolombia"),$D21,0) -> 0 | K21: =+IF(AND($A21="tomas gomez",$E21="bancolombia"),$D21,0) -> 0 | L21: =+IF(AND($A21="latas sas",$E21="bbva"),$D21,0) -> 0 | M21: =+IF(AND($A21="tomas gomez",$E21="bbva"),$D21,0) -> 0 | N21: =IF(E21="GIRO",D21,0) -> 0 | O21: =IF(E21="DAVIVIENDA",D21,0) -> 0 | P21: =IF(E21="NEQUI TG",E21,0) -> 0 | Q21: =IF(E21="NEQUI AB",D21,0) -> 0 | R21: =IF(E21="NEQUI OTRO",D21,0) -> 0
A22: LATAS SAS | C22: KIA RIO SPICE PASO RUEDA LH | D22: 75000 | E22: TARJETA | F22: =IF(E22="EFECTIVO",D22,0) -> 0 | G22: =+IF(E22="ENTREGA",D22,0) -> 0 | H22: =+IF(AND(A22="latas sas",E22="tarjeta"),D22,0) -> 75000 | I22: =+IF(AND(A22="tomas gomez",E22="tarjeta"),D22,0) -> 0 | J22: =+IF(AND($A22="latas sas",$E22="bancolombia"),$D22,0) -> 0 | K22: =+IF(AND($A22="tomas gomez",$E22="bancolombia"),$D22,0) -> 0 | L22: =+IF(AND($A22="latas sas",$E22="bbva"),$D22,0) -> 0 | M22: =+IF(AND($A22="tomas gomez",$E22="bbva"),$D22,0) -> 0 | N22: =IF(E22="GIRO",D22,0) -> 0 | O22: =IF(E22="DAVIVIENDA",D22,0) -> 0 | P22: =IF(E22="NEQUI TG",E22,0) -> 0 | Q22: =IF(E22="NEQUI AB",D22,0) -> 0 | R22: =IF(E22="NEQUI OTRO",D22,0) -> 0
C23: ANDRES TRANSPORTES | D23: -3000 | E23: EFECTIVO | F23: =IF(E23="EFECTIVO",D23,0) -> -3000 | G23: =+IF(E23="ENTREGA",D23,0) -> 0 | H23: =+IF(AND(A23="latas sas",E23="tarjeta"),D23,0) -> 0 | I23: =+IF(AND(A23="tomas gomez",E23="tarjeta"),D23,0) -> 0 | J23: =+IF(AND($A23="latas sas",$E23="bancolombia"),$D23,0) -> 0 | K23: =+IF(AND($A23="tomas gomez",$E23="bancolombia"),$D23,0) -> 0 | L23: =+IF(AND($A23="latas sas",$E23="bbva"),$D23,0) -> 0 | M23: =+IF(AND($A23="tomas gomez",$E23="bbva"),$D23,0) -> 0 | N23: =IF(E23="GIRO",D23,0) -> 0 | O23: =IF(E23="DAVIVIENDA",D23,0) -> 0 | P23: =IF(E23="NEQUI TG",E23,0) -> 0 | Q23: =IF(E23="NEQUI AB",D23,0) -> 0 | R23: =IF(E23="NEQUI OTRO",D23,0) -> 0
C24: TOYOTA LUZ COMPUERTA PLATON ROJA DEPO | D24: 160000 | E24: EFECTIVO | F24: =IF(E24="EFECTIVO",D24,0) -> 160000 | G24: =+IF(E24="ENTREGA",D24,0) -> 0 | H24: =+IF(AND(A24="latas sas",E24="tarjeta"),D24,0) -> 0 | I24: =+IF(AND(A24="tomas gomez",E24="tarjeta"),D24,0) -> 0 | J24: =+IF(AND($A24="latas sas",$E24="bancolombia"),$D24,0) -> 0 | K24: =+IF(AND($A24="tomas gomez",$E24="bancolombia"),$D24,0) -> 0 | L24: =+IF(AND($A24="latas sas",$E24="bbva"),$D24,0) -> 0 | M24: =+IF(AND($A24="tomas gomez",$E24="bbva"),$D24,0) -> 0 | N24: =IF(E24="GIRO",D24,0) -> 0 | O24: =IF(E24="DAVIVIENDA",D24,0) -> 0 | P24: =IF(E24="NEQUI TG",E24,0) -> 0 | Q24: =IF(E24="NEQUI AB",D24,0) -> 0 | R24: =IF(E24="NEQUI OTRO",D24,0) -> 0
A25: LATAS SAS | C25: RENAULT CLIO SIMBOL RETROV LH MANUAL | D25: 100000 | E25: BANCOLOMBIA | F25: =IF(E25="EFECTIVO",D25,0) -> 0 | G25: =+IF(E25="ENTREGA",D25,0) -> 0 | H25: =+IF(AND(A25="latas sas",E25="tarjeta"),D25,0) -> 0 | I25: =+IF(AND(A25="tomas gomez",E25="tarjeta"),D25,0) -> 0 | J25: =+IF(AND($A25="latas sas",$E25="bancolombia"),$D25,0) -> 100000 | K25: =+IF(AND($A25="tomas gomez",$E25="bancolombia"),$D25,0) -> 0 | L25: =+IF(AND($A25="latas sas",$E25="bbva"),$D25,0) -> 0 | M25: =+IF(AND($A25="tomas gomez",$E25="bbva"),$D25,0) -> 0 | N25: =IF(E25="GIRO",D25,0) -> 0 | O25: =IF(E25="DAVIVIENDA",D25,0) -> 0 | P25: =IF(E25="NEQUI TG",E25,0) -> 0 | Q25: =IF(E25="NEQUI AB",D25,0) -> 0 | R25: =IF(E25="NEQUI OTRO",D25,0) -> 0
C26: KIA ION 18/20 PASO RUEDA LH | D26: 60000 | E26: EFECTIVO | F26: =IF(E26="EFECTIVO",D26,0) -> 60000 | G26: =+IF(E26="ENTREGA",D26,0) -> 0 | H26: =+IF(AND(A26="latas sas",E26="tarjeta"),D26,0) -> 0 | I26: =+IF(AND(A26="tomas gomez",E26="tarjeta"),D26,0) -> 0 | J26: =+IF(AND($A26="latas sas",$E26="bancolombia"),$D26,0) -> 0 | K26: =+IF(AND($A26="tomas gomez",$E26="bancolombia"),$D26,0) -> 0 | L26: =+IF(AND($A26="latas sas",$E26="bbva"),$D26,0) -> 0 | M26: =+IF(AND($A26="tomas gomez",$E26="bbva"),$D26,0) -> 0 | N26: =IF(E26="GIRO",D26,0) -> 0 | O26: =IF(E26="DAVIVIENDA",D26,0) -> 0 | P26: =IF(E26="NEQUI TG",E26,0) -> 0 | Q26: =IF(E26="NEQUI AB",D26,0) -> 0 | R26: =IF(E26="NEQUI OTRO",D26,0) -> 0
C27: PINES 15 | D27: 15000 | E27: EFECTIVO | F27: =IF(E27="EFECTIVO",D27,0) -> 15000 | G27: =+IF(E27="ENTREGA",D27,0) -> 0 | H27: =+IF(AND(A27="latas sas",E27="tarjeta"),D27,0) -> 0 | I27: =+IF(AND(A27="tomas gomez",E27="tarjeta"),D27,0) -> 0 | J27: =+IF(AND($A27="latas sas",$E27="bancolombia"),$D27,0) -> 0 | K27: =+IF(AND($A27="tomas gomez",$E27="bancolombia"),$D27,0) -> 0 | L27: =+IF(AND($A27="latas sas",$E27="bbva"),$D27,0) -> 0 | M27: =+IF(AND($A27="tomas gomez",$E27="bbva"),$D27,0) -> 0 | N27: =IF(E27="GIRO",D27,0) -> 0 | O27: =IF(E27="DAVIVIENDA",D27,0) -> 0 | P27: =IF(E27="NEQUI TG",E27,0) -> 0 | Q27: =IF(E27="NEQUI AB",D27,0) -> 0 | R27: =IF(E27="NEQUI OTRO",D27,0) -> 0
C28: PAGO VIGILANTE | D28: -30000 | E28: EFECTIVO | F28: =IF(E28="EFECTIVO",D28,0) -> -30000 | G28: =+IF(E28="ENTREGA",D28,0) -> 0 | H28: =+IF(AND(A28="latas sas",E28="tarjeta"),D28,0) -> 0 | I28: =+IF(AND(A28="tomas gomez",E28="tarjeta"),D28,0) -> 0 | J28: =+IF(AND($A28="latas sas",$E28="bancolombia"),$D28,0) -> 0 | K28: =+IF(AND($A28="tomas gomez",$E28="bancolombia"),$D28,0) -> 0 | L28: =+IF(AND($A28="latas sas",$E28="bbva"),$D28,0) -> 0 | M28: =+IF(AND($A28="tomas gomez",$E28="bbva"),$D28,0) -> 0 | N28: =IF(E28="GIRO",D28,0) -> 0 | O28: =IF(E28="DAVIVIENDA",D28,0) -> 0 | P28: =IF(E28="NEQUI TG",E28,0) -> 0 | Q28: =IF(E28="NEQUI AB",D28,0) -> 0 | R28: =IF(E28="NEQUI OTRO",D28,0) -> 0
C29: CHEVR OPTRA 05/08 MANIJA EXT RHDEL LH | D29: 45000 | E29: EFECTIVO | F29: =IF(E29="EFECTIVO",D29,0) -> 45000 | G29: =+IF(E29="ENTREGA",D29,0) -> 0 | H29: =+IF(AND(A29="latas sas",E29="tarjeta"),D29,0) -> 0 | I29: =+IF(AND(A29="tomas gomez",E29="tarjeta"),D29,0) -> 0 | J29: =+IF(AND($A29="latas sas",$E29="bancolombia"),$D29,0) -> 0 | K29: =+IF(AND($A29="tomas gomez",$E29="bancolombia"),$D29,0) -> 0 | L29: =+IF(AND($A29="latas sas",$E29="bbva"),$D29,0) -> 0 | M29: =+IF(AND($A29="tomas gomez",$E29="bbva"),$D29,0) -> 0 | N29: =IF(E29="GIRO",D29,0) -> 0 | O29: =IF(E29="DAVIVIENDA",D29,0) -> 0 | P29: =IF(E29="NEQUI TG",E29,0) -> 0 | Q29: =IF(E29="NEQUI AB",D29,0) -> 0 | R29: =IF(E29="NEQUI OTRO",D29,0) -> 0
C30: NEYLA NEQUI SR TOMAS | D30: -50000 | E30: EFECTIVO | F30: =IF(E30="EFECTIVO",D30,0) -> -50000 | G30: =+IF(E30="ENTREGA",D30,0) -> 0 | H30: =+IF(AND(A30="latas sas",E30="tarjeta"),D30,0) -> 0 | I30: =+IF(AND(A30="tomas gomez",E30="tarjeta"),D30,0) -> 0 | J30: =+IF(AND($A30="latas sas",$E30="bancolombia"),$D30,0) -> 0 | K30: =+IF(AND($A30="tomas gomez",$E30="bancolombia"),$D30,0) -> 0 | L30: =+IF(AND($A30="latas sas",$E30="bbva"),$D30,0) -> 0 | M30: =+IF(AND($A30="tomas gomez",$E30="bbva"),$D30,0) -> 0 | N30: =IF(E30="GIRO",D30,0) -> 0 | O30: =IF(E30="DAVIVIENDA",D30,0) -> 0 | P30: =IF(E30="NEQUI TG",E30,0) -> 0 | Q30: =IF(E30="NEQUI AB",D30,0) -> 0 | R30: =IF(E30="NEQUI OTRO",D30,0) -> 0
D31: 197000 | E31: ENTREGA | F31: =IF(E31="EFECTIVO",D31,0) -> 0 | G31: =+IF(E31="ENTREGA",D31,0) -> 197000 | H31: =+IF(AND(A31="latas sas",E31="tarjeta"),D31,0) -> 0 | I31: =+IF(AND(A31="tomas gomez",E31="tarjeta"),D31,0) -> 0 | J31: =+IF(AND($A31="latas sas",$E31="bancolombia"),$D31,0) -> 0 | K31: =+IF(AND($A31="tomas gomez",$E31="bancolombia"),$D31,0) -> 0 | L31: =+IF(AND($A31="latas sas",$E31="bbva"),$D31,0) -> 0 | M31: =+IF(AND($A31="tomas gomez",$E31="bbva"),$D31,0) -> 0 | N31: =IF(E31="GIRO",D31,0) -> 0 | O31: =IF(E31="DAVIVIENDA",D31,0) -> 0 | P31: =IF(E31="NEQUI TG",E31,0) -> 0 | Q31: =IF(E31="NEQUI AB",D31,0) -> 0 | R31: =IF(E31="NEQUI OTRO",D31,0) -> 0
F32: =IF(E32="EFECTIVO",D32,0) -> 0 | G32: =+IF(E32="ENTREGA",D32,0) -> 0 | H32: =+IF(AND(A32="latas sas",E32="tarjeta"),D32,0) -> 0 | I32: =+IF(AND(A32="tomas gomez",E32="tarjeta"),D32,0) -> 0 | J32: =+IF(AND($A32="latas sas",$E32="bancolombia"),$D32,0) -> 0 | K32: =+IF(AND($A32="tomas gomez",$E32="bancolombia"),$D32,0) -> 0 | L32: =+IF(AND($A32="latas sas",$E32="bbva"),$D32,0) -> 0 | M32: =+IF(AND($A32="tomas gomez",$E32="bbva"),$D32,0) -> 0 | N32: =IF(E32="GIRO",D32,0) -> 0 | O32: =IF(E32="DAVIVIENDA",D32,0) -> 0 | P32: =IF(E32="NEQUI TG",E32,0) -> 0 | Q32: =IF(E32="NEQUI AB",D32,0) -> 0 | R32: =IF(E32="NEQUI OTRO",D32,0) -> 0
F33: =IF(E33="EFECTIVO",D33,0) -> 0 | G33: =+IF(E33="ENTREGA",D33,0) -> 0 | H33: =+IF(AND(A33="latas sas",E33="tarjeta"),D33,0) -> 0 | I33: =+IF(AND(A33="tomas gomez",E33="tarjeta"),D33,0) -> 0 | J33: =+IF(AND($A33="latas sas",$E33="bancolombia"),$D33,0) -> 0 | K33: =+IF(AND($A33="tomas gomez",$E33="bancolombia"),$D33,0) -> 0 | L33: =+IF(AND($A33="latas sas",$E33="bbva"),$D33,0) -> 0 | M33: =+IF(AND($A33="tomas gomez",$E33="bbva"),$D33,0) -> 0 | N33: =IF(E33="GIRO",D33,0) -> 0 | O33: =IF(E33="DAVIVIENDA",D33,0) -> 0 | P33: =IF(E33="NEQUI TG",E33,0) -> 0 | Q33: =IF(E33="NEQUI AB",D33,0) -> 0 | R33: =IF(E33="NEQUI OTRO",D33,0) -> 0
F34: =IF(E34="EFECTIVO",D34,0) -> 0 | G34: =+IF(E34="ENTREGA",D34,0) -> 0 | H34: =+IF(AND(A34="latas sas",E34="tarjeta"),D34,0) -> 0 | I34: =+IF(AND(A34="tomas gomez",E34="tarjeta"),D34,0) -> 0 | J34: =+IF(AND($A34="latas sas",$E34="bancolombia"),$D34,0) -> 0 | K34: =+IF(AND($A34="tomas gomez",$E34="bancolombia"),$D34,0) -> 0 | L34: =+IF(AND($A34="latas sas",$E34="bbva"),$D34,0) -> 0 | M34: =+IF(AND($A34="tomas gomez",$E34="bbva"),$D34,0) -> 0 | N34: =IF(E34="GIRO",D34,0) -> 0 | O34: =IF(E34="DAVIVIENDA",D34,0) -> 0 | P34: =IF(E34="NEQUI TG",E34,0) -> 0 | Q34: =IF(E34="NEQUI AB",D34,0) -> 0 | R34: =IF(E34="NEQUI OTRO",D34,0) -> 0
F35: =IF(E35="EFECTIVO",D35,0) -> 0 | G35: =+IF(E35="ENTREGA",D35,0) -> 0 | H35: =+IF(AND(A35="latas sas",E35="tarjeta"),D35,0) -> 0 | I35: =+IF(AND(A35="tomas gomez",E35="tarjeta"),D35,0) -> 0 | J35: =+IF(AND($A35="latas sas",$E35="bancolombia"),$D35,0) -> 0 | K35: =+IF(AND($A35="tomas gomez",$E35="bancolombia"),$D35,0) -> 0 | L35: =+IF(AND($A35="latas sas",$E35="bbva"),$D35,0) -> 0 | M35: =+IF(AND($A35="tomas gomez",$E35="bbva"),$D35,0) -> 0 | N35: =IF(E35="GIRO",D35,0) -> 0 | O35: =IF(E35="DAVIVIENDA",D35,0) -> 0 | P35: =IF(E35="NEQUI TG",E35,0) -> 0 | Q35: =IF(E35="NEQUI AB",D35,0) -> 0 | R35: =IF(E35="NEQUI OTRO",D35,0) -> 0
F36: =IF(E36="EFECTIVO",D36,0) -> 0 | G36: =+IF(E36="ENTREGA",D36,0) -> 0 | H36: =+IF(AND(A36="latas sas",E36="tarjeta"),D36,0) -> 0 | I36: =+IF(AND(A36="tomas gomez",E36="tarjeta"),D36,0) -> 0 | J36: =+IF(AND($A36="latas sas",$E36="bancolombia"),$D36,0) -> 0 | K36: =+IF(AND($A36="tomas gomez",$E36="bancolombia"),$D36,0) -> 0 | L36: =+IF(AND($A36="latas sas",$E36="bbva"),$D36,0) -> 0 | M36: =+IF(AND($A36="tomas gomez",$E36="bbva"),$D36,0) -> 0 | N36: =IF(E36="GIRO",D36,0) -> 0 | O36: =IF(E36="DAVIVIENDA",D36,0) -> 0 | P36: =IF(E36="NEQUI TG",E36,0) -> 0 | Q36: =IF(E36="NEQUI AB",D36,0) -> 0 | R36: =IF(E36="NEQUI OTRO",D36,0) -> 0
F37: =IF(E37="EFECTIVO",D37,0) -> 0 | G37: =+IF(E37="ENTREGA",D37,0) -> 0 | H37: =+IF(AND(A37="latas sas",E37="tarjeta"),D37,0) -> 0 | I37: =+IF(AND(A37="tomas gomez",E37="tarjeta"),D37,0) -> 0 | J37: =+IF(AND($A37="latas sas",$E37="bancolombia"),$D37,0) -> 0 | K37: =+IF(AND($A37="tomas gomez",$E37="bancolombia"),$D37,0) -> 0 | L37: =+IF(AND($A37="latas sas",$E37="bbva"),$D37,0) -> 0 | M37: =+IF(AND($A37="tomas gomez",$E37="bbva"),$D37,0) -> 0 | N37: =IF(E37="GIRO",D37,0) -> 0 | O37: =IF(E37="DAVIVIENDA",D37,0) -> 0 | P37: =IF(E37="NEQUI TG",E37,0) -> 0 | Q37: =IF(E37="NEQUI AB",D37,0) -> 0 | R37: =IF(E37="NEQUI OTRO",D37,0) -> 0
F38: =IF(E38="EFECTIVO",D38,0) -> 0 | G38: =+IF(E38="ENTREGA",D38,0) -> 0 | H38: =+IF(AND(A38="latas sas",E38="tarjeta"),D38,0) -> 0 | I38: =+IF(AND(A38="tomas gomez",E38="tarjeta"),D38,0) -> 0 | J38: =+IF(AND($A38="latas sas",$E38="bancolombia"),$D38,0) -> 0 | K38: =+IF(AND($A38="tomas gomez",$E38="bancolombia"),$D38,0) -> 0 | L38: =+IF(AND($A38="latas sas",$E38="bbva"),$D38,0) -> 0 | M38: =+IF(AND($A38="tomas gomez",$E38="bbva"),$D38,0) -> 0 | N38: =IF(E38="GIRO",D38,0) -> 0 | O38: =IF(E38="DAVIVIENDA",D38,0) -> 0 | P38: =IF(E38="NEQUI TG",E38,0) -> 0 | Q38: =IF(E38="NEQUI AB",D38,0) -> 0 | R38: =IF(E38="NEQUI OTRO",D38,0) -> 0
F39: =IF(E39="EFECTIVO",D39,0) -> 0 | G39: =+IF(E39="ENTREGA",D39,0) -> 0 | H39: =+IF(AND(A39="latas sas",E39="tarjeta"),D39,0) -> 0 | I39: =+IF(AND(A39="tomas gomez",E39="tarjeta"),D39,0) -> 0 | J39: =+IF(AND($A39="latas sas",$E39="bancolombia"),$D39,0) -> 0 | K39: =+IF(AND($A39="tomas gomez",$E39="bancolombia"),$D39,0) -> 0 | L39: =+IF(AND($A39="latas sas",$E39="bbva"),$D39,0) -> 0 | M39: =+IF(AND($A39="tomas gomez",$E39="bbva"),$D39,0) -> 0 | N39: =IF(E39="GIRO",D39,0) -> 0 | O39: =IF(E39="DAVIVIENDA",D39,0) -> 0 | P39: =IF(E39="NEQUI TG",E39,0) -> 0 | Q39: =IF(E39="NEQUI AB",D39,0) -> 0 | R39: =IF(E39="NEQUI OTRO",D39,0) -> 0
F40: =IF(E40="EFECTIVO",D40,0) -> 0 | G40: =+IF(E40="ENTREGA",D40,0) -> 0 | H40: =+IF(AND(A40="latas sas",E40="tarjeta"),D40,0) -> 0 | I40: =+IF(AND(A40="tomas gomez",E40="tarjeta"),D40,0) -> 0 | J40: =+IF(AND($A40="latas sas",$E40="bancolombia"),$D40,0) -> 0 | K40: =+IF(AND($A40="tomas gomez",$E40="bancolombia"),$D40,0) -> 0 | L40: =+IF(AND($A40="latas sas",$E40="bbva"),$D40,0) -> 0 | M40: =+IF(AND($A40="tomas gomez",$E40="bbva"),$D40,0) -> 0 | N40: =IF(E40="GIRO",D40,0) -> 0 | O40: =IF(E40="DAVIVIENDA",D40,0) -> 0 | P40: =IF(E40="NEQUI TG",E40,0) -> 0 | Q40: =IF(E40="NEQUI AB",D40,0) -> 0 | R40: =IF(E40="NEQUI OTRO",D40,0) -> 0
...

Sheet 4
A1: LATAS Y PARTES DE LA COSTA
C2: CAJA MENOR
C3: CAJA EFECTIVO | D3: =+F3-G3 -> 200000 | E3: =(SUM(F3:R3))-G3 -> 2743000 | F3: =SUM(F5:F50) -> 833000 | G3: =SUM(G5:G50) -> 633000 | H3: =SUM(H5:H50) -> 0 | I3: =SUM(I5:I50) -> 0 | J3: =SUM(J5:J50) -> 1420000 | K3: =SUM(K5:K50) -> 0 | L3: =SUM(L5:L50) -> 0 | M3: =SUM(M5:M50) -> 0 | ... R3: =SUM(R5:R50) -> 0
A4: EMPRESA | B4: NOTA | C4: DESCRIPCIÓN | D4: VALOR | E4: FORMA PAGO | F4: EFECTIVO | G4: ENTREGA | H4: TARJETA LATAS | I4: TARJETA TOMAS | J4: BANCOLOMBIA LATAS | K4: BANCOLOMBIA TOMAS | L4: BBVA LATAS | M4: BBVA TOMAS | N4: GIRO | O4: DAVIVIENDA | P4: NEQUI TG | Q4: NEQUI AB | R4: NEQUI OTRO
C5: DEVOLUCION MANIJA EXT DEL RH $45.000 CAMBIO POR MANIJA INT DEL RH SALDO A FAVOR $10.000 | F5: =IF(E5="EFECTIVO",D5,0) -> 0 | G5: =+IF(E5="ENTREGA",D5,0) -> 0 | H5: =+IF(AND(A5="latas sas",E5="tarjeta"),D5,0) -> 0 | I5: =+IF(AND(A5="tomas gomez",E5="tarjeta"),D5,0) -> 0 | J5: =+IF(AND($A5="latas sas",$E5="bancolombia"),$D5,0) -> 0 | K5: =+IF(AND($A5="tomas gomez",$E5="bancolombia"),$D5,0) -> 0 | L5: =+IF(AND($A5="latas sas",$E5="bbva"),$D5,0) -> 0 | M5: =+IF(AND($A5="tomas gomez",$E5="bbva"),$D5,0) -> 0 | N5: =IF(E5="GIRO",D5,0) -> 0 | O5: =IF(E5="DAVIVIENDA",D5,0) -> 0 | P5: =IF(E5="NEQUI TG",D5,0) -> 0 | Q5: =IF(E5="NEQUI AB",D5,0) -> 0 | R5: =IF(E5="NEQUI OTRO",D5,0) -> 0
B6: MARCOS MONTAÑEZ | C6: TOYOTA PRADO BOCELES PERSIANA | D6: 220000 | E6: EFECTIVO | F6: =IF(E6="EFECTIVO",D6,0) -> 220000 | G6: =+IF(E6="ENTREGA",D6,0) -> 0 | H6: =+IF(AND(A6="latas sas",E6="tarjeta"),D6,0) -> 0 | I6: =+IF(AND(A6="tomas gomez",E6="tarjeta"),D6,0) -> 0 | J6: =+IF(AND($A6="latas sas",$E6="bancolombia"),$D6,0) -> 0 | K6: =+IF(AND($A6="tomas gomez",$E6="bancolombia"),$D6,0) -> 0 | L6: =+IF(AND($A6="latas sas",$E6="bbva"),$D6,0) -> 0 | M6: =+IF(AND($A6="tomas gomez",$E6="bbva"),$D6,0) -> 0 | N6: =IF(E6="GIRO",D6,0) -> 0 | O6: =IF(E6="DAVIVIENDA",D6,0) -> 0 | P6: =IF(E6="NEQUI TG",E6,0) -> 0 | Q6: =IF(E6="NEQUI AB",D6,0) -> 0 | R6: =IF(E6="NEQUI OTRO",D6,0) -> 0
A7: LATAS SAS | C7: MAZDA ALLEGRO MANIJA INT RH | D7: 25000 | E7: BANCOLOMBIA | F7: =IF(E7="EFECTIVO",D7,0) -> 0 | G7: =+IF(E7="ENTREGA",D7,0) -> 0 | H7: =+IF(AND(A7="latas sas",E7="tarjeta"),D7,0) -> 0 | I7: =+IF(AND(A7="tomas gomez",E7="tarjeta"),D7,0) -> 0 | J7: =+IF(AND($A7="latas sas",$E7="bancolombia"),$D7,0) -> 25000 | K7: =+IF(AND($A7="tomas gomez",$E7="bancolombia"),$D7,0) -> 0 | L7: =+IF(AND($A7="latas sas",$E7="bbva"),$D7,0) -> 0 | M7: =+IF(AND($A7="tomas gomez",$E7="bbva"),$D7,0) -> 0 | N7: =IF(E7="GIRO",D7,0) -> 0 | O7: =IF(E7="DAVIVIENDA",D7,0) -> 0 | P7: =IF(E7="NEQUI TG",E7,0) -> 0 | Q7: =IF(E7="NEQUI AB",D7,0) -> 0 | R7: =IF(E7="NEQUI OTRO",D7,0) -> 0
C8: KIA PICANTO ION LUNA LH | D8: 35000 | E8: EFECTIVO | F8: =IF(E8="EFECTIVO",D8,0) -> 35000 | G8: =+IF(E8="ENTREGA",D8,0) -> 0 | H8: =+IF(AND(A8="latas sas",E8="tarjeta"),D8,0) -> 0 | I8: =+IF(AND(A8="tomas gomez",E8="tarjeta"),D8,0) -> 0 | J8: =+IF(AND($A8="latas sas",$E8="bancolombia"),$D8,0) -> 0 | K8: =+IF(AND($A8="tomas gomez",$E8="bancolombia"),$D8,0) -> 0 | L8: =+IF(AND($A8="latas sas",$E8="bbva"),$D8,0) -> 0 | M8: =+IF(AND($A8="tomas gomez",$E8="bbva"),$D8,0) -> 0 | N8: =IF(E8="GIRO",D8,0) -> 0 | O8: =IF(E8="DAVIVIENDA",D8,0) -> 0 | P8: =IF(E8="NEQUI TG",E8,0) -> 0 | Q8: =IF(E8="NEQUI AB",D8,0) -> 0 | R8: =IF(E8="NEQUI OTRO",D8,0) -> 0
C9: RENAULT LOGAN SANDERO DUSTER LUNA RH | D9: 30000 | E9: EFECTIVO | F9: =IF(E9="EFECTIVO",D9,0) -> 30000 | G9: =+IF(E9="ENTREGA",D9,0) -> 0 | H9: =+IF(AND(A9="latas sas",E9="tarjeta"),D9,0) -> 0 | I9: =+IF(AND(A9="tomas gomez",E9="tarjeta"),D9,0) -> 0 | J9: =+IF(AND($A9="latas sas",$E9="bancolombia"),$D9,0) -> 0 | K9: =+IF(AND($A9="tomas gomez",$E9="bancolombia"),$D9,0) -> 0 | L9: =+IF(AND($A9="latas sas",$E9="bbva"),$D9,0) -> 0 | M9: =+IF(AND($A9="tomas gomez",$E9="bbva"),$D9,0) -> 0 | N9: =IF(E9="GIRO",D9,0) -> 0 | O9: =IF(E9="DAVIVIENDA",D9,0) -> 0 | P9: =IF(E9="NEQUI TG",E9,0) -> 0 | Q9: =IF(E9="NEQUI AB",D9,0) -> 0 | R9: =IF(E9="NEQUI OTRO",D9,0) -> 0
C10: PICANTO ION 11/17 GUIA RH/LH/ 10 PINES | D10: 70000 | E10: EFECTIVO | F10: =IF(E10="EFECTIVO",D10,0) -> 70000 | G10: =+IF(E10="ENTREGA",D10,0) -> 0 | H10: =+IF(AND(A10="latas sas",E10="tarjeta"),D10,0) -> 0 | I10: =+IF(AND(A10="tomas gomez",E10="tarjeta"),D10,0) -> 0 | J10: =+IF(AND($A10="latas sas",$E10="bancolombia"),$D10,0) -> 0 | K10: =+IF(AND($A10="tomas gomez",$E10="bancolombia"),$D10,0) -> 0 | L10: =+IF(AND($A10="latas sas",$E10="bbva"),$D10,0) -> 0 | M10: =+IF(AND($A10="tomas gomez",$E10="bbva"),$D10,0) -> 0 | N10: =IF(E10="GIRO",D10,0) -> 0 | O10: =IF(E10="DAVIVIENDA",D10,0) -> 0 | P10: =IF(E10="NEQUI TG",E10,0) -> 0 | Q10: =IF(E10="NEQUI AB",D10,0) -> 0 | R10: =IF(E10="NEQUI OTRO",D10,0) -> 0
A11: LATAS SAS | C11: CHEVR AVEO FAMILY LAMP RH/LH | D11: 260000 | E11: BANCOLOMBIA | F11: =IF(E11="EFECTIVO",D11,0) -> 0 | G11: =+IF(E11="ENTREGA",D11,0) -> 0 | H11: =+IF(AND(A11="latas sas",E11="tarjeta"),D11,0) -> 0 | I11: =+IF(AND(A11="tomas gomez",E11="tarjeta"),D11,0) -> 0 | J11: =+IF(AND($A11="latas sas",$E11="bancolombia"),$D11,0) -> 260000 | K11: =+IF(AND($A11="tomas gomez",$E11="bancolombia"),$D11,0) -> 0 | L11: =+IF(AND($A11="latas sas",$E11="bbva"),$D11,0) -> 0 | M11: =+IF(AND($A11="tomas gomez",$E11="bbva"),$D11,0) -> 0 | N11: =IF(E11="GIRO",D11,0) -> 0 | O11: =IF(E11="DAVIVIENDA",D11,0) -> 0 | P11: =IF(E11="NEQUI TG",E11,0) -> 0 | Q11: =IF(E11="NEQUI AB",D11,0) -> 0 | R11: =IF(E11="NEQUI OTRO",D11,0) -> 0
C12: BOMBILLO AMARILLO | D12: 4000 | E12: EFECTIVO | F12: =IF(E12="EFECTIVO",D12,0) -> 4000 | G12: =+IF(E12="ENTREGA",D12,0) -> 0 | H12: =+IF(AND(A12="latas sas",E12="tarjeta"),D12,0) -> 0 | I12: =+IF(AND(A12="tomas gomez",E12="tarjeta"),D12,0) -> 0 | J12: =+IF(AND($A12="latas sas",$E12="bancolombia"),$D12,0) -> 0 | K12: =+IF(AND($A12="tomas gomez",$E12="bancolombia"),$D12,0) -> 0 | L12: =+IF(AND($A12="latas sas",$E12="bbva"),$D12,0) -> 0 | M12: =+IF(AND($A12="tomas gomez",$E12="bbva"),$D12,0) -> 0 | N12: =IF(E12="GIRO",D12,0) -> 0 | O12: =IF(E12="DAVIVIENDA",D12,0) -> 0 | P12: =IF(E12="NEQUI TG",E12,0) -> 0 | Q12: =IF(E12="NEQUI AB",D12,0) -> 0 | R12: =IF(E12="NEQUI OTRO",D12,0) -> 0
B13: MARCOS MONTAÑEZ | C13: KIA ION PASO RUEDA LH | D13: 50000 | E13: EFECTIVO | F13: =IF(E13="EFECTIVO",D13,0) -> 50000 | G13: =+IF(E13="ENTREGA",D13,0) -> 0 | H13: =+IF(AND(A13="latas sas",E13="tarjeta"),D13,0) -> 0 | I13: =+IF(AND(A13="tomas gomez",E13="tarjeta"),D13,0) -> 0 | J13: =+IF(AND($A13="latas sas",$E13="bancolombia"),$D13,0) -> 0 | K13: =+IF(AND($A13="tomas gomez",$E13="bancolombia"),$D13,0) -> 0 | L13: =+IF(AND($A13="latas sas",$E13="bbva"),$D13,0) -> 0 | M13: =+IF(AND($A13="tomas gomez",$E13="bbva"),$D13,0) -> 0 | N13: =IF(E13="GIRO",D13,0) -> 0 | O13: =IF(E13="DAVIVIENDA",D13,0) -> 0 | P13: =IF(E13="NEQUI TG",E13,0) -> 0 | Q13: =IF(E13="NEQUI AB",D13,0) -> 0 | R13: =IF(E13="NEQUI OTRO",D13,0) -> 0
A14: LATAS SAS | C14: CHEVR ONIX GUARDAF DEL RH GRANDE | D14: 200000 | E14: BANCOLOMBIA | F14: =IF(E14="EFECTIVO",D14,0) -> 0 | G14: =+IF(E14="ENTREGA",D14,0) -> 0 | H14: =+IF(AND(A14="latas sas",E14="tarjeta"),D14,0) -> 0 | I14: =+IF(AND(A14="tomas gomez",E14="tarjeta"),D14,0) -> 0 | J14: =+IF(AND($A14="latas sas",$E14="bancolombia"),$D14,0) -> 200000 | K14: =+IF(AND($A14="tomas gomez",$E14="bancolombia"),$D14,0) -> 0 | L14: =+IF(AND($A14="latas sas",$E14="bbva"),$D14,0) -> 0 | M14: =+IF(AND($A14="tomas gomez",$E14="bbva"),$D14,0) -> 0 | N14: =IF(E14="GIRO",D14,0) -> 0 | O14: =IF(E14="DAVIVIENDA",D14,0) -> 0 | P14: =IF(E14="NEQUI TG",E14,0) -> 0 | Q14: =IF(E14="NEQUI AB",D14,0) -> 0 | R14: =IF(E14="NEQUI OTRO",D14,0) -> 0
